                Sunday, January 11, 2026 12:00:03
12:00:03 MRP finite scheduling process begin.
12:00:03 ------------------------------------------------------------
12:00:03 Cut Off Date                      -> 1/11/2036 12:00:00 AM
12:00:03 Schedule Start Date               -> 1/11/2026 12:00:00 AM
12:00:03 Run Finite Scheduling             -> True
12:00:03 Ignore Constrained Materials      -> False
12:00:03 Allow Historical Dates            -> False
12:00:03 Use Production Preparation Buffer -> True
12:00:03 ------------------------------------------------------------
12:00:03 Process Control Queue
12:00:03   Group -> Delete; Queue -> DeleteJob; Type -> Job; Finite -> False
12:00:03     Check List -> DeleteAllPO~DeleteJob~DeleteTO; Last Group -> False
12:00:03   Group -> Load; Queue -> SaveLoad; Type -> Job; Finite -> False
12:00:03     Check List -> SaveLoad; Last Group -> True
12:00:03   Group -> NonPart; Queue -> LotJobSplit; Type -> Job; Finite -> False
12:00:03   Group -> NonPart; Queue -> SchedJobF; Type -> Job; Finite -> True
12:00:03   Group -> NonPart; Queue -> SchedJobI; Type -> Job; Finite -> False
12:00:03   Group -> NonPart; Queue -> FirmJob; Type -> Job; Finite -> False
12:00:03     Check List -> FirmJob~LotJobSplit~Part~SchedJobF~SchedJobI; Last Group -> False
12:00:03   Group -> Part; Queue -> LotJobSplit; Type -> Job; Finite -> False
12:00:03   Group -> Part; Queue -> SchedJobF; Type -> Job; Finite -> True
12:00:03   Group -> Part; Queue -> SchedJobI; Type -> Job; Finite -> False
12:00:03   Group -> Part; Queue -> FirmJob; Type -> Job; Finite -> False
12:00:03     Check List -> FirmJob~LotJobSplit~Part~SchedJobF~SchedJobI; Last Group -> False
12:00:03   Group -> Sched; Queue -> PreJobF; Type -> Job; Finite -> True
12:00:03   Group -> Sched; Queue -> PreJobI; Type -> Job; Finite -> False
12:00:03     Check List -> PreJobF~PreJobI; Last Group -> False
12:00:03   Group -> Zero; Queue -> LotJobSplit; Type -> Job; Finite -> False
12:00:03     Check List -> LotJobSplit~Part; Last Group -> False
12:00:03   Group -> ZeroSort; Queue -> SchedJobF; Type -> Job; Finite -> True
12:00:03   Group -> ZeroSort; Queue -> SchedJobI; Type -> Job; Finite -> False
12:00:03   Group -> ZeroSort; Queue -> FirmJob; Type -> Job; Finite -> False
12:00:03     Check List -> FirmJob~SchedJobF~SchedJobI~ZeroJob; Last Group -> False
12:00:03 ------------------------------------------------------------
12:00:14 Ending Part Level: 0-0.  Wait Time 00h:00m:08s, Jobs 0
12:00:14 Done Scheduling Jobs.
12:01:16 MRP process 101 done.  Total Non Scheduling Time = 00h:01m:10s. Scheduled Jobs: 0 Deleted Jobs: 0 Save Load Jobs: 0
                Monday, January 12, 2026 12:00:05
12:00:05 MRP finite scheduling process begin.
12:00:05 ------------------------------------------------------------
12:00:05 Cut Off Date                      -> 1/12/2036 12:00:00 AM
12:00:05 Schedule Start Date               -> 1/12/2026 12:00:00 AM
12:00:05 Run Finite Scheduling             -> True
12:00:05 Ignore Constrained Materials      -> False
12:00:05 Allow Historical Dates            -> False
12:00:05 Use Production Preparation Buffer -> True
12:00:05 ------------------------------------------------------------
12:00:05 Process Control Queue
12:00:05   Group -> Delete; Queue -> DeleteJob; Type -> Job; Finite -> False
12:00:05     Check List -> DeleteAllPO~DeleteJob~DeleteTO; Last Group -> False
12:00:05   Group -> Load; Queue -> SaveLoad; Type -> Job; Finite -> False
12:00:05     Check List -> SaveLoad; Last Group -> True
12:00:05   Group -> NonPart; Queue -> LotJobSplit; Type -> Job; Finite -> False
12:00:05   Group -> NonPart; Queue -> SchedJobF; Type -> Job; Finite -> True
12:00:05   Group -> NonPart; Queue -> SchedJobI; Type -> Job; Finite -> False
12:00:05   Group -> NonPart; Queue -> FirmJob; Type -> Job; Finite -> False
12:00:05     Check List -> FirmJob~LotJobSplit~Part~SchedJobF~SchedJobI; Last Group -> False
12:00:05   Group -> Part; Queue -> LotJobSplit; Type -> Job; Finite -> False
12:00:05   Group -> Part; Queue -> SchedJobF; Type -> Job; Finite -> True
12:00:05   Group -> Part; Queue -> SchedJobI; Type -> Job; Finite -> False
12:00:05   Group -> Part; Queue -> FirmJob; Type -> Job; Finite -> False
12:00:05     Check List -> FirmJob~LotJobSplit~Part~SchedJobF~SchedJobI; Last Group -> False
12:00:05   Group -> Sched; Queue -> PreJobF; Type -> Job; Finite -> True
12:00:05   Group -> Sched; Queue -> PreJobI; Type -> Job; Finite -> False
12:00:05     Check List -> PreJobF~PreJobI; Last Group -> False
12:00:05   Group -> Zero; Queue -> LotJobSplit; Type -> Job; Finite -> False
12:00:05     Check List -> LotJobSplit~Part; Last Group -> False
12:00:05   Group -> ZeroSort; Queue -> SchedJobF; Type -> Job; Finite -> True
12:00:05   Group -> ZeroSort; Queue -> SchedJobI; Type -> Job; Finite -> False
12:00:05   Group -> ZeroSort; Queue -> FirmJob; Type -> Job; Finite -> False
12:00:05     Check List -> FirmJob~SchedJobF~SchedJobI~ZeroJob; Last Group -> False
12:00:05 ------------------------------------------------------------
12:00:13 Starting Part Level: 0-0.
12:00:13 Scheduling new unfirm job:U0000000007868
12:00:13 Done Scheduling job:U0000000007868 sending job to queue SaveLoad
12:00:31 Scheduling new unfirm job:U0000000007869
12:00:35 Done Scheduling job:U0000000007869 sending job to queue SaveLoad
12:00:35 Scheduling new unfirm job:U0000000007871
12:00:36 Done Scheduling job:U0000000007871 sending job to queue SaveLoad
12:01:09 Scheduling new unfirm job:U0000000007972
12:01:12 Done Scheduling job:U0000000007972 sending job to queue SaveLoad
12:01:14 Scheduling new unfirm job:U0000000007974
12:01:17 Done Scheduling job:U0000000007974 sending job to queue SaveLoad
12:01:19 Scheduling new unfirm job:U0000000007976
12:01:23 Done Scheduling job:U0000000007976 sending job to queue SaveLoad
12:01:27 Scheduling new unfirm job:U0000000007979
12:01:31 Done Scheduling job:U0000000007979 sending job to queue SaveLoad
12:01:49 Ending Part Level: 0-0.  Wait Time 00h:01m:36s, Jobs 7
12:01:49 Starting Part Level: 1-0.
12:01:49 Scheduling new unfirm job:U0000000008070
12:01:50 Done Scheduling job:U0000000008070 sending job to queue SaveLoad
12:01:50 Scheduling new unfirm job:U0000000007874
12:01:50 Done Scheduling job:U0000000007874 sending job to queue SaveLoad
12:01:50 Scheduling new unfirm job:U0000000007984
12:01:51 Done Scheduling job:U0000000007984 sending job to queue SaveLoad
12:01:51 Scheduling new unfirm job:U0000000008071
12:01:51 Done Scheduling job:U0000000008071 sending job to queue SaveLoad
12:01:51 Scheduling new unfirm job:U0000000007985
12:01:52 Done Scheduling job:U0000000007985 sending job to queue SaveLoad
12:01:52 Scheduling new unfirm job:U0000000008073
12:01:52 Done Scheduling job:U0000000008073 sending job to queue SaveLoad
12:02:00 Ending Part Level: 1-0.  Wait Time 00h:00m:08s, Jobs 6
12:02:00 Starting Part Level: 2-0.
12:02:00 Scheduling new unfirm job:U0000000007875
12:02:01 Done Scheduling job:U0000000007875 sending job to queue SaveLoad
12:02:01 Scheduling new unfirm job:U0000000007876
12:02:01 Done Scheduling job:U0000000007876 sending job to queue SaveLoad
12:02:01 Scheduling new unfirm job:U0000000007986
12:02:02 Done Scheduling job:U0000000007986 sending job to queue SaveLoad
12:02:02 Scheduling new unfirm job:U0000000008074
12:02:02 Done Scheduling job:U0000000008074 sending job to queue SaveLoad
12:02:02 Scheduling new unfirm job:U0000000007877
12:02:02 Done Scheduling job:U0000000007877 sending job to queue SaveLoad
12:02:02 Scheduling new unfirm job:U0000000008075
12:02:03 Done Scheduling job:U0000000008075 sending job to queue SaveLoad
12:02:03 Scheduling new unfirm job:U0000000007878
12:02:03 Done Scheduling job:U0000000007878 sending job to queue SaveLoad
12:02:03 Scheduling new unfirm job:U0000000007989
12:02:04 Done Scheduling job:U0000000007989 sending job to queue SaveLoad
12:02:04 Scheduling new unfirm job:U0000000008077
12:02:04 Done Scheduling job:U0000000008077 sending job to queue SaveLoad
12:02:04 Scheduling new unfirm job:U0000000008079
12:02:04 Done Scheduling job:U0000000008079 sending job to queue SaveLoad
12:02:04 Scheduling new unfirm job:U0000000007990
12:02:05 Done Scheduling job:U0000000007990 sending job to queue SaveLoad
12:02:05 Scheduling new unfirm job:U0000000007993
12:02:05 Done Scheduling job:U0000000007993 sending job to queue SaveLoad
12:02:05 Scheduling new unfirm job:U0000000007994
12:02:05 Done Scheduling job:U0000000007994 sending job to queue SaveLoad
12:02:05 Scheduling new unfirm job:U0000000008081
12:02:06 Done Scheduling job:U0000000008081 sending job to queue SaveLoad
12:02:06 Scheduling new unfirm job:U0000000008082
12:02:06 Done Scheduling job:U0000000008082 sending job to queue SaveLoad
12:02:06 Scheduling new unfirm job:U0000000008084
12:02:07 Done Scheduling job:U0000000008084 sending job to queue SaveLoad
12:02:07 Scheduling new unfirm job:U0000000008089
12:02:07 Done Scheduling job:U0000000008089 sending job to queue SaveLoad
12:02:07 Scheduling new unfirm job:U0000000008087
12:02:08 Done Scheduling job:U0000000008087 sending job to queue SaveLoad
12:02:08 Scheduling new unfirm job:U0000000007997
12:02:08 Done Scheduling job:U0000000007997 sending job to queue SaveLoad
12:02:08 Scheduling new unfirm job:U0000000007998
12:02:09 Done Scheduling job:U0000000007998 sending job to queue SaveLoad
12:02:09 Scheduling new unfirm job:U0000000008091
12:02:10 Done Scheduling job:U0000000008091 sending job to queue SaveLoad
12:02:10 Scheduling new unfirm job:U0000000007999
12:02:10 Done Scheduling job:U0000000007999 sending job to queue SaveLoad
12:02:10 Scheduling new unfirm job:U0000000008000
12:02:11 Done Scheduling job:U0000000008000 sending job to queue SaveLoad
12:02:13 Scheduling new unfirm job:U0000000008001
12:02:13 Done Scheduling job:U0000000008001 sending job to queue SaveLoad
12:02:13 Scheduling new unfirm job:U0000000008002
12:02:13 Done Scheduling job:U0000000008002 sending job to queue SaveLoad
12:02:13 Scheduling new unfirm job:U0000000007882
12:02:14 Done Scheduling job:U0000000007882 sending job to queue SaveLoad
12:02:14 Scheduling new unfirm job:U0000000008003
12:02:14 Done Scheduling job:U0000000008003 sending job to queue SaveLoad
12:02:14 Scheduling new unfirm job:U0000000007883
12:02:15 Done Scheduling job:U0000000007883 sending job to queue SaveLoad
12:02:15 Scheduling new unfirm job:U0000000007884
12:02:16 Done Scheduling job:U0000000007884 sending job to queue SaveLoad
12:02:16 Scheduling new unfirm job:U0000000007885
12:02:16 Done Scheduling job:U0000000007885 sending job to queue SaveLoad
12:02:16 Scheduling new unfirm job:U0000000007886
12:02:17 Done Scheduling job:U0000000007886 sending job to queue SaveLoad
12:02:17 Scheduling new unfirm job:U0000000007887
12:02:18 Done Scheduling job:U0000000007887 sending job to queue SaveLoad
12:02:18 Scheduling new unfirm job:U0000000007888
12:02:19 Done Scheduling job:U0000000007888 sending job to queue SaveLoad
12:02:19 Scheduling new unfirm job:U0000000007889
12:02:20 Done Scheduling job:U0000000007889 sending job to queue SaveLoad
12:02:20 Scheduling new unfirm job:U0000000008004
12:02:21 Done Scheduling job:U0000000008004 sending job to queue SaveLoad
12:02:21 Scheduling new unfirm job:U0000000007890
12:02:22 Done Scheduling job:U0000000007890 sending job to queue SaveLoad
12:02:22 Scheduling new unfirm job:U0000000008092
12:02:22 Done Scheduling job:U0000000008092 sending job to queue SaveLoad
12:02:22 Scheduling new unfirm job:U0000000007891
12:02:23 Done Scheduling job:U0000000007891 sending job to queue SaveLoad
12:02:23 Scheduling new unfirm job:U0000000008005
12:02:24 Done Scheduling job:U0000000008005 sending job to queue SaveLoad
12:02:24 Scheduling new unfirm job:U0000000008093
12:02:25 Done Scheduling job:U0000000008093 sending job to queue SaveLoad
12:02:25 Scheduling new unfirm job:U0000000007892
12:02:25 Done Scheduling job:U0000000007892 sending job to queue SaveLoad
12:02:25 Scheduling new unfirm job:U0000000008094
12:02:26 Done Scheduling job:U0000000008094 sending job to queue SaveLoad
12:02:26 Scheduling new unfirm job:U0000000007893
12:02:27 Done Scheduling job:U0000000007893 sending job to queue SaveLoad
12:02:27 Scheduling new unfirm job:U0000000008006
12:02:27 Done Scheduling job:U0000000008006 sending job to queue SaveLoad
12:02:27 Scheduling new unfirm job:U0000000008095
12:02:27 Done Scheduling job:U0000000008095 sending job to queue SaveLoad
12:02:27 Scheduling new unfirm job:U0000000008007
12:02:28 Done Scheduling job:U0000000008007 sending job to queue SaveLoad
12:02:28 Scheduling new unfirm job:U0000000008096
12:02:28 Done Scheduling job:U0000000008096 sending job to queue SaveLoad
12:02:28 Scheduling new unfirm job:U0000000008008
12:02:29 Done Scheduling job:U0000000008008 sending job to queue SaveLoad
12:02:29 Scheduling new unfirm job:U0000000007909
12:02:30 Done Scheduling job:U0000000007909 sending job to queue SaveLoad
12:02:30 Scheduling new unfirm job:U0000000007911
12:02:30 Done Scheduling job:U0000000007911 sending job to queue SaveLoad
12:02:30 Scheduling new unfirm job:U0000000007912
12:02:31 Done Scheduling job:U0000000007912 sending job to queue SaveLoad
12:02:31 Scheduling new unfirm job:U0000000008010
12:02:32 Done Scheduling job:U0000000008010 sending job to queue SaveLoad
12:02:32 Scheduling new unfirm job:U0000000007914
12:02:33 Done Scheduling job:U0000000007914 sending job to queue SaveLoad
12:02:33 Scheduling new unfirm job:U0000000008113
12:02:33 Done Scheduling job:U0000000008113 sending job to queue SaveLoad
12:02:33 Scheduling new unfirm job:U0000000008114
12:02:34 Done Scheduling job:U0000000008114 sending job to queue SaveLoad
12:02:34 Scheduling new unfirm job:U0000000007916
12:02:35 Done Scheduling job:U0000000007916 sending job to queue SaveLoad
12:02:35 Scheduling new unfirm job:U0000000008115
12:02:36 Done Scheduling job:U0000000008115 sending job to queue SaveLoad
12:02:36 Scheduling new unfirm job:U0000000007917
12:02:37 Done Scheduling job:U0000000007917 sending job to queue SaveLoad
12:02:37 Scheduling new unfirm job:U0000000007918
12:02:37 Done Scheduling job:U0000000007918 sending job to queue SaveLoad
12:02:37 Scheduling new unfirm job:U0000000007919
12:02:38 Done Scheduling job:U0000000007919 sending job to queue SaveLoad
12:02:38 Scheduling new unfirm job:U0000000007920
12:02:39 Done Scheduling job:U0000000007920 sending job to queue SaveLoad
12:02:39 Scheduling new unfirm job:U0000000007924
12:02:40 Done Scheduling job:U0000000007924 sending job to queue SaveLoad
12:02:40 Scheduling new unfirm job:U0000000008023
12:02:41 Done Scheduling job:U0000000008023 sending job to queue SaveLoad
12:02:41 Scheduling new unfirm job:U0000000007925
12:02:41 Done Scheduling job:U0000000007925 sending job to queue SaveLoad
12:02:41 Scheduling new unfirm job:U0000000008024
12:02:42 Done Scheduling job:U0000000008024 sending job to queue SaveLoad
12:02:42 Scheduling new unfirm job:U0000000007926
12:02:43 Done Scheduling job:U0000000007926 sending job to queue SaveLoad
12:02:43 Scheduling new unfirm job:U0000000008135
12:02:43 Done Scheduling job:U0000000008135 sending job to queue SaveLoad
12:02:43 Scheduling new unfirm job:U0000000007927
12:02:43 Done Scheduling job:U0000000007927 sending job to queue SaveLoad
12:02:43 Scheduling new unfirm job:U0000000007928
12:02:43 Done Scheduling job:U0000000007928 sending job to queue SaveLoad
12:02:43 Scheduling new unfirm job:U0000000008118
12:02:44 Done Scheduling job:U0000000008118 sending job to queue SaveLoad
12:02:44 Scheduling new unfirm job:U0000000008138
12:02:44 Done Scheduling job:U0000000008138 sending job to queue SaveLoad
12:02:44 Scheduling new unfirm job:U0000000008119
12:02:45 Done Scheduling job:U0000000008119 sending job to queue SaveLoad
12:02:45 Scheduling new unfirm job:U0000000008120
12:02:45 Done Scheduling job:U0000000008120 sending job to queue SaveLoad
12:02:45 Scheduling new unfirm job:U0000000007930
12:02:45 Done Scheduling job:U0000000007930 sending job to queue SaveLoad
12:02:45 Scheduling new unfirm job:U0000000008139
12:02:47 Done Scheduling job:U0000000008139 sending job to queue SaveLoad
12:02:47 Scheduling new unfirm job:U0000000007931
12:02:48 Done Scheduling job:U0000000007931 sending job to queue SaveLoad
12:02:48 Scheduling new unfirm job:U0000000008140
12:02:49 Done Scheduling job:U0000000008140 sending job to queue SaveLoad
12:02:49 Scheduling new unfirm job:U0000000007932
12:02:50 Done Scheduling job:U0000000007932 sending job to queue SaveLoad
12:02:50 Scheduling new unfirm job:U0000000008141
12:02:51 Done Scheduling job:U0000000008141 sending job to queue SaveLoad
12:02:51 Scheduling new unfirm job:U0000000008025
12:02:52 Done Scheduling job:U0000000008025 sending job to queue SaveLoad
12:02:52 Scheduling new unfirm job:U0000000007933
12:02:53 Done Scheduling job:U0000000007933 sending job to queue SaveLoad
12:02:53 Scheduling new unfirm job:U0000000008142
12:02:53 Done Scheduling job:U0000000008142 sending job to queue SaveLoad
12:02:53 Scheduling new unfirm job:U0000000008026
12:02:54 Done Scheduling job:U0000000008026 sending job to queue SaveLoad
12:02:54 Scheduling new unfirm job:U0000000008027
12:02:55 Done Scheduling job:U0000000008027 sending job to queue SaveLoad
12:02:55 Scheduling new unfirm job:U0000000008028
12:02:56 Done Scheduling job:U0000000008028 sending job to queue SaveLoad
12:02:56 Scheduling new unfirm job:U0000000008143
12:02:57 Done Scheduling job:U0000000008143 sending job to queue SaveLoad
12:02:57 Scheduling new unfirm job:U0000000008029
12:02:58 Done Scheduling job:U0000000008029 sending job to queue SaveLoad
12:02:58 Scheduling new unfirm job:U0000000007934
12:02:58 Done Scheduling job:U0000000007934 sending job to queue SaveLoad
12:02:58 Scheduling new unfirm job:U0000000008148
12:02:59 Done Scheduling job:U0000000008148 sending job to queue SaveLoad
12:02:59 Scheduling new unfirm job:U0000000008149
12:02:59 Done Scheduling job:U0000000008149 sending job to queue SaveLoad
12:02:59 Scheduling new unfirm job:U0000000008150
12:03:00 Done Scheduling job:U0000000008150 sending job to queue SaveLoad
12:03:00 Scheduling new unfirm job:U0000000008151
12:03:00 Done Scheduling job:U0000000008151 sending job to queue SaveLoad
12:03:00 Scheduling new unfirm job:U0000000007947
12:03:02 Done Scheduling job:U0000000007947 sending job to queue SaveLoad
12:03:02 Scheduling new unfirm job:U0000000008155
12:03:03 Done Scheduling job:U0000000008155 sending job to queue SaveLoad
12:03:03 Scheduling new unfirm job:U0000000008147
12:03:03 Done Scheduling job:U0000000008147 sending job to queue SaveLoad
12:03:03 Scheduling new unfirm job:U0000000007939
12:03:04 Done Scheduling job:U0000000007939 sending job to queue SaveLoad
12:03:04 Scheduling new unfirm job:U0000000007950
12:03:05 Done Scheduling job:U0000000007950 sending job to queue SaveLoad
12:03:05 Scheduling new unfirm job:U0000000008040
12:03:07 Done Scheduling job:U0000000008040 sending job to queue SaveLoad
12:03:07 Scheduling new unfirm job:U0000000008041
12:03:08 Done Scheduling job:U0000000008041 sending job to queue SaveLoad
12:03:08 Scheduling new unfirm job:U0000000008042
12:03:09 Done Scheduling job:U0000000008042 sending job to queue SaveLoad
12:03:09 Scheduling new unfirm job:U0000000008043
12:03:10 Done Scheduling job:U0000000008043 sending job to queue SaveLoad
12:03:10 Scheduling new unfirm job:U0000000008044
12:03:11 Done Scheduling job:U0000000008044 sending job to queue SaveLoad
12:03:11 Scheduling new unfirm job:U0000000008045
12:03:12 Done Scheduling job:U0000000008045 sending job to queue SaveLoad
12:03:12 Scheduling new unfirm job:U0000000008046
12:03:14 Done Scheduling job:U0000000008046 sending job to queue SaveLoad
12:03:14 Scheduling new unfirm job:U0000000008161
12:03:16 Done Scheduling job:U0000000008161 sending job to queue SaveLoad
12:03:16 Scheduling new unfirm job:U0000000007955
12:03:18 Done Scheduling job:U0000000007955 sending job to queue SaveLoad
12:03:18 Scheduling new unfirm job:U0000000007957
12:03:18 Done Scheduling job:U0000000007957 sending job to queue SaveLoad
12:03:18 Scheduling new unfirm job:U0000000008052
12:03:20 Done Scheduling job:U0000000008052 sending job to queue SaveLoad
12:03:20 Scheduling new unfirm job:U0000000008164
12:03:21 Done Scheduling job:U0000000008164 sending job to queue SaveLoad
12:03:21 Scheduling new unfirm job:U0000000007958
12:03:23 Done Scheduling job:U0000000007958 sending job to queue SaveLoad
12:03:23 Scheduling new unfirm job:U0000000008053
12:03:24 Done Scheduling job:U0000000008053 sending job to queue SaveLoad
12:03:24 Scheduling new unfirm job:U0000000008166
12:03:26 Done Scheduling job:U0000000008166 sending job to queue SaveLoad
12:03:26 Scheduling new unfirm job:U0000000008167
12:03:27 Done Scheduling job:U0000000008167 sending job to queue SaveLoad
12:03:27 Scheduling new unfirm job:U0000000008168
12:03:29 Done Scheduling job:U0000000008168 sending job to queue SaveLoad
12:03:29 Scheduling new unfirm job:U0000000007961
12:03:30 Done Scheduling job:U0000000007961 sending job to queue SaveLoad
12:03:30 Scheduling new unfirm job:U0000000008056
12:03:31 Done Scheduling job:U0000000008056 sending job to queue SaveLoad
12:03:31 Scheduling new unfirm job:U0000000008057
12:03:32 Done Scheduling job:U0000000008057 sending job to queue SaveLoad
12:03:32 Scheduling new unfirm job:U0000000008064
12:03:33 Done Scheduling job:U0000000008064 sending job to queue SaveLoad
12:03:33 Scheduling new unfirm job:U0000000008065
12:03:34 Done Scheduling job:U0000000008065 sending job to queue SaveLoad
12:03:34 Scheduling new unfirm job:U0000000008179
12:03:36 Done Scheduling job:U0000000008179 sending job to queue SaveLoad
12:03:36 Scheduling new unfirm job:U0000000008180
12:03:37 Done Scheduling job:U0000000008180 sending job to queue SaveLoad
12:03:37 Scheduling new unfirm job:U0000000008372
12:03:38 Done Scheduling job:U0000000008372 sending job to queue SaveLoad
12:03:38 Scheduling new unfirm job:U0000000008181
12:03:40 Done Scheduling job:U0000000008181 sending job to queue SaveLoad
12:03:40 Scheduling new unfirm job:U0000000008270
12:03:40 Done Scheduling job:U0000000008270 sending job to queue SaveLoad
12:03:40 Scheduling new unfirm job:U0000000008271
12:03:41 Done Scheduling job:U0000000008271 sending job to queue SaveLoad
12:03:41 Scheduling new unfirm job:U0000000008272
12:03:42 Done Scheduling job:U0000000008272 sending job to queue SaveLoad
12:03:42 Scheduling new unfirm job:U0000000008373
12:03:43 Part MMP-05028 has a receive time of 3 days and will be available January 30 2026.  It will not meet its required date of January 29 2026. 
12:03:43 Done Scheduling job:U0000000008373 sending job to queue SaveLoad
12:03:43 Scheduling new unfirm job:U0000000008182
12:03:45 Part MMP-05029 has a receive time of 3 days and will be available January 30 2026.  It will not meet its required date of January 29 2026. 
12:03:45 Done Scheduling job:U0000000008182 sending job to queue SaveLoad
12:03:45 Scheduling new unfirm job:U0000000008273
12:03:45 Done Scheduling job:U0000000008273 sending job to queue SaveLoad
12:03:46 Scheduling new unfirm job:U0000000008274
12:03:46 Done Scheduling job:U0000000008274 sending job to queue SaveLoad
12:03:46 Scheduling new unfirm job:U0000000008376
12:03:48 Done Scheduling job:U0000000008376 sending job to queue SaveLoad
12:03:48 Scheduling new unfirm job:U0000000008185
12:03:49 Part MMP-05168 has a receive time of 3 days and will be available February 2 2026.  It will not meet its required date of January 28 2026. 
12:03:49 Done Scheduling job:U0000000008185 sending job to queue SaveLoad
12:03:49 Scheduling new unfirm job:U0000000008186
12:03:49 Done Scheduling job:U0000000008186 sending job to queue SaveLoad
12:03:49 Scheduling new unfirm job:U0000000008379
12:03:50 Done Scheduling job:U0000000008379 sending job to queue SaveLoad
12:03:50 Scheduling new unfirm job:U0000000008380
12:03:50 Done Scheduling job:U0000000008380 sending job to queue SaveLoad
12:03:50 Scheduling new unfirm job:U0000000008381
12:03:51 Done Scheduling job:U0000000008381 sending job to queue SaveLoad
12:03:51 Scheduling new unfirm job:U0000000008190
12:03:51 Done Scheduling job:U0000000008190 sending job to queue SaveLoad
12:03:51 Scheduling new unfirm job:U0000000008191
12:03:51 Done Scheduling job:U0000000008191 sending job to queue SaveLoad
12:03:51 Scheduling new unfirm job:U0000000008192
12:03:52 Done Scheduling job:U0000000008192 sending job to queue SaveLoad
12:03:52 Scheduling new unfirm job:U0000000008193
12:03:52 Done Scheduling job:U0000000008193 sending job to queue SaveLoad
12:03:52 Scheduling new unfirm job:U0000000008194
12:03:52 Done Scheduling job:U0000000008194 sending job to queue SaveLoad
12:03:52 Scheduling new unfirm job:U0000000008195
12:03:53 Done Scheduling job:U0000000008195 sending job to queue SaveLoad
12:03:53 Scheduling new unfirm job:U0000000008288
12:03:53 Done Scheduling job:U0000000008288 sending job to queue SaveLoad
12:03:53 Scheduling new unfirm job:U0000000008196
12:03:54 Done Scheduling job:U0000000008196 sending job to queue SaveLoad
12:03:54 Scheduling new unfirm job:U0000000008289
12:03:54 Done Scheduling job:U0000000008289 sending job to queue SaveLoad
12:03:54 Scheduling new unfirm job:U0000000008290
12:03:55 Done Scheduling job:U0000000008290 sending job to queue SaveLoad
12:03:55 Scheduling new unfirm job:U0000000008291
12:03:55 Done Scheduling job:U0000000008291 sending job to queue SaveLoad
12:03:55 Scheduling new unfirm job:U0000000008292
12:03:56 Done Scheduling job:U0000000008292 sending job to queue SaveLoad
12:03:56 Scheduling new unfirm job:U0000000008197
12:03:57 Done Scheduling job:U0000000008197 sending job to queue SaveLoad
12:03:57 Scheduling new unfirm job:U0000000008198
12:03:58 Done Scheduling job:U0000000008198 sending job to queue SaveLoad
12:03:58 Scheduling new unfirm job:U0000000008293
12:03:59 Done Scheduling job:U0000000008293 sending job to queue SaveLoad
12:03:59 Scheduling new unfirm job:U0000000008199
12:04:00 Done Scheduling job:U0000000008199 sending job to queue SaveLoad
12:04:00 Scheduling new unfirm job:U0000000008294
12:04:00 Done Scheduling job:U0000000008294 sending job to queue SaveLoad
12:04:00 Scheduling new unfirm job:U0000000008384
12:04:02 Done Scheduling job:U0000000008384 sending job to queue SaveLoad
12:04:02 Scheduling new unfirm job:U0000000008385
12:04:04 Done Scheduling job:U0000000008385 sending job to queue SaveLoad
12:04:04 Scheduling new unfirm job:U0000000008386
12:04:05 Done Scheduling job:U0000000008386 sending job to queue SaveLoad
12:04:05 Scheduling new unfirm job:U0000000008387
12:04:06 Done Scheduling job:U0000000008387 sending job to queue SaveLoad
12:04:06 Scheduling new unfirm job:U0000000008388
12:04:07 Done Scheduling job:U0000000008388 sending job to queue SaveLoad
12:04:07 Scheduling new unfirm job:U0000000008389
12:04:09 Done Scheduling job:U0000000008389 sending job to queue SaveLoad
12:04:09 Scheduling new unfirm job:U0000000008390
12:04:10 Done Scheduling job:U0000000008390 sending job to queue SaveLoad
12:04:10 Scheduling new unfirm job:U0000000008391
12:04:11 Done Scheduling job:U0000000008391 sending job to queue SaveLoad
12:04:11 Scheduling new unfirm job:U0000000008302
12:04:12 Done Scheduling job:U0000000008302 sending job to queue SaveLoad
12:04:12 Scheduling new unfirm job:U0000000008200
12:04:13 Done Scheduling job:U0000000008200 sending job to queue SaveLoad
12:04:13 Scheduling new unfirm job:U0000000008303
12:04:13 Done Scheduling job:U0000000008303 sending job to queue SaveLoad
12:04:13 Scheduling new unfirm job:U0000000008201
12:04:14 Done Scheduling job:U0000000008201 sending job to queue SaveLoad
12:04:14 Scheduling new unfirm job:U0000000008395
12:04:15 Done Scheduling job:U0000000008395 sending job to queue SaveLoad
12:04:15 Scheduling new unfirm job:U0000000008304
12:04:16 Part WHS-00646 has a receive time of 3 days and will be available January 21 2026.  It will not meet its required date of January 19 2026. 
12:04:16 Done Scheduling job:U0000000008304 sending job to queue SaveLoad
12:04:16 Scheduling new unfirm job:U0000000008202
12:04:16 Done Scheduling job:U0000000008202 sending job to queue SaveLoad
12:04:16 Scheduling new unfirm job:U0000000008305
12:04:17 Done Scheduling job:U0000000008305 sending job to queue SaveLoad
12:04:17 Scheduling new unfirm job:U0000000008203
12:04:18 Done Scheduling job:U0000000008203 sending job to queue SaveLoad
12:04:18 Scheduling new unfirm job:U0000000008396
12:04:19 Done Scheduling job:U0000000008396 sending job to queue SaveLoad
12:04:19 Scheduling new unfirm job:U0000000008397
12:04:20 Done Scheduling job:U0000000008397 sending job to queue SaveLoad
12:04:20 Scheduling new unfirm job:U0000000008310
12:04:21 Done Scheduling job:U0000000008310 sending job to queue SaveLoad
12:04:21 Scheduling new unfirm job:U0000000008311
12:04:21 Done Scheduling job:U0000000008311 sending job to queue SaveLoad
12:04:21 Scheduling new unfirm job:U0000000008314
12:04:22 Done Scheduling job:U0000000008314 sending job to queue SaveLoad
12:04:22 Scheduling new unfirm job:U0000000008316
12:04:23 Done Scheduling job:U0000000008316 sending job to queue SaveLoad
12:04:23 Scheduling new unfirm job:U0000000008317
12:04:24 Done Scheduling job:U0000000008317 sending job to queue SaveLoad
12:04:24 Scheduling new unfirm job:U0000000008312
12:04:24 Done Scheduling job:U0000000008312 sending job to queue SaveLoad
12:04:24 Scheduling new unfirm job:U0000000008313
12:04:25 Done Scheduling job:U0000000008313 sending job to queue SaveLoad
12:04:25 Scheduling new unfirm job:U0000000008405
12:04:25 Done Scheduling job:U0000000008405 sending job to queue SaveLoad
12:04:25 Scheduling new unfirm job:U0000000008407
12:04:26 Done Scheduling job:U0000000008407 sending job to queue SaveLoad
12:04:26 Scheduling new unfirm job:U0000000008315
12:04:27 Done Scheduling job:U0000000008315 sending job to queue SaveLoad
12:04:27 Scheduling new unfirm job:U0000000008212
12:04:27 Done Scheduling job:U0000000008212 sending job to queue SaveLoad
12:04:27 Scheduling new unfirm job:U0000000008213
12:04:28 Done Scheduling job:U0000000008213 sending job to queue SaveLoad
12:04:28 Scheduling new unfirm job:U0000000008214
12:04:28 Done Scheduling job:U0000000008214 sending job to queue SaveLoad
12:04:28 Scheduling new unfirm job:U0000000008215
12:04:29 Done Scheduling job:U0000000008215 sending job to queue SaveLoad
12:04:29 Scheduling new unfirm job:U0000000008216
12:04:29 Done Scheduling job:U0000000008216 sending job to queue SaveLoad
12:04:29 Scheduling new unfirm job:U0000000008217
12:04:30 Done Scheduling job:U0000000008217 sending job to queue SaveLoad
12:04:30 Scheduling new unfirm job:U0000000008218
12:04:31 Done Scheduling job:U0000000008218 sending job to queue SaveLoad
12:04:31 Scheduling new unfirm job:U0000000008219
12:04:31 Done Scheduling job:U0000000008219 sending job to queue SaveLoad
12:04:31 Scheduling new unfirm job:U0000000008220
12:04:32 Done Scheduling job:U0000000008220 sending job to queue SaveLoad
12:04:32 Scheduling new unfirm job:U0000000008410
12:04:33 Done Scheduling job:U0000000008410 sending job to queue SaveLoad
12:04:33 Scheduling new unfirm job:U0000000008411
12:04:33 Done Scheduling job:U0000000008411 sending job to queue SaveLoad
12:04:33 Scheduling new unfirm job:U0000000008412
12:04:34 Done Scheduling job:U0000000008412 sending job to queue SaveLoad
12:04:34 Scheduling new unfirm job:U0000000008413
12:04:35 Done Scheduling job:U0000000008413 sending job to queue SaveLoad
12:04:35 Scheduling new unfirm job:U0000000008414
12:04:36 Done Scheduling job:U0000000008414 sending job to queue SaveLoad
12:04:36 Scheduling new unfirm job:U0000000008415
12:04:37 Done Scheduling job:U0000000008415 sending job to queue SaveLoad
12:04:37 Scheduling new unfirm job:U0000000008416
12:04:38 Done Scheduling job:U0000000008416 sending job to queue SaveLoad
12:04:38 Scheduling new unfirm job:U0000000008417
12:04:38 Done Scheduling job:U0000000008417 sending job to queue SaveLoad
12:04:38 Scheduling new unfirm job:U0000000008418
12:04:39 Done Scheduling job:U0000000008418 sending job to queue SaveLoad
12:04:47 Scheduling new unfirm job:U0000000008432
12:04:48 Done Scheduling job:U0000000008432 sending job to queue SaveLoad
12:05:04 Ending Part Level: 2-0.  Wait Time 00h:02m:53s, Jobs 201
12:05:04 Starting Part Level: 3-0.
12:05:04 Scheduling new unfirm job:U0000000008435
12:05:05 Done Scheduling job:U0000000008435 sending job to queue SaveLoad
12:05:05 Scheduling new unfirm job:U0000000008318
12:05:06 Done Scheduling job:U0000000008318 sending job to queue SaveLoad
12:05:06 Scheduling new unfirm job:U0000000008436
12:05:06 Done Scheduling job:U0000000008436 sending job to queue SaveLoad
12:05:06 Scheduling new unfirm job:U0000000008319
12:05:07 Done Scheduling job:U0000000008319 sending job to queue SaveLoad
12:05:07 Scheduling new unfirm job:U0000000008437
12:05:07 Done Scheduling job:U0000000008437 sending job to queue SaveLoad
12:05:07 Scheduling new unfirm job:U0000000008438
12:05:08 Done Scheduling job:U0000000008438 sending job to queue SaveLoad
12:05:08 Scheduling new unfirm job:U0000000008439
12:05:08 Done Scheduling job:U0000000008439 sending job to queue SaveLoad
12:05:08 Scheduling new unfirm job:U0000000008440
12:05:09 Done Scheduling job:U0000000008440 sending job to queue SaveLoad
12:05:09 Scheduling new unfirm job:U0000000008325
12:05:09 Done Scheduling job:U0000000008325 sending job to queue SaveLoad
12:05:09 Scheduling new unfirm job:U0000000008441
12:05:10 Done Scheduling job:U0000000008441 sending job to queue SaveLoad
12:05:10 Scheduling new unfirm job:U0000000008326
12:05:10 Done Scheduling job:U0000000008326 sending job to queue SaveLoad
12:05:10 Scheduling new unfirm job:U0000000008442
12:05:11 Done Scheduling job:U0000000008442 sending job to queue SaveLoad
12:05:11 Scheduling new unfirm job:U0000000008327
12:05:11 Done Scheduling job:U0000000008327 sending job to queue SaveLoad
12:05:11 Scheduling new unfirm job:U0000000008443
12:05:12 Done Scheduling job:U0000000008443 sending job to queue SaveLoad
12:05:12 Scheduling new unfirm job:U0000000008240
12:05:13 Done Scheduling job:U0000000008240 sending job to queue SaveLoad
12:05:13 Scheduling new unfirm job:U0000000008330
12:05:13 Done Scheduling job:U0000000008330 sending job to queue SaveLoad
12:05:13 Scheduling new unfirm job:U0000000008241
12:05:14 Done Scheduling job:U0000000008241 sending job to queue SaveLoad
12:05:14 Scheduling new unfirm job:U0000000008332
12:05:15 Done Scheduling job:U0000000008332 sending job to queue SaveLoad
12:05:15 Scheduling new unfirm job:U0000000008447
12:05:15 Done Scheduling job:U0000000008447 sending job to queue SaveLoad
12:05:15 Scheduling new unfirm job:U0000000008333
12:05:16 Done Scheduling job:U0000000008333 sending job to queue SaveLoad
12:05:16 Scheduling new unfirm job:U0000000008450
12:05:16 Done Scheduling job:U0000000008450 sending job to queue SaveLoad
12:05:16 Scheduling new unfirm job:U0000000008451
12:05:17 Done Scheduling job:U0000000008451 sending job to queue SaveLoad
12:05:17 Scheduling new unfirm job:U0000000008335
12:05:18 Done Scheduling job:U0000000008335 sending job to queue SaveLoad
12:05:18 Scheduling new unfirm job:U0000000008449
12:05:18 Done Scheduling job:U0000000008449 sending job to queue SaveLoad
12:05:18 Scheduling new unfirm job:U0000000008336
12:05:19 Done Scheduling job:U0000000008336 sending job to queue SaveLoad
12:05:19 Scheduling new unfirm job:U0000000008337
12:05:19 Done Scheduling job:U0000000008337 sending job to queue SaveLoad
12:05:19 Scheduling new unfirm job:U0000000008338
12:05:20 Done Scheduling job:U0000000008338 sending job to queue SaveLoad
12:05:20 Scheduling new unfirm job:U0000000008247
12:05:21 Done Scheduling job:U0000000008247 sending job to queue SaveLoad
12:05:21 Scheduling new unfirm job:U0000000008249
12:05:21 Done Scheduling job:U0000000008249 sending job to queue SaveLoad
12:05:21 Scheduling new unfirm job:U0000000008339
12:05:22 Done Scheduling job:U0000000008339 sending job to queue SaveLoad
12:05:22 Scheduling new unfirm job:U0000000008340
12:05:23 Done Scheduling job:U0000000008340 sending job to queue SaveLoad
12:05:23 Scheduling new unfirm job:U0000000008341
12:05:24 Done Scheduling job:U0000000008341 sending job to queue SaveLoad
12:05:24 Scheduling new unfirm job:U0000000008342
12:05:24 Done Scheduling job:U0000000008342 sending job to queue SaveLoad
12:05:24 Scheduling new unfirm job:U0000000008343
12:05:25 Done Scheduling job:U0000000008343 sending job to queue SaveLoad
12:05:25 Scheduling new unfirm job:U0000000008460
12:05:25 Done Scheduling job:U0000000008460 sending job to queue SaveLoad
12:05:25 Scheduling new unfirm job:U0000000008465
12:05:26 Done Scheduling job:U0000000008465 sending job to queue SaveLoad
12:05:26 Scheduling new unfirm job:U0000000008258
12:05:26 Done Scheduling job:U0000000008258 sending job to queue SaveLoad
12:05:26 Scheduling new unfirm job:U0000000008252
12:05:27 Done Scheduling job:U0000000008252 sending job to queue SaveLoad
12:05:27 Scheduling new unfirm job:U0000000008259
12:05:27 Done Scheduling job:U0000000008259 sending job to queue SaveLoad
12:05:27 Scheduling new unfirm job:U0000000008260
12:05:28 Done Scheduling job:U0000000008260 sending job to queue SaveLoad
12:05:28 Scheduling new unfirm job:U0000000008255
12:05:28 Done Scheduling job:U0000000008255 sending job to queue SaveLoad
12:05:28 Scheduling new unfirm job:U0000000008344
12:05:29 Done Scheduling job:U0000000008344 sending job to queue SaveLoad
12:05:29 Scheduling new unfirm job:U0000000008345
12:05:29 Done Scheduling job:U0000000008345 sending job to queue SaveLoad
12:05:29 Scheduling new unfirm job:U0000000008257
12:05:30 Done Scheduling job:U0000000008257 sending job to queue SaveLoad
12:05:30 Scheduling new unfirm job:U0000000008347
12:05:30 Done Scheduling job:U0000000008347 sending job to queue SaveLoad
12:05:30 Scheduling new unfirm job:U0000000008466
12:05:31 Done Scheduling job:U0000000008466 sending job to queue SaveLoad
12:05:31 Scheduling new unfirm job:U0000000008348
12:05:31 Done Scheduling job:U0000000008348 sending job to queue SaveLoad
12:05:31 Scheduling new unfirm job:U0000000008349
12:05:32 Done Scheduling job:U0000000008349 sending job to queue SaveLoad
12:05:32 Scheduling new unfirm job:U0000000008350
12:05:32 Done Scheduling job:U0000000008350 sending job to queue SaveLoad
12:05:34 Scheduling new unfirm job:U0000000008351
12:05:35 Done Scheduling job:U0000000008351 sending job to queue SaveLoad
12:05:35 Scheduling new unfirm job:U0000000008471
12:05:35 Done Scheduling job:U0000000008471 sending job to queue SaveLoad
12:05:35 Scheduling new unfirm job:U0000000008352
12:05:36 Done Scheduling job:U0000000008352 sending job to queue SaveLoad
12:05:36 Scheduling new unfirm job:U0000000008472
12:05:36 Done Scheduling job:U0000000008472 sending job to queue SaveLoad
12:05:36 Scheduling new unfirm job:U0000000008261
12:05:37 Done Scheduling job:U0000000008261 sending job to queue SaveLoad
12:05:37 Scheduling new unfirm job:U0000000008262
12:05:37 Done Scheduling job:U0000000008262 sending job to queue SaveLoad
12:05:37 Scheduling new unfirm job:U0000000008263
12:05:38 Done Scheduling job:U0000000008263 sending job to queue SaveLoad
12:05:38 Scheduling new unfirm job:U0000000008264
12:05:39 Done Scheduling job:U0000000008264 sending job to queue SaveLoad
12:05:39 Scheduling new unfirm job:U0000000008265
12:05:39 Done Scheduling job:U0000000008265 sending job to queue SaveLoad
12:05:39 Scheduling new unfirm job:U0000000008266
12:05:40 Done Scheduling job:U0000000008266 sending job to queue SaveLoad
12:05:40 Scheduling new unfirm job:U0000000008267
12:05:41 Done Scheduling job:U0000000008267 sending job to queue SaveLoad
12:05:41 Scheduling new unfirm job:U0000000008568
12:05:41 Done Scheduling job:U0000000008568 sending job to queue SaveLoad
12:05:41 Scheduling new unfirm job:U0000000008569
12:05:42 Done Scheduling job:U0000000008569 sending job to queue SaveLoad
12:05:42 Scheduling new unfirm job:U0000000008570
12:05:43 Done Scheduling job:U0000000008570 sending job to queue SaveLoad
12:05:43 Scheduling new unfirm job:U0000000008571
12:05:43 Done Scheduling job:U0000000008571 sending job to queue SaveLoad
12:05:43 Scheduling new unfirm job:U0000000008572
12:05:44 Done Scheduling job:U0000000008572 sending job to queue SaveLoad
12:05:44 Scheduling new unfirm job:U0000000008573
12:05:45 Done Scheduling job:U0000000008573 sending job to queue SaveLoad
12:05:45 Scheduling new unfirm job:U0000000008574
12:05:45 Done Scheduling job:U0000000008574 sending job to queue SaveLoad
12:05:45 Scheduling new unfirm job:U0000000008575
12:05:46 Done Scheduling job:U0000000008575 sending job to queue SaveLoad
12:05:46 Scheduling new unfirm job:U0000000008576
12:05:47 Done Scheduling job:U0000000008576 sending job to queue SaveLoad
12:05:47 Scheduling new unfirm job:U0000000008577
12:05:47 Done Scheduling job:U0000000008577 sending job to queue SaveLoad
12:05:47 Scheduling new unfirm job:U0000000008578
12:05:48 Done Scheduling job:U0000000008578 sending job to queue SaveLoad
12:05:48 Scheduling new unfirm job:U0000000008579
12:05:49 Done Scheduling job:U0000000008579 sending job to queue SaveLoad
12:05:49 Scheduling new unfirm job:U0000000008366
12:05:49 Done Scheduling job:U0000000008366 sending job to queue SaveLoad
12:05:49 Scheduling new unfirm job:U0000000008486
12:05:50 Done Scheduling job:U0000000008486 sending job to queue SaveLoad
12:05:50 Scheduling new unfirm job:U0000000008487
12:05:50 Done Scheduling job:U0000000008487 sending job to queue SaveLoad
12:05:50 Scheduling new unfirm job:U0000000008488
12:05:51 Done Scheduling job:U0000000008488 sending job to queue SaveLoad
12:05:51 Scheduling new unfirm job:U0000000008591
12:05:51 Done Scheduling job:U0000000008591 sending job to queue SaveLoad
12:05:51 Scheduling new unfirm job:U0000000008489
12:05:52 Done Scheduling job:U0000000008489 sending job to queue SaveLoad
12:05:52 Scheduling new unfirm job:U0000000008681
12:05:52 Done Scheduling job:U0000000008681 sending job to queue SaveLoad
12:05:52 Scheduling new unfirm job:U0000000008490
12:05:53 Done Scheduling job:U0000000008490 sending job to queue SaveLoad
12:05:53 Scheduling new unfirm job:U0000000008491
12:05:54 Done Scheduling job:U0000000008491 sending job to queue SaveLoad
12:05:54 Scheduling new unfirm job:U0000000008593
12:05:54 Done Scheduling job:U0000000008593 sending job to queue SaveLoad
12:05:54 Scheduling new unfirm job:U0000000008492
12:05:55 Done Scheduling job:U0000000008492 sending job to queue SaveLoad
12:05:55 Scheduling new unfirm job:U0000000008683
12:05:56 Done Scheduling job:U0000000008683 sending job to queue SaveLoad
12:05:56 Scheduling new unfirm job:U0000000008493
12:05:57 Done Scheduling job:U0000000008493 sending job to queue SaveLoad
12:05:57 Scheduling new unfirm job:U0000000008594
12:05:57 Done Scheduling job:U0000000008594 sending job to queue SaveLoad
12:05:57 Scheduling new unfirm job:U0000000008494
12:05:58 Done Scheduling job:U0000000008494 sending job to queue SaveLoad
12:05:58 Scheduling new unfirm job:U0000000008495
12:05:59 Done Scheduling job:U0000000008495 sending job to queue SaveLoad
12:05:59 Scheduling new unfirm job:U0000000008496
12:06:00 Done Scheduling job:U0000000008496 sending job to queue SaveLoad
12:06:00 Scheduling new unfirm job:U0000000008684
12:06:00 Done Scheduling job:U0000000008684 sending job to queue SaveLoad
12:06:00 Scheduling new unfirm job:U0000000008596
12:06:01 Done Scheduling job:U0000000008596 sending job to queue SaveLoad
12:06:01 Scheduling new unfirm job:U0000000008497
12:06:01 Done Scheduling job:U0000000008497 sending job to queue SaveLoad
12:06:01 Scheduling new unfirm job:U0000000008498
12:06:02 Done Scheduling job:U0000000008498 sending job to queue SaveLoad
12:06:02 Scheduling new unfirm job:U0000000008688
12:06:02 Done Scheduling job:U0000000008688 sending job to queue SaveLoad
12:06:02 Scheduling new unfirm job:U0000000008501
12:06:03 Done Scheduling job:U0000000008501 sending job to queue SaveLoad
12:06:03 Scheduling new unfirm job:U0000000008597
12:06:03 Done Scheduling job:U0000000008597 sending job to queue SaveLoad
12:06:03 Scheduling new unfirm job:U0000000008502
12:06:04 Done Scheduling job:U0000000008502 sending job to queue SaveLoad
12:06:04 Scheduling new unfirm job:U0000000008603
12:06:04 Done Scheduling job:U0000000008603 sending job to queue SaveLoad
12:06:04 Scheduling new unfirm job:U0000000008600
12:06:04 Done Scheduling job:U0000000008600 sending job to queue SaveLoad
12:06:04 Scheduling new unfirm job:U0000000008601
12:06:05 Done Scheduling job:U0000000008601 sending job to queue SaveLoad
12:06:05 Scheduling new unfirm job:U0000000008602
12:06:05 Done Scheduling job:U0000000008602 sending job to queue SaveLoad
12:06:05 Scheduling new unfirm job:U0000000008604
12:06:05 Done Scheduling job:U0000000008604 sending job to queue SaveLoad
12:06:05 Scheduling new unfirm job:U0000000008690
12:06:06 Done Scheduling job:U0000000008690 sending job to queue SaveLoad
12:06:06 Scheduling new unfirm job:U0000000008506
12:06:06 Done Scheduling job:U0000000008506 sending job to queue SaveLoad
12:06:06 Scheduling new unfirm job:U0000000008606
12:06:07 Done Scheduling job:U0000000008606 sending job to queue SaveLoad
12:06:07 Scheduling new unfirm job:U0000000008607
12:06:07 Done Scheduling job:U0000000008607 sending job to queue SaveLoad
12:06:07 Scheduling new unfirm job:U0000000008508
12:06:07 Done Scheduling job:U0000000008508 sending job to queue SaveLoad
12:06:07 Scheduling new unfirm job:U0000000008608
12:06:08 Done Scheduling job:U0000000008608 sending job to queue SaveLoad
12:06:08 Scheduling new unfirm job:U0000000008509
12:06:08 Done Scheduling job:U0000000008509 sending job to queue SaveLoad
12:06:08 Scheduling new unfirm job:U0000000008510
12:06:09 Done Scheduling job:U0000000008510 sending job to queue SaveLoad
12:06:09 Scheduling new unfirm job:U0000000008610
12:06:09 Done Scheduling job:U0000000008610 sending job to queue SaveLoad
12:06:09 Scheduling new unfirm job:U0000000008511
12:06:09 Done Scheduling job:U0000000008511 sending job to queue SaveLoad
12:06:09 Scheduling new unfirm job:U0000000008695
12:06:10 Done Scheduling job:U0000000008695 sending job to queue SaveLoad
12:06:10 Scheduling new unfirm job:U0000000008513
12:06:11 Done Scheduling job:U0000000008513 sending job to queue SaveLoad
12:06:11 Scheduling new unfirm job:U0000000008611
12:06:11 Done Scheduling job:U0000000008611 sending job to queue SaveLoad
12:06:11 Scheduling new unfirm job:U0000000008514
12:06:12 Done Scheduling job:U0000000008514 sending job to queue SaveLoad
12:06:12 Scheduling new unfirm job:U0000000008517
12:06:13 Done Scheduling job:U0000000008517 sending job to queue SaveLoad
12:06:13 Scheduling new unfirm job:U0000000008698
12:06:15 Done Scheduling job:U0000000008698 sending job to queue SaveLoad
12:06:15 Scheduling new unfirm job:U0000000008699
12:06:16 Done Scheduling job:U0000000008699 sending job to queue SaveLoad
12:06:18 Scheduling new unfirm job:U0000000008615
12:06:19 Done Scheduling job:U0000000008615 sending job to queue SaveLoad
12:06:19 Scheduling new unfirm job:U0000000008700
12:06:21 Done Scheduling job:U0000000008700 sending job to queue SaveLoad
12:06:21 Scheduling new unfirm job:U0000000008618
12:06:22 Done Scheduling job:U0000000008618 sending job to queue SaveLoad
12:06:22 Scheduling new unfirm job:U0000000008619
12:06:23 Done Scheduling job:U0000000008619 sending job to queue SaveLoad
12:06:23 Scheduling new unfirm job:U0000000008703
12:06:24 Done Scheduling job:U0000000008703 sending job to queue SaveLoad
12:06:24 Scheduling new unfirm job:U0000000008705
12:06:25 Done Scheduling job:U0000000008705 sending job to queue SaveLoad
12:06:25 Scheduling new unfirm job:U0000000008706
12:06:26 Done Scheduling job:U0000000008706 sending job to queue SaveLoad
12:06:26 Scheduling new unfirm job:U0000000008518
12:06:27 Part MMP-01755 has a receive time of 3 days and will be available January 28 2026.  It will not meet its required date of January 15 2026. 
12:06:27 Done Scheduling job:U0000000008518 sending job to queue SaveLoad
12:06:27 Scheduling new unfirm job:U0000000008519
12:06:27 Part MMP-01755 has a receive time of 3 days and will be available January 28 2026.  It will not meet its required date of January 16 2026. 
12:06:27 Done Scheduling job:U0000000008519 sending job to queue SaveLoad
12:06:28 Scheduling new unfirm job:U0000000008520
12:06:28 Part MMP-01755 has a receive time of 3 days and will be available January 28 2026.  It will not meet its required date of January 19 2026. 
12:06:28 Done Scheduling job:U0000000008520 sending job to queue SaveLoad
12:06:28 Scheduling new unfirm job:U0000000008521
12:06:29 Part MMP-01755 has a receive time of 3 days and will be available January 28 2026.  It will not meet its required date of January 20 2026. 
12:06:29 Done Scheduling job:U0000000008521 sending job to queue SaveLoad
12:06:29 Scheduling new unfirm job:U0000000008522
12:06:30 Part MMP-01755 has a receive time of 3 days and will be available January 28 2026.  It will not meet its required date of January 21 2026. 
12:06:30 Done Scheduling job:U0000000008522 sending job to queue SaveLoad
12:06:30 Scheduling new unfirm job:U0000000008523
12:06:30 Part MMP-01755 has a receive time of 3 days and will be available January 28 2026.  It will not meet its required date of January 26 2026. 
12:06:30 Done Scheduling job:U0000000008523 sending job to queue SaveLoad
12:06:30 Scheduling new unfirm job:U0000000008524
12:06:31 Done Scheduling job:U0000000008524 sending job to queue SaveLoad
12:06:31 Scheduling new unfirm job:U0000000008707
12:06:32 Done Scheduling job:U0000000008707 sending job to queue SaveLoad
12:06:32 Scheduling new unfirm job:U0000000008525
12:06:33 Done Scheduling job:U0000000008525 sending job to queue SaveLoad
12:06:33 Scheduling new unfirm job:U0000000008708
12:06:35 Done Scheduling job:U0000000008708 sending job to queue SaveLoad
12:06:35 Scheduling new unfirm job:U0000000008526
12:06:35 Done Scheduling job:U0000000008526 sending job to queue SaveLoad
12:06:35 Scheduling new unfirm job:U0000000008709
12:06:37 Done Scheduling job:U0000000008709 sending job to queue SaveLoad
12:06:37 Scheduling new unfirm job:U0000000008527
12:06:37 Done Scheduling job:U0000000008527 sending job to queue SaveLoad
12:06:37 Scheduling new unfirm job:U0000000008710
12:06:39 Done Scheduling job:U0000000008710 sending job to queue SaveLoad
12:06:39 Scheduling new unfirm job:U0000000008528
12:06:40 Done Scheduling job:U0000000008528 sending job to queue SaveLoad
12:06:40 Scheduling new unfirm job:U0000000008711
12:06:41 Done Scheduling job:U0000000008711 sending job to queue SaveLoad
12:06:41 Scheduling new unfirm job:U0000000008529
12:06:42 Done Scheduling job:U0000000008529 sending job to queue SaveLoad
12:06:42 Scheduling new unfirm job:U0000000008712
12:06:43 Done Scheduling job:U0000000008712 sending job to queue SaveLoad
12:06:43 Scheduling new unfirm job:U0000000008530
12:06:44 Done Scheduling job:U0000000008530 sending job to queue SaveLoad
12:06:44 Scheduling new unfirm job:U0000000008531
12:06:45 Done Scheduling job:U0000000008531 sending job to queue SaveLoad
12:06:45 Scheduling new unfirm job:U0000000008630
12:06:47 Done Scheduling job:U0000000008630 sending job to queue SaveLoad
12:06:47 Scheduling new unfirm job:U0000000008631
12:06:48 Done Scheduling job:U0000000008631 sending job to queue SaveLoad
12:06:48 Scheduling new unfirm job:U0000000008718
12:06:51 Done Scheduling job:U0000000008718 sending job to queue SaveLoad
12:06:51 Scheduling new unfirm job:U0000000008719
12:06:53 Done Scheduling job:U0000000008719 sending job to queue SaveLoad
12:06:53 Scheduling new unfirm job:U0000000008724
12:06:55 Done Scheduling job:U0000000008724 sending job to queue SaveLoad
12:06:55 Scheduling new unfirm job:U0000000008552
12:06:56 Done Scheduling job:U0000000008552 sending job to queue SaveLoad
12:06:56 Scheduling new unfirm job:U0000000008545
12:06:57 Done Scheduling job:U0000000008545 sending job to queue SaveLoad
12:06:57 Scheduling new unfirm job:U0000000008648
12:06:57 Done Scheduling job:U0000000008648 sending job to queue SaveLoad
12:06:57 Scheduling new unfirm job:U0000000008546
12:06:58 Done Scheduling job:U0000000008546 sending job to queue SaveLoad
12:06:58 Scheduling new unfirm job:U0000000008721
12:06:59 Done Scheduling job:U0000000008721 sending job to queue SaveLoad
12:06:59 Scheduling new unfirm job:U0000000008556
12:07:00 Done Scheduling job:U0000000008556 sending job to queue SaveLoad
12:07:00 Scheduling new unfirm job:U0000000008557
12:07:02 Done Scheduling job:U0000000008557 sending job to queue SaveLoad
12:07:02 Scheduling new unfirm job:U0000000008558
12:07:04 Done Scheduling job:U0000000008558 sending job to queue SaveLoad
12:07:04 Scheduling new unfirm job:U0000000008559
12:07:05 Done Scheduling job:U0000000008559 sending job to queue SaveLoad
12:07:05 Scheduling new unfirm job:U0000000008560
12:07:06 Done Scheduling job:U0000000008560 sending job to queue SaveLoad
12:07:06 Scheduling new unfirm job:U0000000008561
12:07:08 Done Scheduling job:U0000000008561 sending job to queue SaveLoad
12:07:08 Scheduling new unfirm job:U0000000008562
12:07:09 Done Scheduling job:U0000000008562 sending job to queue SaveLoad
12:07:09 Scheduling new unfirm job:U0000000008741
12:07:10 Done Scheduling job:U0000000008741 sending job to queue SaveLoad
12:07:10 Scheduling new unfirm job:U0000000008742
12:07:10 Done Scheduling job:U0000000008742 sending job to queue SaveLoad
12:07:10 Scheduling new unfirm job:U0000000008743
12:07:10 Done Scheduling job:U0000000008743 sending job to queue SaveLoad
12:07:10 Scheduling new unfirm job:U0000000008744
12:07:11 Done Scheduling job:U0000000008744 sending job to queue SaveLoad
12:07:11 Scheduling new unfirm job:U0000000008745
12:07:11 Done Scheduling job:U0000000008745 sending job to queue SaveLoad
12:07:11 Scheduling new unfirm job:U0000000008746
12:07:12 Done Scheduling job:U0000000008746 sending job to queue SaveLoad
12:07:12 Scheduling new unfirm job:U0000000008657
12:07:12 Done Scheduling job:U0000000008657 sending job to queue SaveLoad
12:07:12 Scheduling new unfirm job:U0000000008747
12:07:13 Done Scheduling job:U0000000008747 sending job to queue SaveLoad
12:07:13 Scheduling new unfirm job:U0000000008748
12:07:13 Done Scheduling job:U0000000008748 sending job to queue SaveLoad
12:07:13 Scheduling new unfirm job:U0000000008749
12:07:13 Done Scheduling job:U0000000008749 sending job to queue SaveLoad
12:07:14 Scheduling new unfirm job:U0000000008750
12:07:14 Done Scheduling job:U0000000008750 sending job to queue SaveLoad
12:07:14 Scheduling new unfirm job:U0000000008751
12:07:14 Done Scheduling job:U0000000008751 sending job to queue SaveLoad
12:07:14 Scheduling new unfirm job:U0000000008728
12:07:15 Done Scheduling job:U0000000008728 sending job to queue SaveLoad
12:07:15 Scheduling new unfirm job:U0000000008730
12:07:16 Done Scheduling job:U0000000008730 sending job to queue SaveLoad
12:07:16 Scheduling new unfirm job:U0000000008646
12:07:17 Done Scheduling job:U0000000008646 sending job to queue SaveLoad
12:07:17 Scheduling new unfirm job:U0000000008734
12:07:17 Done Scheduling job:U0000000008734 sending job to queue SaveLoad
12:07:17 Scheduling new unfirm job:U0000000008736
12:07:17 Done Scheduling job:U0000000008736 sending job to queue SaveLoad
12:07:17 Scheduling new unfirm job:U0000000008737
12:07:17 Done Scheduling job:U0000000008737 sending job to queue SaveLoad
12:07:17 Scheduling new unfirm job:U0000000008739
12:07:18 Done Scheduling job:U0000000008739 sending job to queue SaveLoad
12:07:18 Scheduling new unfirm job:U0000000008649
12:07:18 Done Scheduling job:U0000000008649 sending job to queue SaveLoad
12:07:18 Scheduling new unfirm job:U0000000008660
12:07:20 Done Scheduling job:U0000000008660 sending job to queue SaveLoad
12:07:20 Scheduling new unfirm job:U0000000008763
12:07:21 Done Scheduling job:U0000000008763 sending job to queue SaveLoad
12:07:21 Scheduling new unfirm job:U0000000008777
12:07:22 Done Scheduling job:U0000000008777 sending job to queue SaveLoad
12:07:22 Scheduling new unfirm job:U0000000008778
12:07:22 Done Scheduling job:U0000000008778 sending job to queue SaveLoad
12:07:22 Scheduling new unfirm job:U0000000008654
12:07:23 Done Scheduling job:U0000000008654 sending job to queue SaveLoad
12:07:23 Scheduling new unfirm job:U0000000008655
12:07:24 Done Scheduling job:U0000000008655 sending job to queue SaveLoad
12:07:24 Scheduling new unfirm job:U0000000008656
12:07:25 Done Scheduling job:U0000000008656 sending job to queue SaveLoad
12:07:25 Scheduling new unfirm job:U0000000008769
12:07:25 Done Scheduling job:U0000000008769 sending job to queue SaveLoad
12:07:25 Scheduling new unfirm job:U0000000008771
12:07:26 Done Scheduling job:U0000000008771 sending job to queue SaveLoad
12:07:26 Scheduling new unfirm job:U0000000008772
12:07:27 Done Scheduling job:U0000000008772 sending job to queue SaveLoad
12:07:27 Scheduling new unfirm job:U0000000008774
12:07:30 Done Scheduling job:U0000000008774 sending job to queue SaveLoad
12:07:30 Scheduling new unfirm job:U0000000008874
12:07:30 Done Scheduling job:U0000000008874 sending job to queue SaveLoad
12:07:31 Scheduling new unfirm job:U0000000008875
12:07:31 Done Scheduling job:U0000000008875 sending job to queue SaveLoad
12:07:31 Scheduling new unfirm job:U0000000008876
12:07:32 Done Scheduling job:U0000000008876 sending job to queue SaveLoad
12:07:32 Scheduling new unfirm job:U0000000008784
12:07:32 Done Scheduling job:U0000000008784 sending job to queue SaveLoad
12:07:32 Scheduling new unfirm job:U0000000008785
12:07:33 Done Scheduling job:U0000000008785 sending job to queue SaveLoad
12:07:33 Scheduling new unfirm job:U0000000008786
12:07:34 Done Scheduling job:U0000000008786 sending job to queue SaveLoad
12:07:34 Scheduling new unfirm job:U0000000008787
12:07:34 Done Scheduling job:U0000000008787 sending job to queue SaveLoad
12:07:34 Scheduling new unfirm job:U0000000008970
12:07:35 Done Scheduling job:U0000000008970 sending job to queue SaveLoad
12:07:35 Scheduling new unfirm job:U0000000008788
12:07:35 Done Scheduling job:U0000000008788 sending job to queue SaveLoad
12:07:35 Scheduling new unfirm job:U0000000008789
12:07:36 Done Scheduling job:U0000000008789 sending job to queue SaveLoad
12:07:36 Scheduling new unfirm job:U0000000008790
12:07:37 Done Scheduling job:U0000000008790 sending job to queue SaveLoad
12:07:37 Scheduling new unfirm job:U0000000008791
12:07:37 Done Scheduling job:U0000000008791 sending job to queue SaveLoad
12:07:37 Scheduling new unfirm job:U0000000008780
12:07:38 Done Scheduling job:U0000000008780 sending job to queue SaveLoad
12:07:38 Scheduling new unfirm job:U0000000008781
12:07:39 Done Scheduling job:U0000000008781 sending job to queue SaveLoad
12:07:39 Scheduling new unfirm job:U0000000008868
12:07:39 Done Scheduling job:U0000000008868 sending job to queue SaveLoad
12:07:39 Scheduling new unfirm job:U0000000008782
12:07:40 Done Scheduling job:U0000000008782 sending job to queue SaveLoad
12:07:40 Scheduling new unfirm job:U0000000008783
12:07:40 Done Scheduling job:U0000000008783 sending job to queue SaveLoad
12:07:40 Scheduling new unfirm job:U0000000008973
12:07:41 Done Scheduling job:U0000000008973 sending job to queue SaveLoad
12:07:41 Scheduling new unfirm job:U0000000008870
12:07:42 Done Scheduling job:U0000000008870 sending job to queue SaveLoad
12:07:42 Scheduling new unfirm job:U0000000008872
12:07:42 Done Scheduling job:U0000000008872 sending job to queue SaveLoad
12:07:42 Scheduling new unfirm job:U0000000008873
12:07:43 Done Scheduling job:U0000000008873 sending job to queue SaveLoad
12:07:43 Scheduling new unfirm job:U0000000008666
12:07:45 Done Scheduling job:U0000000008666 sending job to queue SaveLoad
12:07:45 Scheduling new unfirm job:U0000000008968
12:07:47 Done Scheduling job:U0000000008968 sending job to queue SaveLoad
12:07:47 Scheduling new unfirm job:U0000000008800
12:07:47 Done Scheduling job:U0000000008800 sending job to queue SaveLoad
12:07:47 Scheduling new unfirm job:U0000000008882
12:07:49 Done Scheduling job:U0000000008882 sending job to queue SaveLoad
12:07:49 Scheduling new unfirm job:U0000000008883
12:07:50 Done Scheduling job:U0000000008883 sending job to queue SaveLoad
12:07:50 Scheduling new unfirm job:U0000000008884
12:07:51 Done Scheduling job:U0000000008884 sending job to queue SaveLoad
12:07:51 Scheduling new unfirm job:U0000000008885
12:07:52 Done Scheduling job:U0000000008885 sending job to queue SaveLoad
12:07:52 Scheduling new unfirm job:U0000000008886
12:07:54 Done Scheduling job:U0000000008886 sending job to queue SaveLoad
12:07:54 Scheduling new unfirm job:U0000000008887
12:07:55 Done Scheduling job:U0000000008887 sending job to queue SaveLoad
12:07:55 Scheduling new unfirm job:U0000000008984
12:07:56 Done Scheduling job:U0000000008984 sending job to queue SaveLoad
12:07:56 Scheduling new unfirm job:U0000000008797
12:07:56 Done Scheduling job:U0000000008797 sending job to queue SaveLoad
12:07:56 Scheduling new unfirm job:U0000000008799
12:07:57 Done Scheduling job:U0000000008799 sending job to queue SaveLoad
12:07:57 Scheduling new unfirm job:U0000000008975
12:07:58 Done Scheduling job:U0000000008975 sending job to queue SaveLoad
12:07:58 Scheduling new unfirm job:U0000000008977
12:07:59 Done Scheduling job:U0000000008977 sending job to queue SaveLoad
12:07:59 Scheduling new unfirm job:U0000000008811
12:07:59 Done Scheduling job:U0000000008811 sending job to queue SaveLoad
12:07:59 Scheduling new unfirm job:U0000000008801
12:08:00 Done Scheduling job:U0000000008801 sending job to queue SaveLoad
12:08:00 Scheduling new unfirm job:U0000000008802
12:08:01 Done Scheduling job:U0000000008802 sending job to queue SaveLoad
12:08:01 Scheduling new unfirm job:U0000000008981
12:08:02 Done Scheduling job:U0000000008981 sending job to queue SaveLoad
12:08:02 Scheduling new unfirm job:U0000000008982
12:08:03 Done Scheduling job:U0000000008982 sending job to queue SaveLoad
12:08:03 Scheduling new unfirm job:U0000000008983
12:08:03 Done Scheduling job:U0000000008983 sending job to queue SaveLoad
12:08:03 Scheduling new unfirm job:U0000000008806
12:08:04 Done Scheduling job:U0000000008806 sending job to queue SaveLoad
12:08:04 Scheduling new unfirm job:U0000000008808
12:08:05 Done Scheduling job:U0000000008808 sending job to queue SaveLoad
12:08:05 Scheduling new unfirm job:U0000000008810
12:08:06 Done Scheduling job:U0000000008810 sending job to queue SaveLoad
12:08:06 Scheduling new unfirm job:U0000000008889
12:08:07 Done Scheduling job:U0000000008889 sending job to queue SaveLoad
12:08:07 Scheduling new unfirm job:U0000000008985
12:08:07 Done Scheduling job:U0000000008985 sending job to queue SaveLoad
12:08:07 Scheduling new unfirm job:U0000000008995
12:08:08 Done Scheduling job:U0000000008995 sending job to queue SaveLoad
12:08:08 Scheduling new unfirm job:U0000000008987
12:08:09 Done Scheduling job:U0000000008987 sending job to queue SaveLoad
12:08:09 Scheduling new unfirm job:U0000000008892
12:08:10 Done Scheduling job:U0000000008892 sending job to queue SaveLoad
12:08:10 Scheduling new unfirm job:U0000000008822
12:08:10 Done Scheduling job:U0000000008822 sending job to queue SaveLoad
12:08:10 Scheduling new unfirm job:U0000000008901
12:08:11 Done Scheduling job:U0000000008901 sending job to queue SaveLoad
12:08:11 Scheduling new unfirm job:U0000000008812
12:08:12 Done Scheduling job:U0000000008812 sending job to queue SaveLoad
12:08:12 Scheduling new unfirm job:U0000000008813
12:08:12 Done Scheduling job:U0000000008813 sending job to queue SaveLoad
12:08:12 Scheduling new unfirm job:U0000000008991
12:08:13 Done Scheduling job:U0000000008991 sending job to queue SaveLoad
12:08:13 Scheduling new unfirm job:U0000000008814
12:08:14 Done Scheduling job:U0000000008814 sending job to queue SaveLoad
12:08:14 Scheduling new unfirm job:U0000000008895
12:08:15 Done Scheduling job:U0000000008895 sending job to queue SaveLoad
12:08:15 Scheduling new unfirm job:U0000000008993
12:08:16 Done Scheduling job:U0000000008993 sending job to queue SaveLoad
12:08:16 Scheduling new unfirm job:U0000000008896
12:08:17 Done Scheduling job:U0000000008896 sending job to queue SaveLoad
12:08:17 Scheduling new unfirm job:U0000000008817
12:08:17 Done Scheduling job:U0000000008817 sending job to queue SaveLoad
12:08:17 Scheduling new unfirm job:U0000000009006
12:08:18 Done Scheduling job:U0000000009006 sending job to queue SaveLoad
12:08:18 Scheduling new unfirm job:U0000000008897
12:08:19 Done Scheduling job:U0000000008897 sending job to queue SaveLoad
12:08:19 Scheduling new unfirm job:U0000000008898
12:08:20 Done Scheduling job:U0000000008898 sending job to queue SaveLoad
12:08:20 Scheduling new unfirm job:U0000000008912
12:08:21 Done Scheduling job:U0000000008912 sending job to queue SaveLoad
12:08:21 Scheduling new unfirm job:U0000000008900
12:08:22 Done Scheduling job:U0000000008900 sending job to queue SaveLoad
12:08:22 Scheduling new unfirm job:U0000000008998
12:08:22 Done Scheduling job:U0000000008998 sending job to queue SaveLoad
12:08:23 Scheduling new unfirm job:U0000000009000
12:08:23 Done Scheduling job:U0000000009000 sending job to queue SaveLoad
12:08:23 Scheduling new unfirm job:U0000000008824
12:08:24 Done Scheduling job:U0000000008824 sending job to queue SaveLoad
12:08:24 Scheduling new unfirm job:U0000000008833
12:08:25 Done Scheduling job:U0000000008833 sending job to queue SaveLoad
12:08:25 Scheduling new unfirm job:U0000000008825
12:08:25 Done Scheduling job:U0000000008825 sending job to queue SaveLoad
12:08:26 Scheduling new unfirm job:U0000000008904
12:08:26 Done Scheduling job:U0000000008904 sending job to queue SaveLoad
12:08:26 Scheduling new unfirm job:U0000000008826
12:08:27 Done Scheduling job:U0000000008826 sending job to queue SaveLoad
12:08:27 Scheduling new unfirm job:U0000000008923
12:08:27 Done Scheduling job:U0000000008923 sending job to queue SaveLoad
12:08:27 Scheduling new unfirm job:U0000000009004
12:08:28 Done Scheduling job:U0000000009004 sending job to queue SaveLoad
12:08:28 Scheduling new unfirm job:U0000000009017
12:08:28 Done Scheduling job:U0000000009017 sending job to queue SaveLoad
12:08:28 Scheduling new unfirm job:U0000000009005
12:08:29 Done Scheduling job:U0000000009005 sending job to queue SaveLoad
12:08:29 Scheduling new unfirm job:U0000000008925
12:08:30 Done Scheduling job:U0000000008925 sending job to queue SaveLoad
12:08:30 Scheduling new unfirm job:U0000000008829
12:08:30 Done Scheduling job:U0000000008829 sending job to queue SaveLoad
12:08:30 Scheduling new unfirm job:U0000000008830
12:08:31 Done Scheduling job:U0000000008830 sending job to queue SaveLoad
12:08:31 Scheduling new unfirm job:U0000000008910
12:08:32 Done Scheduling job:U0000000008910 sending job to queue SaveLoad
12:08:32 Scheduling new unfirm job:U0000000008911
12:08:32 Done Scheduling job:U0000000008911 sending job to queue SaveLoad
12:08:32 Scheduling new unfirm job:U0000000009007
12:08:33 Done Scheduling job:U0000000009007 sending job to queue SaveLoad
12:08:33 Scheduling new unfirm job:U0000000009009
12:08:34 Done Scheduling job:U0000000009009 sending job to queue SaveLoad
12:08:34 Scheduling new unfirm job:U0000000009011
12:08:34 Done Scheduling job:U0000000009011 sending job to queue SaveLoad
12:08:34 Scheduling new unfirm job:U0000000009012
12:08:35 Done Scheduling job:U0000000009012 sending job to queue SaveLoad
12:08:35 Scheduling new unfirm job:U0000000009013
12:08:35 Done Scheduling job:U0000000009013 sending job to queue SaveLoad
12:08:35 Scheduling new unfirm job:U0000000009028
12:08:36 Done Scheduling job:U0000000009028 sending job to queue SaveLoad
12:08:36 Scheduling new unfirm job:U0000000008916
12:08:37 Done Scheduling job:U0000000008916 sending job to queue SaveLoad
12:08:37 Scheduling new unfirm job:U0000000008918
12:08:37 Done Scheduling job:U0000000008918 sending job to queue SaveLoad
12:08:37 Scheduling new unfirm job:U0000000008834
12:08:38 Done Scheduling job:U0000000008834 sending job to queue SaveLoad
12:08:38 Scheduling new unfirm job:U0000000008836
12:08:39 Done Scheduling job:U0000000008836 sending job to queue SaveLoad
12:08:39 Scheduling new unfirm job:U0000000008838
12:08:40 Done Scheduling job:U0000000008838 sending job to queue SaveLoad
12:08:40 Scheduling new unfirm job:U0000000009020
12:08:41 Done Scheduling job:U0000000009020 sending job to queue SaveLoad
12:08:41 Scheduling new unfirm job:U0000000008928
12:08:42 Done Scheduling job:U0000000008928 sending job to queue SaveLoad
12:08:42 Scheduling new unfirm job:U0000000008929
12:08:42 Done Scheduling job:U0000000008929 sending job to queue SaveLoad
12:08:43 Scheduling new unfirm job:U0000000008930
12:08:43 Done Scheduling job:U0000000008930 sending job to queue SaveLoad
12:08:43 Scheduling new unfirm job:U0000000008931
12:08:44 Done Scheduling job:U0000000008931 sending job to queue SaveLoad
12:08:44 Scheduling new unfirm job:U0000000008932
12:08:45 Done Scheduling job:U0000000008932 sending job to queue SaveLoad
12:08:45 Scheduling new unfirm job:U0000000008933
12:08:45 Done Scheduling job:U0000000008933 sending job to queue SaveLoad
12:08:45 Scheduling new unfirm job:U0000000008934
12:08:46 Done Scheduling job:U0000000008934 sending job to queue SaveLoad
12:08:46 Scheduling new unfirm job:U0000000008935
12:08:47 Done Scheduling job:U0000000008935 sending job to queue SaveLoad
12:08:47 Scheduling new unfirm job:U0000000008937
12:08:47 Done Scheduling job:U0000000008937 sending job to queue SaveLoad
12:08:49 Scheduling new unfirm job:U0000000008942
12:08:50 Done Scheduling job:U0000000008942 sending job to queue SaveLoad
12:09:14 Ending Part Level: 3-0.  Wait Time 00h:03m:42s, Jobs 296
12:09:14 Starting Part Level: 4-0.
12:09:14 Scheduling new unfirm job:U0000000008853
12:09:16 Part ELA-00249 has a receive time of 3 days and will be available February 2 2026.  It will not meet its required date of January 19 2026. 
12:09:16 Done Scheduling job:U0000000008853 sending job to queue SaveLoad
12:09:16 Scheduling new unfirm job:U0000000009029
12:09:17 Done Scheduling job:U0000000009029 sending job to queue SaveLoad
12:09:17 Scheduling new unfirm job:U0000000008945
12:09:19 Done Scheduling job:U0000000008945 sending job to queue SaveLoad
12:09:19 Scheduling new unfirm job:U0000000008857
12:09:20 Done Scheduling job:U0000000008857 sending job to queue SaveLoad
12:09:20 Scheduling new unfirm job:U0000000008947
12:09:21 Done Scheduling job:U0000000008947 sending job to queue SaveLoad
12:09:21 Scheduling new unfirm job:U0000000008948
12:09:23 Done Scheduling job:U0000000008948 sending job to queue SaveLoad
12:09:23 Scheduling new unfirm job:U0000000009033
12:09:24 Done Scheduling job:U0000000009033 sending job to queue SaveLoad
12:09:24 Scheduling new unfirm job:U0000000008858
12:09:26 Done Scheduling job:U0000000008858 sending job to queue SaveLoad
12:09:26 Scheduling new unfirm job:U0000000008859
12:09:27 Done Scheduling job:U0000000008859 sending job to queue SaveLoad
12:09:27 Scheduling new unfirm job:U0000000008860
12:09:29 Done Scheduling job:U0000000008860 sending job to queue SaveLoad
12:09:29 Scheduling new unfirm job:U0000000009036
12:09:29 Done Scheduling job:U0000000009036 sending job to queue SaveLoad
12:09:29 Scheduling new unfirm job:U0000000009037
12:09:30 Done Scheduling job:U0000000009037 sending job to queue SaveLoad
12:09:30 Scheduling new unfirm job:U0000000008861
12:09:31 Done Scheduling job:U0000000008861 sending job to queue SaveLoad
12:09:31 Scheduling new unfirm job:U0000000009038
12:09:32 Done Scheduling job:U0000000009038 sending job to queue SaveLoad
12:09:32 Scheduling new unfirm job:U0000000008954
12:09:33 Done Scheduling job:U0000000008954 sending job to queue SaveLoad
12:09:33 Scheduling new unfirm job:U0000000009041
12:09:34 Done Scheduling job:U0000000009041 sending job to queue SaveLoad
12:09:34 Scheduling new unfirm job:U0000000009042
12:09:34 Done Scheduling job:U0000000009042 sending job to queue SaveLoad
12:09:34 Scheduling new unfirm job:U0000000009043
12:09:35 Done Scheduling job:U0000000009043 sending job to queue SaveLoad
12:09:35 Scheduling new unfirm job:U0000000008955
12:09:36 Done Scheduling job:U0000000008955 sending job to queue SaveLoad
12:09:38 Scheduling new unfirm job:U0000000008957
12:09:38 Done Scheduling job:U0000000008957 sending job to queue SaveLoad
12:09:38 Scheduling new unfirm job:U0000000008959
12:09:39 Done Scheduling job:U0000000008959 sending job to queue SaveLoad
12:09:39 Scheduling new unfirm job:U0000000009046
12:09:41 Done Scheduling job:U0000000009046 sending job to queue SaveLoad
12:09:41 Scheduling new unfirm job:U0000000008960
12:09:41 Done Scheduling job:U0000000008960 sending job to queue SaveLoad
12:09:41 Scheduling new unfirm job:U0000000008961
12:09:41 Done Scheduling job:U0000000008961 sending job to queue SaveLoad
12:09:41 Scheduling new unfirm job:U0000000008863
12:09:44 Done Scheduling job:U0000000008863 sending job to queue SaveLoad
12:09:44 Scheduling new unfirm job:U0000000008962
12:09:45 Done Scheduling job:U0000000008962 sending job to queue SaveLoad
12:09:45 Scheduling new unfirm job:U0000000008963
12:09:46 Done Scheduling job:U0000000008963 sending job to queue SaveLoad
12:09:46 Scheduling new unfirm job:U0000000008964
12:09:46 Done Scheduling job:U0000000008964 sending job to queue SaveLoad
12:09:46 Scheduling new unfirm job:U0000000008965
12:09:47 Done Scheduling job:U0000000008965 sending job to queue SaveLoad
12:09:47 Scheduling new unfirm job:U0000000008966
12:09:47 Done Scheduling job:U0000000008966 sending job to queue SaveLoad
12:09:47 Scheduling new unfirm job:U0000000008967
12:09:48 Done Scheduling job:U0000000008967 sending job to queue SaveLoad
12:09:48 Scheduling new unfirm job:U0000000009068
12:09:48 Done Scheduling job:U0000000009068 sending job to queue SaveLoad
12:09:48 Scheduling new unfirm job:U0000000009069
12:09:50 Done Scheduling job:U0000000009069 sending job to queue SaveLoad
12:09:50 Scheduling new unfirm job:U0000000009070
12:09:51 Done Scheduling job:U0000000009070 sending job to queue SaveLoad
12:09:51 Scheduling new unfirm job:U0000000009051
12:09:52 Done Scheduling job:U0000000009051 sending job to queue SaveLoad
12:09:52 Scheduling new unfirm job:U0000000009052
12:09:53 Done Scheduling job:U0000000009052 sending job to queue SaveLoad
12:09:53 Scheduling new unfirm job:U0000000009053
12:09:54 Done Scheduling job:U0000000009053 sending job to queue SaveLoad
12:09:54 Scheduling new unfirm job:U0000000009054
12:09:55 Done Scheduling job:U0000000009054 sending job to queue SaveLoad
12:09:55 Scheduling new unfirm job:U0000000009168
12:09:56 Done Scheduling job:U0000000009168 sending job to queue SaveLoad
12:09:56 Scheduling new unfirm job:U0000000009072
12:09:58 Done Scheduling job:U0000000009072 sending job to queue SaveLoad
12:09:58 Scheduling new unfirm job:U0000000009169
12:09:59 Done Scheduling job:U0000000009169 sending job to queue SaveLoad
12:09:59 Scheduling new unfirm job:U0000000009073
12:10:00 Done Scheduling job:U0000000009073 sending job to queue SaveLoad
12:10:00 Scheduling new unfirm job:U0000000009062
12:10:01 Done Scheduling job:U0000000009062 sending job to queue SaveLoad
12:10:01 Scheduling new unfirm job:U0000000009171
12:10:02 Done Scheduling job:U0000000009171 sending job to queue SaveLoad
12:10:02 Scheduling new unfirm job:U0000000009173
12:10:02 Done Scheduling job:U0000000009173 sending job to queue SaveLoad
12:10:02 Scheduling new unfirm job:U0000000009074
12:10:05 Done Scheduling job:U0000000009074 sending job to queue SaveLoad
12:10:05 Scheduling new unfirm job:U0000000009177
12:10:07 Done Scheduling job:U0000000009177 sending job to queue SaveLoad
12:10:07 Scheduling new unfirm job:U0000000009078
12:10:09 Done Scheduling job:U0000000009078 sending job to queue SaveLoad
12:10:09 Scheduling new unfirm job:U0000000009066
12:10:10 Done Scheduling job:U0000000009066 sending job to queue SaveLoad
12:10:10 Scheduling new unfirm job:U0000000009185
12:10:10 Done Scheduling job:U0000000009185 sending job to queue SaveLoad
12:10:10 Scheduling new unfirm job:U0000000009269
12:10:11 Done Scheduling job:U0000000009269 sending job to queue SaveLoad
12:10:11 Scheduling new unfirm job:U0000000009079
12:10:13 Done Scheduling job:U0000000009079 sending job to queue SaveLoad
12:10:13 Scheduling new unfirm job:U0000000009277
12:10:13 Done Scheduling job:U0000000009277 sending job to queue SaveLoad
12:10:13 Scheduling new unfirm job:U0000000009080
12:10:14 Done Scheduling job:U0000000009080 sending job to queue SaveLoad
12:10:14 Scheduling new unfirm job:U0000000009081
12:10:16 Done Scheduling job:U0000000009081 sending job to queue SaveLoad
12:10:16 Scheduling new unfirm job:U0000000009182
12:10:17 Done Scheduling job:U0000000009182 sending job to queue SaveLoad
12:10:17 Scheduling new unfirm job:U0000000009183
12:10:18 Done Scheduling job:U0000000009183 sending job to queue SaveLoad
12:10:18 Scheduling new unfirm job:U0000000009270
12:10:19 Done Scheduling job:U0000000009270 sending job to queue SaveLoad
12:10:19 Scheduling new unfirm job:U0000000009083
12:10:20 Done Scheduling job:U0000000009083 sending job to queue SaveLoad
12:10:20 Scheduling new unfirm job:U0000000009084
12:10:21 Done Scheduling job:U0000000009084 sending job to queue SaveLoad
12:10:21 Scheduling new unfirm job:U0000000009085
12:10:22 Done Scheduling job:U0000000009085 sending job to queue SaveLoad
12:10:22 Scheduling new unfirm job:U0000000009187
12:10:22 Done Scheduling job:U0000000009187 sending job to queue SaveLoad
12:10:33 Ending Part Level: 4-0.  Wait Time 00h:00m:57s, Jobs 62
12:10:33 Starting Part Level: 5-0.
12:10:33 Scheduling new unfirm job:U0000000009188
12:10:34 Part A60342 has a receive time of 3 days and will be available January 23 2026.  It will not meet its required date of January 12 2026. 
12:10:34 Done Scheduling job:U0000000009188 sending job to queue SaveLoad
12:10:34 Scheduling new unfirm job:U0000000009189
12:10:34 Part A60342 has a receive time of 3 days and will be available January 22 2026.  It will not meet its required date of January 12 2026. 
12:10:34 Done Scheduling job:U0000000009189 sending job to queue SaveLoad
12:10:34 Scheduling new unfirm job:U0000000009190
12:10:35 Done Scheduling job:U0000000009190 sending job to queue SaveLoad
12:10:35 Scheduling new unfirm job:U0000000009191
12:10:36 Done Scheduling job:U0000000009191 sending job to queue SaveLoad
12:10:36 Scheduling new unfirm job:U0000000009192
12:10:36 Done Scheduling job:U0000000009192 sending job to queue SaveLoad
12:10:36 Scheduling new unfirm job:U0000000009193
12:10:37 Done Scheduling job:U0000000009193 sending job to queue SaveLoad
12:10:37 Scheduling new unfirm job:U0000000009196
12:10:38 Done Scheduling job:U0000000009196 sending job to queue SaveLoad
12:10:42 Scheduling new unfirm job:U0000000009280
12:10:42 Done Scheduling job:U0000000009280 sending job to queue SaveLoad
12:10:42 Scheduling new unfirm job:U0000000009281
12:10:42 Done Scheduling job:U0000000009281 sending job to queue SaveLoad
12:10:43 Scheduling new unfirm job:U0000000009282
12:10:43 Done Scheduling job:U0000000009282 sending job to queue SaveLoad
12:10:43 Scheduling new unfirm job:U0000000009088
12:10:44 Done Scheduling job:U0000000009088 sending job to queue SaveLoad
12:10:44 Scheduling new unfirm job:U0000000009283
12:10:44 Done Scheduling job:U0000000009283 sending job to queue SaveLoad
12:10:44 Scheduling new unfirm job:U0000000009284
12:10:45 Done Scheduling job:U0000000009284 sending job to queue SaveLoad
12:10:45 Scheduling new unfirm job:U0000000009285
12:10:45 Done Scheduling job:U0000000009285 sending job to queue SaveLoad
12:10:45 Scheduling new unfirm job:U0000000009286
12:10:46 Done Scheduling job:U0000000009286 sending job to queue SaveLoad
12:10:52 Scheduling new unfirm job:U0000000009197
12:10:52 Done Scheduling job:U0000000009197 sending job to queue SaveLoad
12:10:52 Scheduling new unfirm job:U0000000009287
12:10:53 Done Scheduling job:U0000000009287 sending job to queue SaveLoad
12:10:53 Scheduling new unfirm job:U0000000009198
12:10:54 Done Scheduling job:U0000000009198 sending job to queue SaveLoad
12:10:54 Scheduling new unfirm job:U0000000009288
12:10:55 Done Scheduling job:U0000000009288 sending job to queue SaveLoad
12:10:55 Scheduling new unfirm job:U0000000009199
12:10:55 Done Scheduling job:U0000000009199 sending job to queue SaveLoad
12:10:55 Scheduling new unfirm job:U0000000009200
12:10:56 Done Scheduling job:U0000000009200 sending job to queue SaveLoad
12:10:56 Scheduling new unfirm job:U0000000009289
12:10:56 Done Scheduling job:U0000000009289 sending job to queue SaveLoad
12:10:56 Scheduling new unfirm job:U0000000009089
12:10:57 Done Scheduling job:U0000000009089 sending job to queue SaveLoad
12:10:57 Scheduling new unfirm job:U0000000009201
12:10:58 Done Scheduling job:U0000000009201 sending job to queue SaveLoad
12:10:58 Scheduling new unfirm job:U0000000009290
12:10:58 Done Scheduling job:U0000000009290 sending job to queue SaveLoad
12:10:58 Scheduling new unfirm job:U0000000009090
12:10:59 Done Scheduling job:U0000000009090 sending job to queue SaveLoad
12:10:59 Scheduling new unfirm job:U0000000009202
12:10:59 Done Scheduling job:U0000000009202 sending job to queue SaveLoad
12:10:59 Scheduling new unfirm job:U0000000009291
12:11:00 Done Scheduling job:U0000000009291 sending job to queue SaveLoad
12:11:00 Scheduling new unfirm job:U0000000009203
12:11:01 Done Scheduling job:U0000000009203 sending job to queue SaveLoad
12:11:01 Scheduling new unfirm job:U0000000009091
12:11:01 Done Scheduling job:U0000000009091 sending job to queue SaveLoad
12:11:01 Scheduling new unfirm job:U0000000009204
12:11:02 Done Scheduling job:U0000000009204 sending job to queue SaveLoad
12:11:02 Scheduling new unfirm job:U0000000009092
12:11:03 Done Scheduling job:U0000000009092 sending job to queue SaveLoad
12:11:03 Scheduling new unfirm job:U0000000009093
12:11:03 Done Scheduling job:U0000000009093 sending job to queue SaveLoad
12:11:03 Scheduling new unfirm job:U0000000009094
12:11:04 Done Scheduling job:U0000000009094 sending job to queue SaveLoad
12:11:04 Scheduling new unfirm job:U0000000009095
12:11:05 Done Scheduling job:U0000000009095 sending job to queue SaveLoad
12:11:05 Scheduling new unfirm job:U0000000009096
12:11:05 Done Scheduling job:U0000000009096 sending job to queue SaveLoad
12:11:05 Scheduling new unfirm job:U0000000009097
12:11:06 Done Scheduling job:U0000000009097 sending job to queue SaveLoad
12:11:06 Scheduling new unfirm job:U0000000009098
12:11:06 Done Scheduling job:U0000000009098 sending job to queue SaveLoad
12:11:06 Scheduling new unfirm job:U0000000009099
12:11:07 Done Scheduling job:U0000000009099 sending job to queue SaveLoad
12:11:07 Scheduling new unfirm job:U0000000009105
12:11:08 Done Scheduling job:U0000000009105 sending job to queue SaveLoad
12:11:08 Scheduling new unfirm job:U0000000009106
12:11:08 Done Scheduling job:U0000000009106 sending job to queue SaveLoad
12:11:08 Scheduling new unfirm job:U0000000009107
12:11:09 Done Scheduling job:U0000000009107 sending job to queue SaveLoad
12:11:09 Scheduling new unfirm job:U0000000009304
12:11:09 Done Scheduling job:U0000000009304 sending job to queue SaveLoad
12:11:09 Scheduling new unfirm job:U0000000009305
12:11:10 Done Scheduling job:U0000000009305 sending job to queue SaveLoad
12:11:10 Scheduling new unfirm job:U0000000009219
12:11:10 Done Scheduling job:U0000000009219 sending job to queue SaveLoad
12:11:10 Scheduling new unfirm job:U0000000009110
12:11:11 Done Scheduling job:U0000000009110 sending job to queue SaveLoad
12:11:11 Scheduling new unfirm job:U0000000009111
12:11:12 Done Scheduling job:U0000000009111 sending job to queue SaveLoad
12:11:12 Scheduling new unfirm job:U0000000009112
12:11:13 Done Scheduling job:U0000000009112 sending job to queue SaveLoad
12:11:13 Scheduling new unfirm job:U0000000009235
12:11:13 Done Scheduling job:U0000000009235 sending job to queue SaveLoad
12:11:13 Scheduling new unfirm job:U0000000009236
12:11:14 Done Scheduling job:U0000000009236 sending job to queue SaveLoad
12:11:14 Scheduling new unfirm job:U0000000009237
12:11:14 Done Scheduling job:U0000000009237 sending job to queue SaveLoad
12:11:14 Scheduling new unfirm job:U0000000009238
12:11:15 Done Scheduling job:U0000000009238 sending job to queue SaveLoad
12:11:15 Scheduling new unfirm job:U0000000009239
12:11:15 Done Scheduling job:U0000000009239 sending job to queue SaveLoad
12:11:15 Scheduling new unfirm job:U0000000009229
12:11:16 Done Scheduling job:U0000000009229 sending job to queue SaveLoad
12:11:16 Scheduling new unfirm job:U0000000009230
12:11:16 Done Scheduling job:U0000000009230 sending job to queue SaveLoad
12:11:16 Scheduling new unfirm job:U0000000009231
12:11:17 Done Scheduling job:U0000000009231 sending job to queue SaveLoad
12:11:17 Scheduling new unfirm job:U0000000009233
12:11:17 Done Scheduling job:U0000000009233 sending job to queue SaveLoad
12:11:17 Scheduling new unfirm job:U0000000009113
12:11:18 Done Scheduling job:U0000000009113 sending job to queue SaveLoad
12:11:18 Scheduling new unfirm job:U0000000009115
12:11:19 Done Scheduling job:U0000000009115 sending job to queue SaveLoad
12:11:19 Scheduling new unfirm job:U0000000009119
12:11:19 Done Scheduling job:U0000000009119 sending job to queue SaveLoad
12:11:19 Scheduling new unfirm job:U0000000009241
12:11:20 Done Scheduling job:U0000000009241 sending job to queue SaveLoad
12:11:20 Scheduling new unfirm job:U0000000009242
12:11:20 Done Scheduling job:U0000000009242 sending job to queue SaveLoad
12:11:20 Scheduling new unfirm job:U0000000009118
12:11:21 Done Scheduling job:U0000000009118 sending job to queue SaveLoad
12:11:21 Scheduling new unfirm job:U0000000009307
12:11:21 Done Scheduling job:U0000000009307 sending job to queue SaveLoad
12:11:21 Scheduling new unfirm job:U0000000009308
12:11:22 Done Scheduling job:U0000000009308 sending job to queue SaveLoad
12:11:22 Scheduling new unfirm job:U0000000009122
12:11:22 Done Scheduling job:U0000000009122 sending job to queue SaveLoad
12:11:22 Scheduling new unfirm job:U0000000009310
12:11:22 Done Scheduling job:U0000000009310 sending job to queue SaveLoad
12:11:22 Scheduling new unfirm job:U0000000009311
12:11:23 Done Scheduling job:U0000000009311 sending job to queue SaveLoad
12:11:23 Scheduling new unfirm job:U0000000009314
12:11:23 Done Scheduling job:U0000000009314 sending job to queue SaveLoad
12:11:23 Scheduling new unfirm job:U0000000009316
12:11:24 Done Scheduling job:U0000000009316 sending job to queue SaveLoad
12:11:24 Scheduling new unfirm job:U0000000009317
12:11:24 Done Scheduling job:U0000000009317 sending job to queue SaveLoad
12:11:24 Scheduling new unfirm job:U0000000009319
12:11:25 Done Scheduling job:U0000000009319 sending job to queue SaveLoad
12:11:25 Scheduling new unfirm job:U0000000009320
12:11:25 Done Scheduling job:U0000000009320 sending job to queue SaveLoad
12:11:25 Scheduling new unfirm job:U0000000009321
12:11:26 Done Scheduling job:U0000000009321 sending job to queue SaveLoad
12:11:26 Scheduling new unfirm job:U0000000009322
12:11:26 Done Scheduling job:U0000000009322 sending job to queue SaveLoad
12:11:26 Scheduling new unfirm job:U0000000009323
12:11:26 Done Scheduling job:U0000000009323 sending job to queue SaveLoad
12:11:26 Scheduling new unfirm job:U0000000009245
12:11:27 Done Scheduling job:U0000000009245 sending job to queue SaveLoad
12:11:27 Scheduling new unfirm job:U0000000009124
12:11:27 Done Scheduling job:U0000000009124 sending job to queue SaveLoad
12:11:27 Scheduling new unfirm job:U0000000009326
12:11:27 Done Scheduling job:U0000000009326 sending job to queue SaveLoad
12:11:27 Scheduling new unfirm job:U0000000009327
12:11:28 Done Scheduling job:U0000000009327 sending job to queue SaveLoad
12:11:28 Scheduling new unfirm job:U0000000009127
12:11:28 Done Scheduling job:U0000000009127 sending job to queue SaveLoad
12:11:28 Scheduling new unfirm job:U0000000009247
12:11:28 Done Scheduling job:U0000000009247 sending job to queue SaveLoad
12:11:28 Scheduling new unfirm job:U0000000009128
12:11:29 Done Scheduling job:U0000000009128 sending job to queue SaveLoad
12:11:29 Scheduling new unfirm job:U0000000009248
12:11:29 Done Scheduling job:U0000000009248 sending job to queue SaveLoad
12:11:29 Scheduling new unfirm job:U0000000009249
12:11:29 Done Scheduling job:U0000000009249 sending job to queue SaveLoad
12:11:29 Scheduling new unfirm job:U0000000009330
12:11:30 Done Scheduling job:U0000000009330 sending job to queue SaveLoad
12:11:30 Scheduling new unfirm job:U0000000009131
12:11:30 Done Scheduling job:U0000000009131 sending job to queue SaveLoad
12:11:30 Scheduling new unfirm job:U0000000009332
12:11:31 Done Scheduling job:U0000000009332 sending job to queue SaveLoad
12:11:31 Scheduling new unfirm job:U0000000009334
12:11:31 Done Scheduling job:U0000000009334 sending job to queue SaveLoad
12:11:31 Scheduling new unfirm job:U0000000009251
12:11:32 Done Scheduling job:U0000000009251 sending job to queue SaveLoad
12:11:32 Scheduling new unfirm job:U0000000009338
12:11:32 Done Scheduling job:U0000000009338 sending job to queue SaveLoad
12:11:32 Scheduling new unfirm job:U0000000009339
12:11:33 Done Scheduling job:U0000000009339 sending job to queue SaveLoad
12:11:33 Scheduling new unfirm job:U0000000009340
12:11:33 Done Scheduling job:U0000000009340 sending job to queue SaveLoad
12:11:33 Scheduling new unfirm job:U0000000009342
12:11:34 Done Scheduling job:U0000000009342 sending job to queue SaveLoad
12:11:34 Scheduling new unfirm job:U0000000009344
12:11:34 Done Scheduling job:U0000000009344 sending job to queue SaveLoad
12:11:36 Scheduling new unfirm job:U0000000009132
12:11:37 Done Scheduling job:U0000000009132 sending job to queue SaveLoad
12:11:37 Scheduling new unfirm job:U0000000009133
12:11:38 Done Scheduling job:U0000000009133 sending job to queue SaveLoad
12:11:38 Scheduling new unfirm job:U0000000009134
12:11:39 Done Scheduling job:U0000000009134 sending job to queue SaveLoad
12:11:39 Scheduling new unfirm job:U0000000009135
12:11:39 Done Scheduling job:U0000000009135 sending job to queue SaveLoad
12:11:39 Scheduling new unfirm job:U0000000009136
12:11:40 Done Scheduling job:U0000000009136 sending job to queue SaveLoad
12:11:40 Scheduling new unfirm job:U0000000009254
12:11:41 Done Scheduling job:U0000000009254 sending job to queue SaveLoad
12:11:41 Scheduling new unfirm job:U0000000009255
12:11:41 Done Scheduling job:U0000000009255 sending job to queue SaveLoad
12:11:41 Scheduling new unfirm job:U0000000009256
12:11:42 Done Scheduling job:U0000000009256 sending job to queue SaveLoad
12:11:42 Scheduling new unfirm job:U0000000009257
12:11:42 Done Scheduling job:U0000000009257 sending job to queue SaveLoad
12:11:42 Scheduling new unfirm job:U0000000009258
12:11:43 Done Scheduling job:U0000000009258 sending job to queue SaveLoad
12:11:43 Scheduling new unfirm job:U0000000009259
12:11:44 Done Scheduling job:U0000000009259 sending job to queue SaveLoad
12:11:44 Scheduling new unfirm job:U0000000009260
12:11:44 Done Scheduling job:U0000000009260 sending job to queue SaveLoad
12:11:44 Scheduling new unfirm job:U0000000009145
12:11:45 Done Scheduling job:U0000000009145 sending job to queue SaveLoad
12:11:45 Scheduling new unfirm job:U0000000009352
12:11:47 Done Scheduling job:U0000000009352 sending job to queue SaveLoad
12:11:47 Scheduling new unfirm job:U0000000009353
12:11:49 Done Scheduling job:U0000000009353 sending job to queue SaveLoad
12:11:49 Scheduling new unfirm job:U0000000009146
12:11:51 Done Scheduling job:U0000000009146 sending job to queue SaveLoad
12:11:51 Scheduling new unfirm job:U0000000009147
12:11:52 Done Scheduling job:U0000000009147 sending job to queue SaveLoad
12:11:52 Scheduling new unfirm job:U0000000009148
12:11:52 Done Scheduling job:U0000000009148 sending job to queue SaveLoad
12:11:52 Scheduling new unfirm job:U0000000009356
12:11:55 Done Scheduling job:U0000000009356 sending job to queue SaveLoad
12:11:55 Scheduling new unfirm job:U0000000009357
12:11:56 Done Scheduling job:U0000000009357 sending job to queue SaveLoad
12:11:56 Scheduling new unfirm job:U0000000009358
12:11:57 Done Scheduling job:U0000000009358 sending job to queue SaveLoad
12:11:57 Scheduling new unfirm job:U0000000009153
12:11:58 Done Scheduling job:U0000000009153 sending job to queue SaveLoad
12:11:58 Scheduling new unfirm job:U0000000009154
12:11:58 Done Scheduling job:U0000000009154 sending job to queue SaveLoad
12:11:58 Scheduling new unfirm job:U0000000009365
12:11:58 Done Scheduling job:U0000000009365 sending job to queue SaveLoad
12:11:58 Scheduling new unfirm job:U0000000009366
12:11:59 Done Scheduling job:U0000000009366 sending job to queue SaveLoad
12:11:59 Scheduling new unfirm job:U0000000009166
12:11:59 Done Scheduling job:U0000000009166 sending job to queue SaveLoad
12:11:59 Scheduling new unfirm job:U0000000009468
12:11:59 Done Scheduling job:U0000000009468 sending job to queue SaveLoad
12:11:59 Scheduling new unfirm job:U0000000009469
12:12:00 Done Scheduling job:U0000000009469 sending job to queue SaveLoad
12:12:00 Scheduling new unfirm job:U0000000009470
12:12:00 Done Scheduling job:U0000000009470 sending job to queue SaveLoad
12:12:02 Scheduling new unfirm job:U0000000009373
12:12:03 Done Scheduling job:U0000000009373 sending job to queue SaveLoad
12:12:03 Scheduling new unfirm job:U0000000009374
12:12:05 Done Scheduling job:U0000000009374 sending job to queue SaveLoad
12:12:05 Scheduling new unfirm job:U0000000009375
12:12:06 Done Scheduling job:U0000000009375 sending job to queue SaveLoad
12:12:06 Scheduling new unfirm job:U0000000009376
12:12:07 Done Scheduling job:U0000000009376 sending job to queue SaveLoad
12:12:08 Scheduling new unfirm job:U0000000009377
12:12:09 Done Scheduling job:U0000000009377 sending job to queue SaveLoad
12:12:09 Scheduling new unfirm job:U0000000009378
12:12:10 Done Scheduling job:U0000000009378 sending job to queue SaveLoad
12:12:10 Scheduling new unfirm job:U0000000009379
12:12:12 Done Scheduling job:U0000000009379 sending job to queue SaveLoad
12:12:12 Scheduling new unfirm job:U0000000009380
12:12:13 Done Scheduling job:U0000000009380 sending job to queue SaveLoad
12:12:13 Scheduling new unfirm job:U0000000009381
12:12:14 Done Scheduling job:U0000000009381 sending job to queue SaveLoad
12:12:14 Scheduling new unfirm job:U0000000009389
12:12:15 Done Scheduling job:U0000000009389 sending job to queue SaveLoad
12:12:15 Scheduling new unfirm job:U0000000009485
12:12:16 Done Scheduling job:U0000000009485 sending job to queue SaveLoad
12:12:16 Scheduling new unfirm job:U0000000009392
12:12:17 Done Scheduling job:U0000000009392 sending job to queue SaveLoad
12:12:17 Scheduling new unfirm job:U0000000009167
12:12:18 Done Scheduling job:U0000000009167 sending job to queue SaveLoad
12:12:18 Scheduling new unfirm job:U0000000009486
12:12:18 Done Scheduling job:U0000000009486 sending job to queue SaveLoad
12:12:18 Scheduling new unfirm job:U0000000009568
12:12:19 Done Scheduling job:U0000000009568 sending job to queue SaveLoad
12:12:19 Scheduling new unfirm job:U0000000009487
12:12:20 Done Scheduling job:U0000000009487 sending job to queue SaveLoad
12:12:20 Scheduling new unfirm job:U0000000009570
12:12:21 Done Scheduling job:U0000000009570 sending job to queue SaveLoad
12:12:21 Scheduling new unfirm job:U0000000009397
12:12:22 Done Scheduling job:U0000000009397 sending job to queue SaveLoad
12:12:22 Scheduling new unfirm job:U0000000009398
12:12:23 Done Scheduling job:U0000000009398 sending job to queue SaveLoad
12:12:23 Scheduling new unfirm job:U0000000009400
12:12:24 Done Scheduling job:U0000000009400 sending job to queue SaveLoad
12:12:24 Scheduling new unfirm job:U0000000009401
12:12:25 Done Scheduling job:U0000000009401 sending job to queue SaveLoad
12:12:25 Scheduling new unfirm job:U0000000009402
12:12:25 Part WHS-04596 has a receive time of 3 days and will be available January 22 2026.  It will not meet its required date of January 12 2026. 
12:12:25 Done Scheduling job:U0000000009402 sending job to queue SaveLoad
12:12:27 Scheduling new unfirm job:U0000000009403
12:12:27 Part WHS-04597 has a receive time of 3 days and will be available January 22 2026.  It will not meet its required date of January 12 2026. 
12:12:27 Done Scheduling job:U0000000009403 sending job to queue SaveLoad
12:12:27 Scheduling new unfirm job:U0000000009571
12:12:29 Done Scheduling job:U0000000009571 sending job to queue SaveLoad
12:12:29 Scheduling new unfirm job:U0000000009572
12:12:30 Done Scheduling job:U0000000009572 sending job to queue SaveLoad
12:12:30 Scheduling new unfirm job:U0000000009573
12:12:31 Done Scheduling job:U0000000009573 sending job to queue SaveLoad
12:12:31 Scheduling new unfirm job:U0000000009574
12:12:31 Done Scheduling job:U0000000009574 sending job to queue SaveLoad
12:12:31 Scheduling new unfirm job:U0000000009577
12:12:32 Done Scheduling job:U0000000009577 sending job to queue SaveLoad
12:12:32 Scheduling new unfirm job:U0000000009488
12:12:33 Done Scheduling job:U0000000009488 sending job to queue SaveLoad
12:12:33 Scheduling new unfirm job:U0000000009489
12:12:34 Done Scheduling job:U0000000009489 sending job to queue SaveLoad
12:12:34 Scheduling new unfirm job:U0000000009490
12:12:34 Done Scheduling job:U0000000009490 sending job to queue SaveLoad
12:12:34 Scheduling new unfirm job:U0000000009491
12:12:35 Done Scheduling job:U0000000009491 sending job to queue SaveLoad
12:12:35 Scheduling new unfirm job:U0000000009492
12:12:35 Done Scheduling job:U0000000009492 sending job to queue SaveLoad
12:12:35 Scheduling new unfirm job:U0000000009493
12:12:36 Done Scheduling job:U0000000009493 sending job to queue SaveLoad
12:12:36 Scheduling new unfirm job:U0000000009494
12:12:37 Done Scheduling job:U0000000009494 sending job to queue SaveLoad
12:12:37 Scheduling new unfirm job:U0000000009495
12:12:37 Done Scheduling job:U0000000009495 sending job to queue SaveLoad
12:12:37 Scheduling new unfirm job:U0000000009496
12:12:38 Done Scheduling job:U0000000009496 sending job to queue SaveLoad
12:12:38 Scheduling new unfirm job:U0000000009497
12:12:38 Done Scheduling job:U0000000009497 sending job to queue SaveLoad
12:12:38 Scheduling new unfirm job:U0000000009498
12:12:39 Done Scheduling job:U0000000009498 sending job to queue SaveLoad
12:12:39 Scheduling new unfirm job:U0000000009499
12:12:39 Done Scheduling job:U0000000009499 sending job to queue SaveLoad
12:12:39 Scheduling new unfirm job:U0000000009500
12:12:40 Done Scheduling job:U0000000009500 sending job to queue SaveLoad
12:12:40 Scheduling new unfirm job:U0000000009501
12:12:40 Done Scheduling job:U0000000009501 sending job to queue SaveLoad
12:12:40 Scheduling new unfirm job:U0000000009502
12:12:41 Done Scheduling job:U0000000009502 sending job to queue SaveLoad
12:12:41 Scheduling new unfirm job:U0000000009503
12:12:42 Done Scheduling job:U0000000009503 sending job to queue SaveLoad
12:12:42 Scheduling new unfirm job:U0000000009504
12:12:42 Done Scheduling job:U0000000009504 sending job to queue SaveLoad
12:12:42 Scheduling new unfirm job:U0000000009505
12:12:43 Done Scheduling job:U0000000009505 sending job to queue SaveLoad
12:12:43 Scheduling new unfirm job:U0000000009506
12:12:43 Done Scheduling job:U0000000009506 sending job to queue SaveLoad
