                Sunday, January 11, 2026 12:00:03
12:00:03 MRP scheduling process begin.
12:00:03 ------------------------------------------------------------
12:00:03 Cut Off Date                      -> 1/11/2036 12:00:00 AM
12:00:03 Schedule Start Date               -> 1/11/2026 12:00:00 AM
12:00:03 Run Finite Scheduling             -> True
12:00:03 Ignore Constrained Materials      -> False
12:00:03 Allow Historical Dates            -> False
12:00:03 Use Production Preparation Buffer -> True
12:00:03 ------------------------------------------------------------
12:00:03 Process Control Queue
12:00:03   Group -> Delete; Queue -> DeleteJob; Type -> Job; Finite -> False
12:00:03     Check List -> DeleteAllPO~DeleteJob~DeleteTO; Last Group -> False
12:00:03   Group -> Load; Queue -> SaveLoad; Type -> Job; Finite -> False
12:00:03     Check List -> SaveLoad; Last Group -> True
12:00:03   Group -> NonPart; Queue -> LotJobSplit; Type -> Job; Finite -> False
12:00:03   Group -> NonPart; Queue -> SchedJobF; Type -> Job; Finite -> True
12:00:03   Group -> NonPart; Queue -> SchedJobI; Type -> Job; Finite -> False
12:00:03   Group -> NonPart; Queue -> FirmJob; Type -> Job; Finite -> False
12:00:03     Check List -> FirmJob~LotJobSplit~Part~SchedJobF~SchedJobI; Last Group -> False
12:00:03   Group -> Part; Queue -> LotJobSplit; Type -> Job; Finite -> False
12:00:03   Group -> Part; Queue -> SchedJobF; Type -> Job; Finite -> True
12:00:03   Group -> Part; Queue -> SchedJobI; Type -> Job; Finite -> False
12:00:03   Group -> Part; Queue -> FirmJob; Type -> Job; Finite -> False
12:00:03     Check List -> FirmJob~LotJobSplit~Part~SchedJobF~SchedJobI; Last Group -> False
12:00:03   Group -> Sched; Queue -> PreJobF; Type -> Job; Finite -> True
12:00:03   Group -> Sched; Queue -> PreJobI; Type -> Job; Finite -> False
12:00:03     Check List -> PreJobF~PreJobI; Last Group -> False
12:00:03   Group -> Zero; Queue -> LotJobSplit; Type -> Job; Finite -> False
12:00:03     Check List -> LotJobSplit~Part; Last Group -> False
12:00:03   Group -> ZeroSort; Queue -> SchedJobF; Type -> Job; Finite -> True
12:00:03   Group -> ZeroSort; Queue -> SchedJobI; Type -> Job; Finite -> False
12:00:03   Group -> ZeroSort; Queue -> FirmJob; Type -> Job; Finite -> False
12:00:03     Check List -> FirmJob~SchedJobF~SchedJobI~ZeroJob; Last Group -> False
12:00:03 ------------------------------------------------------------
12:00:14 Ending Part Level: 0-0.  Wait Time 00h:00m:08s, Jobs 0
12:00:14 Done Scheduling Jobs.
12:01:16 MRP process 102 done.  Total Non Scheduling Time = 00h:01m:10s. Scheduled Jobs: 0 Deleted Jobs: 0 Save Load Jobs: 0
                Monday, January 12, 2026 12:00:05
12:00:05 MRP scheduling process begin.
12:00:05 ------------------------------------------------------------
12:00:05 Cut Off Date                      -> 1/12/2036 12:00:00 AM
12:00:05 Schedule Start Date               -> 1/12/2026 12:00:00 AM
12:00:05 Run Finite Scheduling             -> True
12:00:05 Ignore Constrained Materials      -> False
12:00:05 Allow Historical Dates            -> False
12:00:05 Use Production Preparation Buffer -> True
12:00:05 ------------------------------------------------------------
12:00:05 Process Control Queue
12:00:05   Group -> Delete; Queue -> DeleteJob; Type -> Job; Finite -> False
12:00:05     Check List -> DeleteAllPO~DeleteJob~DeleteTO; Last Group -> False
12:00:05   Group -> Load; Queue -> SaveLoad; Type -> Job; Finite -> False
12:00:05     Check List -> SaveLoad; Last Group -> True
12:00:05   Group -> NonPart; Queue -> LotJobSplit; Type -> Job; Finite -> False
12:00:05   Group -> NonPart; Queue -> SchedJobF; Type -> Job; Finite -> True
12:00:05   Group -> NonPart; Queue -> SchedJobI; Type -> Job; Finite -> False
12:00:05   Group -> NonPart; Queue -> FirmJob; Type -> Job; Finite -> False
12:00:05     Check List -> FirmJob~LotJobSplit~Part~SchedJobF~SchedJobI; Last Group -> False
12:00:05   Group -> Part; Queue -> LotJobSplit; Type -> Job; Finite -> False
12:00:05   Group -> Part; Queue -> SchedJobF; Type -> Job; Finite -> True
12:00:05   Group -> Part; Queue -> SchedJobI; Type -> Job; Finite -> False
12:00:05   Group -> Part; Queue -> FirmJob; Type -> Job; Finite -> False
12:00:05     Check List -> FirmJob~LotJobSplit~Part~SchedJobF~SchedJobI; Last Group -> False
12:00:05   Group -> Sched; Queue -> PreJobF; Type -> Job; Finite -> True
12:00:05   Group -> Sched; Queue -> PreJobI; Type -> Job; Finite -> False
12:00:05     Check List -> PreJobF~PreJobI; Last Group -> False
12:00:05   Group -> Zero; Queue -> LotJobSplit; Type -> Job; Finite -> False
12:00:05     Check List -> LotJobSplit~Part; Last Group -> False
12:00:05   Group -> ZeroSort; Queue -> SchedJobF; Type -> Job; Finite -> True
12:00:05   Group -> ZeroSort; Queue -> SchedJobI; Type -> Job; Finite -> False
12:00:05   Group -> ZeroSort; Queue -> FirmJob; Type -> Job; Finite -> False
12:00:05     Check List -> FirmJob~SchedJobF~SchedJobI~ZeroJob; Last Group -> False
12:00:05 ------------------------------------------------------------
12:00:21 Starting Part Level: 0-0.
12:00:21 Scheduling new unfirm job:U0000000007968
12:00:23 Done Scheduling job:U0000000007968 sending job to queue SaveLoad
12:00:29 Scheduling new unfirm job:U0000000008068
12:00:34 Done Scheduling job:U0000000008068 sending job to queue SaveLoad
12:01:06 Scheduling new unfirm job:U0000000007971
12:01:09 Done Scheduling job:U0000000007971 sending job to queue SaveLoad
12:01:11 Scheduling new unfirm job:U0000000007973
12:01:15 Done Scheduling job:U0000000007973 sending job to queue SaveLoad
12:01:25 Scheduling new unfirm job:U0000000007978
12:01:28 Done Scheduling job:U0000000007978 sending job to queue SaveLoad
12:01:32 Scheduling new unfirm job:U0000000007981
12:01:36 Done Scheduling job:U0000000007981 sending job to queue SaveLoad
12:01:36 Scheduling new unfirm job:U0000000007982
12:01:40 Done Scheduling job:U0000000007982 sending job to queue SaveLoad
12:01:50 Ending Part Level: 0-0.  Wait Time 00h:01m:27s, Jobs 7
12:01:50 Starting Part Level: 1-0.
12:01:50 Scheduling new unfirm job:U0000000007872
12:01:50 Done Scheduling job:U0000000007872 sending job to queue SaveLoad
12:01:50 Scheduling new unfirm job:U0000000007873
12:01:50 Done Scheduling job:U0000000007873 sending job to queue SaveLoad
12:02:00 Ending Part Level: 1-0.  Wait Time 00h:00m:10s, Jobs 2
12:02:00 Starting Part Level: 2-0.
12:02:00 Scheduling new unfirm job:U0000000007987
12:02:01 Done Scheduling job:U0000000007987 sending job to queue SaveLoad
12:02:03 Scheduling new unfirm job:U0000000007988
12:02:03 Done Scheduling job:U0000000007988 sending job to queue SaveLoad
12:02:03 Scheduling new unfirm job:U0000000008076
12:02:04 Done Scheduling job:U0000000008076 sending job to queue SaveLoad
12:02:04 Scheduling new unfirm job:U0000000008078
12:02:04 Done Scheduling job:U0000000008078 sending job to queue SaveLoad
12:02:04 Scheduling new unfirm job:U0000000007879
12:02:04 Done Scheduling job:U0000000007879 sending job to queue SaveLoad
12:02:04 Scheduling new unfirm job:U0000000008080
12:02:05 Done Scheduling job:U0000000008080 sending job to queue SaveLoad
12:02:05 Scheduling new unfirm job:U0000000007991
12:02:05 Done Scheduling job:U0000000007991 sending job to queue SaveLoad
12:02:05 Scheduling new unfirm job:U0000000007880
12:02:05 Done Scheduling job:U0000000007880 sending job to queue SaveLoad
12:02:05 Scheduling new unfirm job:U0000000007992
12:02:06 Done Scheduling job:U0000000007992 sending job to queue SaveLoad
12:02:06 Scheduling new unfirm job:U0000000007881
12:02:06 Done Scheduling job:U0000000007881 sending job to queue SaveLoad
12:02:06 Scheduling new unfirm job:U0000000008083
12:02:06 Done Scheduling job:U0000000008083 sending job to queue SaveLoad
12:02:06 Scheduling new unfirm job:U0000000008085
12:02:07 Done Scheduling job:U0000000008085 sending job to queue SaveLoad
12:02:07 Scheduling new unfirm job:U0000000008086
12:02:07 Done Scheduling job:U0000000008086 sending job to queue SaveLoad
12:02:07 Scheduling new unfirm job:U0000000007995
12:02:08 Done Scheduling job:U0000000007995 sending job to queue SaveLoad
12:02:08 Scheduling new unfirm job:U0000000008088
12:02:08 Done Scheduling job:U0000000008088 sending job to queue SaveLoad
12:02:08 Scheduling new unfirm job:U0000000007996
12:02:08 Done Scheduling job:U0000000007996 sending job to queue SaveLoad
12:02:08 Scheduling new unfirm job:U0000000008090
12:02:09 Done Scheduling job:U0000000008090 sending job to queue SaveLoad
12:02:17 Scheduling new unfirm job:U0000000007894
12:02:17 Done Scheduling job:U0000000007894 sending job to queue SaveLoad
12:02:17 Scheduling new unfirm job:U0000000007895
12:02:18 Done Scheduling job:U0000000007895 sending job to queue SaveLoad
12:02:18 Scheduling new unfirm job:U0000000008097
12:02:18 Done Scheduling job:U0000000008097 sending job to queue SaveLoad
12:02:18 Scheduling new unfirm job:U0000000007896
12:02:19 Done Scheduling job:U0000000007896 sending job to queue SaveLoad
12:02:19 Scheduling new unfirm job:U0000000008098
12:02:19 Done Scheduling job:U0000000008098 sending job to queue SaveLoad
12:02:19 Scheduling new unfirm job:U0000000007897
12:02:20 Done Scheduling job:U0000000007897 sending job to queue SaveLoad
12:02:20 Scheduling new unfirm job:U0000000008099
12:02:20 Done Scheduling job:U0000000008099 sending job to queue SaveLoad
12:02:20 Scheduling new unfirm job:U0000000007898
12:02:21 Done Scheduling job:U0000000007898 sending job to queue SaveLoad
12:02:21 Scheduling new unfirm job:U0000000008100
12:02:21 Done Scheduling job:U0000000008100 sending job to queue SaveLoad
12:02:21 Scheduling new unfirm job:U0000000007899
12:02:22 Done Scheduling job:U0000000007899 sending job to queue SaveLoad
12:02:22 Scheduling new unfirm job:U0000000007900
12:02:22 Done Scheduling job:U0000000007900 sending job to queue SaveLoad
12:02:22 Scheduling new unfirm job:U0000000008101
12:02:23 Done Scheduling job:U0000000008101 sending job to queue SaveLoad
12:02:23 Scheduling new unfirm job:U0000000008009
12:02:24 Done Scheduling job:U0000000008009 sending job to queue SaveLoad
12:02:24 Scheduling new unfirm job:U0000000007901
12:02:24 Done Scheduling job:U0000000007901 sending job to queue SaveLoad
12:02:24 Scheduling new unfirm job:U0000000008102
12:02:25 Done Scheduling job:U0000000008102 sending job to queue SaveLoad
12:02:25 Scheduling new unfirm job:U0000000008103
12:02:25 Done Scheduling job:U0000000008103 sending job to queue SaveLoad
12:02:25 Scheduling new unfirm job:U0000000007902
12:02:25 Done Scheduling job:U0000000007902 sending job to queue SaveLoad
12:02:25 Scheduling new unfirm job:U0000000008104
12:02:26 Done Scheduling job:U0000000008104 sending job to queue SaveLoad
12:02:26 Scheduling new unfirm job:U0000000007903
12:02:26 Done Scheduling job:U0000000007903 sending job to queue SaveLoad
12:02:26 Scheduling new unfirm job:U0000000008105
12:02:27 Done Scheduling job:U0000000008105 sending job to queue SaveLoad
12:02:27 Scheduling new unfirm job:U0000000007904
12:02:27 Done Scheduling job:U0000000007904 sending job to queue SaveLoad
12:02:27 Scheduling new unfirm job:U0000000008106
12:02:28 Done Scheduling job:U0000000008106 sending job to queue SaveLoad
12:02:28 Scheduling new unfirm job:U0000000007905
12:02:28 Done Scheduling job:U0000000007905 sending job to queue SaveLoad
12:02:28 Scheduling new unfirm job:U0000000008107
12:02:29 Done Scheduling job:U0000000008107 sending job to queue SaveLoad
12:02:29 Scheduling new unfirm job:U0000000007906
12:02:29 Done Scheduling job:U0000000007906 sending job to queue SaveLoad
12:02:29 Scheduling new unfirm job:U0000000008108
12:02:30 Done Scheduling job:U0000000008108 sending job to queue SaveLoad
12:02:30 Scheduling new unfirm job:U0000000007907
12:02:31 Done Scheduling job:U0000000007907 sending job to queue SaveLoad
12:02:31 Scheduling new unfirm job:U0000000008109
12:02:31 Done Scheduling job:U0000000008109 sending job to queue SaveLoad
12:02:31 Scheduling new unfirm job:U0000000007908
12:02:32 Done Scheduling job:U0000000007908 sending job to queue SaveLoad
12:02:32 Scheduling new unfirm job:U0000000008110
12:02:32 Done Scheduling job:U0000000008110 sending job to queue SaveLoad
12:02:32 Scheduling new unfirm job:U0000000008111
12:02:33 Done Scheduling job:U0000000008111 sending job to queue SaveLoad
12:02:33 Scheduling new unfirm job:U0000000008112
12:02:33 Done Scheduling job:U0000000008112 sending job to queue SaveLoad
12:02:33 Scheduling new unfirm job:U0000000007910
12:02:33 Done Scheduling job:U0000000007910 sending job to queue SaveLoad
12:02:33 Scheduling new unfirm job:U0000000007913
12:02:34 Done Scheduling job:U0000000007913 sending job to queue SaveLoad
12:02:34 Scheduling new unfirm job:U0000000008011
12:02:35 Done Scheduling job:U0000000008011 sending job to queue SaveLoad
12:02:35 Scheduling new unfirm job:U0000000008012
12:02:37 Done Scheduling job:U0000000008012 sending job to queue SaveLoad
12:02:37 Scheduling new unfirm job:U0000000008013
12:02:38 Done Scheduling job:U0000000008013 sending job to queue SaveLoad
12:02:38 Scheduling new unfirm job:U0000000007915
12:02:38 Done Scheduling job:U0000000007915 sending job to queue SaveLoad
12:02:38 Scheduling new unfirm job:U0000000008014
12:02:40 Done Scheduling job:U0000000008014 sending job to queue SaveLoad
12:02:40 Scheduling new unfirm job:U0000000008015
12:02:41 Done Scheduling job:U0000000008015 sending job to queue SaveLoad
12:02:41 Scheduling new unfirm job:U0000000008016
12:02:42 Done Scheduling job:U0000000008016 sending job to queue SaveLoad
12:02:42 Scheduling new unfirm job:U0000000008116
12:02:42 Done Scheduling job:U0000000008116 sending job to queue SaveLoad
12:02:42 Scheduling new unfirm job:U0000000008117
12:02:43 Done Scheduling job:U0000000008117 sending job to queue SaveLoad
12:02:43 Scheduling new unfirm job:U0000000008017
12:02:44 Done Scheduling job:U0000000008017 sending job to queue SaveLoad
12:02:44 Scheduling new unfirm job:U0000000008018
12:02:45 Done Scheduling job:U0000000008018 sending job to queue SaveLoad
12:02:45 Scheduling new unfirm job:U0000000008019
12:02:46 Done Scheduling job:U0000000008019 sending job to queue SaveLoad
12:02:46 Scheduling new unfirm job:U0000000008121
12:02:47 Done Scheduling job:U0000000008121 sending job to queue SaveLoad
12:02:47 Scheduling new unfirm job:U0000000008020
12:02:48 Done Scheduling job:U0000000008020 sending job to queue SaveLoad
12:02:48 Scheduling new unfirm job:U0000000008122
12:02:48 Done Scheduling job:U0000000008122 sending job to queue SaveLoad
12:02:48 Scheduling new unfirm job:U0000000008123
12:02:49 Done Scheduling job:U0000000008123 sending job to queue SaveLoad
12:02:49 Scheduling new unfirm job:U0000000008021
12:02:50 Done Scheduling job:U0000000008021 sending job to queue SaveLoad
12:02:50 Scheduling new unfirm job:U0000000008124
12:02:50 Done Scheduling job:U0000000008124 sending job to queue SaveLoad
12:02:50 Scheduling new unfirm job:U0000000007921
12:02:51 Done Scheduling job:U0000000007921 sending job to queue SaveLoad
12:02:51 Scheduling new unfirm job:U0000000008022
12:02:52 Done Scheduling job:U0000000008022 sending job to queue SaveLoad
12:02:52 Scheduling new unfirm job:U0000000008125
12:02:52 Done Scheduling job:U0000000008125 sending job to queue SaveLoad
12:02:52 Scheduling new unfirm job:U0000000007922
12:02:53 Done Scheduling job:U0000000007922 sending job to queue SaveLoad
12:02:53 Scheduling new unfirm job:U0000000008126
12:02:53 Done Scheduling job:U0000000008126 sending job to queue SaveLoad
12:02:53 Scheduling new unfirm job:U0000000007923
12:02:53 Done Scheduling job:U0000000007923 sending job to queue SaveLoad
12:02:53 Scheduling new unfirm job:U0000000008127
12:02:54 Done Scheduling job:U0000000008127 sending job to queue SaveLoad
12:02:54 Scheduling new unfirm job:U0000000008128
12:02:54 Done Scheduling job:U0000000008128 sending job to queue SaveLoad
12:02:54 Scheduling new unfirm job:U0000000008129
12:02:55 Done Scheduling job:U0000000008129 sending job to queue SaveLoad
12:02:55 Scheduling new unfirm job:U0000000008130
12:02:55 Done Scheduling job:U0000000008130 sending job to queue SaveLoad
12:02:55 Scheduling new unfirm job:U0000000008131
12:02:56 Done Scheduling job:U0000000008131 sending job to queue SaveLoad
12:02:56 Scheduling new unfirm job:U0000000008132
12:02:56 Done Scheduling job:U0000000008132 sending job to queue SaveLoad
12:02:56 Scheduling new unfirm job:U0000000008136
12:02:57 Done Scheduling job:U0000000008136 sending job to queue SaveLoad
12:02:57 Scheduling new unfirm job:U0000000008137
12:02:57 Done Scheduling job:U0000000008137 sending job to queue SaveLoad
12:02:57 Scheduling new unfirm job:U0000000007929
12:02:57 Done Scheduling job:U0000000007929 sending job to queue SaveLoad
12:02:57 Scheduling new unfirm job:U0000000008030
12:02:58 Done Scheduling job:U0000000008030 sending job to queue SaveLoad
12:02:58 Scheduling new unfirm job:U0000000008031
12:02:58 Done Scheduling job:U0000000008031 sending job to queue SaveLoad
12:02:58 Scheduling new unfirm job:U0000000008144
12:02:59 Done Scheduling job:U0000000008144 sending job to queue SaveLoad
12:02:59 Scheduling new unfirm job:U0000000008032
12:02:59 Done Scheduling job:U0000000008032 sending job to queue SaveLoad
12:02:59 Scheduling new unfirm job:U0000000008145
12:03:00 Done Scheduling job:U0000000008145 sending job to queue SaveLoad
12:03:00 Scheduling new unfirm job:U0000000007935
12:03:00 Done Scheduling job:U0000000007935 sending job to queue SaveLoad
12:03:00 Scheduling new unfirm job:U0000000008146
12:03:01 Done Scheduling job:U0000000008146 sending job to queue SaveLoad
12:03:01 Scheduling new unfirm job:U0000000008033
12:03:01 Done Scheduling job:U0000000008033 sending job to queue SaveLoad
12:03:01 Scheduling new unfirm job:U0000000007936
12:03:02 Done Scheduling job:U0000000007936 sending job to queue SaveLoad
12:03:02 Scheduling new unfirm job:U0000000008034
12:03:02 Done Scheduling job:U0000000008034 sending job to queue SaveLoad
12:03:02 Scheduling new unfirm job:U0000000007937
12:03:03 Done Scheduling job:U0000000007937 sending job to queue SaveLoad
12:03:03 Scheduling new unfirm job:U0000000007938
12:03:03 Done Scheduling job:U0000000007938 sending job to queue SaveLoad
12:03:03 Scheduling new unfirm job:U0000000008035
12:03:04 Done Scheduling job:U0000000008035 sending job to queue SaveLoad
12:03:04 Scheduling new unfirm job:U0000000008036
12:03:04 Done Scheduling job:U0000000008036 sending job to queue SaveLoad
12:03:04 Scheduling new unfirm job:U0000000007940
12:03:05 Done Scheduling job:U0000000007940 sending job to queue SaveLoad
12:03:05 Scheduling new unfirm job:U0000000008037
12:03:05 Done Scheduling job:U0000000008037 sending job to queue SaveLoad
12:03:05 Scheduling new unfirm job:U0000000007941
12:03:06 Done Scheduling job:U0000000007941 sending job to queue SaveLoad
12:03:06 Scheduling new unfirm job:U0000000008038
12:03:06 Done Scheduling job:U0000000008038 sending job to queue SaveLoad
12:03:06 Scheduling new unfirm job:U0000000007942
12:03:07 Done Scheduling job:U0000000007942 sending job to queue SaveLoad
12:03:07 Scheduling new unfirm job:U0000000007943
12:03:07 Done Scheduling job:U0000000007943 sending job to queue SaveLoad
12:03:07 Scheduling new unfirm job:U0000000008039
12:03:08 Done Scheduling job:U0000000008039 sending job to queue SaveLoad
12:03:08 Scheduling new unfirm job:U0000000007944
12:03:08 Done Scheduling job:U0000000007944 sending job to queue SaveLoad
12:03:08 Scheduling new unfirm job:U0000000007945
12:03:09 Done Scheduling job:U0000000007945 sending job to queue SaveLoad
12:03:09 Scheduling new unfirm job:U0000000008152
12:03:09 Done Scheduling job:U0000000008152 sending job to queue SaveLoad
12:03:09 Scheduling new unfirm job:U0000000007946
12:03:09 Done Scheduling job:U0000000007946 sending job to queue SaveLoad
12:03:09 Scheduling new unfirm job:U0000000008153
12:03:10 Done Scheduling job:U0000000008153 sending job to queue SaveLoad
12:03:10 Scheduling new unfirm job:U0000000008154
12:03:11 Done Scheduling job:U0000000008154 sending job to queue SaveLoad
12:03:11 Scheduling new unfirm job:U0000000007948
12:03:12 Done Scheduling job:U0000000007948 sending job to queue SaveLoad
12:03:12 Scheduling new unfirm job:U0000000007949
12:03:13 Done Scheduling job:U0000000007949 sending job to queue SaveLoad
12:03:13 Scheduling new unfirm job:U0000000008156
12:03:13 Done Scheduling job:U0000000008156 sending job to queue SaveLoad
12:03:13 Scheduling new unfirm job:U0000000008157
12:03:14 Done Scheduling job:U0000000008157 sending job to queue SaveLoad
12:03:14 Scheduling new unfirm job:U0000000007951
12:03:15 Done Scheduling job:U0000000007951 sending job to queue SaveLoad
12:03:15 Scheduling new unfirm job:U0000000008158
12:03:16 Done Scheduling job:U0000000008158 sending job to queue SaveLoad
12:03:16 Scheduling new unfirm job:U0000000007952
12:03:17 Done Scheduling job:U0000000007952 sending job to queue SaveLoad
12:03:17 Scheduling new unfirm job:U0000000008159
12:03:18 Done Scheduling job:U0000000008159 sending job to queue SaveLoad
12:03:18 Scheduling new unfirm job:U0000000008160
12:03:18 Done Scheduling job:U0000000008160 sending job to queue SaveLoad
12:03:18 Scheduling new unfirm job:U0000000007953
12:03:19 Done Scheduling job:U0000000007953 sending job to queue SaveLoad
12:03:19 Scheduling new unfirm job:U0000000007954
12:03:19 Done Scheduling job:U0000000007954 sending job to queue SaveLoad
12:03:19 Scheduling new unfirm job:U0000000008047
12:03:20 Done Scheduling job:U0000000008047 sending job to queue SaveLoad
12:03:20 Scheduling new unfirm job:U0000000008048
12:03:21 Done Scheduling job:U0000000008048 sending job to queue SaveLoad
12:03:21 Scheduling new unfirm job:U0000000008049
12:03:22 Done Scheduling job:U0000000008049 sending job to queue SaveLoad
12:03:22 Scheduling new unfirm job:U0000000008162
12:03:23 Done Scheduling job:U0000000008162 sending job to queue SaveLoad
12:03:23 Scheduling new unfirm job:U0000000008050
12:03:24 Done Scheduling job:U0000000008050 sending job to queue SaveLoad
12:03:24 Scheduling new unfirm job:U0000000007956
12:03:24 Done Scheduling job:U0000000007956 sending job to queue SaveLoad
12:03:24 Scheduling new unfirm job:U0000000008051
12:03:25 Done Scheduling job:U0000000008051 sending job to queue SaveLoad
12:03:25 Scheduling new unfirm job:U0000000008163
12:03:26 Done Scheduling job:U0000000008163 sending job to queue SaveLoad
12:03:26 Scheduling new unfirm job:U0000000008165
12:03:27 Done Scheduling job:U0000000008165 sending job to queue SaveLoad
12:03:27 Scheduling new unfirm job:U0000000007959
12:03:28 Done Scheduling job:U0000000007959 sending job to queue SaveLoad
12:03:28 Scheduling new unfirm job:U0000000008054
12:03:28 Done Scheduling job:U0000000008054 sending job to queue SaveLoad
12:03:28 Scheduling new unfirm job:U0000000008055
12:03:29 Done Scheduling job:U0000000008055 sending job to queue SaveLoad
12:03:29 Scheduling new unfirm job:U0000000007960
12:03:30 Done Scheduling job:U0000000007960 sending job to queue SaveLoad
12:03:30 Scheduling new unfirm job:U0000000007962
12:03:30 Done Scheduling job:U0000000007962 sending job to queue SaveLoad
12:03:30 Scheduling new unfirm job:U0000000007963
12:03:31 Done Scheduling job:U0000000007963 sending job to queue SaveLoad
12:03:31 Scheduling new unfirm job:U0000000008169
12:03:32 Done Scheduling job:U0000000008169 sending job to queue SaveLoad
12:03:32 Scheduling new unfirm job:U0000000008170
12:03:33 Done Scheduling job:U0000000008170 sending job to queue SaveLoad
12:03:33 Scheduling new unfirm job:U0000000007964
12:03:34 Done Scheduling job:U0000000007964 sending job to queue SaveLoad
12:03:34 Scheduling new unfirm job:U0000000007965
12:03:35 Done Scheduling job:U0000000007965 sending job to queue SaveLoad
12:03:35 Scheduling new unfirm job:U0000000008058
12:03:35 Done Scheduling job:U0000000008058 sending job to queue SaveLoad
12:03:35 Scheduling new unfirm job:U0000000008171
12:03:36 Done Scheduling job:U0000000008171 sending job to queue SaveLoad
12:03:36 Scheduling new unfirm job:U0000000008059
12:03:37 Done Scheduling job:U0000000008059 sending job to queue SaveLoad
12:03:37 Scheduling new unfirm job:U0000000007966
12:03:38 Done Scheduling job:U0000000007966 sending job to queue SaveLoad
12:03:38 Scheduling new unfirm job:U0000000008060
12:03:38 Done Scheduling job:U0000000008060 sending job to queue SaveLoad
12:03:38 Scheduling new unfirm job:U0000000008061
12:03:39 Done Scheduling job:U0000000008061 sending job to queue SaveLoad
12:03:39 Scheduling new unfirm job:U0000000008062
12:03:40 Done Scheduling job:U0000000008062 sending job to queue SaveLoad
12:03:40 Scheduling new unfirm job:U0000000007967
12:03:40 Done Scheduling job:U0000000007967 sending job to queue SaveLoad
12:03:41 Scheduling new unfirm job:U0000000008063
12:03:41 Done Scheduling job:U0000000008063 sending job to queue SaveLoad
12:03:41 Scheduling new unfirm job:U0000000008172
12:03:42 Done Scheduling job:U0000000008172 sending job to queue SaveLoad
12:03:42 Scheduling new unfirm job:U0000000008268
12:03:43 Done Scheduling job:U0000000008268 sending job to queue SaveLoad
12:03:43 Scheduling new unfirm job:U0000000008269
12:03:44 Done Scheduling job:U0000000008269 sending job to queue SaveLoad
12:03:44 Scheduling new unfirm job:U0000000008173
12:03:45 Done Scheduling job:U0000000008173 sending job to queue SaveLoad
12:03:45 Scheduling new unfirm job:U0000000008174
12:03:46 Done Scheduling job:U0000000008174 sending job to queue SaveLoad
12:03:46 Scheduling new unfirm job:U0000000008175
12:03:46 Done Scheduling job:U0000000008175 sending job to queue SaveLoad
12:03:47 Scheduling new unfirm job:U0000000008176
12:03:47 Done Scheduling job:U0000000008176 sending job to queue SaveLoad
12:03:47 Scheduling new unfirm job:U0000000008177
12:03:48 Done Scheduling job:U0000000008177 sending job to queue SaveLoad
12:03:48 Scheduling new unfirm job:U0000000008066
12:03:49 Done Scheduling job:U0000000008066 sending job to queue SaveLoad
12:03:49 Scheduling new unfirm job:U0000000008178
12:03:50 Done Scheduling job:U0000000008178 sending job to queue SaveLoad
12:03:50 Scheduling new unfirm job:U0000000008067
12:03:51 Done Scheduling job:U0000000008067 sending job to queue SaveLoad
12:03:51 Scheduling new unfirm job:U0000000008368
12:03:51 Done Scheduling job:U0000000008368 sending job to queue SaveLoad
12:03:52 Scheduling new unfirm job:U0000000008369
12:03:52 Done Scheduling job:U0000000008369 sending job to queue SaveLoad
12:03:52 Scheduling new unfirm job:U0000000008370
12:03:53 Done Scheduling job:U0000000008370 sending job to queue SaveLoad
12:03:53 Scheduling new unfirm job:U0000000008371
12:03:53 Done Scheduling job:U0000000008371 sending job to queue SaveLoad
12:03:53 Scheduling new unfirm job:U0000000008374
12:03:54 Done Scheduling job:U0000000008374 sending job to queue SaveLoad
12:03:54 Scheduling new unfirm job:U0000000008183
12:03:55 Done Scheduling job:U0000000008183 sending job to queue SaveLoad
12:03:55 Scheduling new unfirm job:U0000000008275
12:03:56 Done Scheduling job:U0000000008275 sending job to queue SaveLoad
12:03:56 Scheduling new unfirm job:U0000000008276
12:03:56 Done Scheduling job:U0000000008276 sending job to queue SaveLoad
12:03:56 Scheduling new unfirm job:U0000000008184
12:03:57 Done Scheduling job:U0000000008184 sending job to queue SaveLoad
12:03:57 Scheduling new unfirm job:U0000000008277
12:03:58 Done Scheduling job:U0000000008277 sending job to queue SaveLoad
12:03:58 Scheduling new unfirm job:U0000000008278
12:03:59 Done Scheduling job:U0000000008278 sending job to queue SaveLoad
12:03:59 Scheduling new unfirm job:U0000000008375
12:04:00 Done Scheduling job:U0000000008375 sending job to queue SaveLoad
12:04:00 Scheduling new unfirm job:U0000000008279
12:04:01 Done Scheduling job:U0000000008279 sending job to queue SaveLoad
12:04:01 Scheduling new unfirm job:U0000000008280
12:04:01 Done Scheduling job:U0000000008280 sending job to queue SaveLoad
12:04:01 Scheduling new unfirm job:U0000000008281
12:04:02 Done Scheduling job:U0000000008281 sending job to queue SaveLoad
12:04:02 Scheduling new unfirm job:U0000000008282
12:04:03 Done Scheduling job:U0000000008282 sending job to queue SaveLoad
12:04:03 Scheduling new unfirm job:U0000000008283
12:04:04 Done Scheduling job:U0000000008283 sending job to queue SaveLoad
12:04:04 Scheduling new unfirm job:U0000000008284
12:04:05 Done Scheduling job:U0000000008284 sending job to queue SaveLoad
12:04:05 Scheduling new unfirm job:U0000000008377
12:04:05 Done Scheduling job:U0000000008377 sending job to queue SaveLoad
12:04:05 Scheduling new unfirm job:U0000000008285
12:04:06 Done Scheduling job:U0000000008285 sending job to queue SaveLoad
12:04:06 Scheduling new unfirm job:U0000000008187
12:04:06 Done Scheduling job:U0000000008187 sending job to queue SaveLoad
12:04:06 Scheduling new unfirm job:U0000000008378
12:04:06 Done Scheduling job:U0000000008378 sending job to queue SaveLoad
12:04:06 Scheduling new unfirm job:U0000000008188
12:04:07 Done Scheduling job:U0000000008188 sending job to queue SaveLoad
12:04:07 Scheduling new unfirm job:U0000000008286
12:04:08 Done Scheduling job:U0000000008286 sending job to queue SaveLoad
12:04:08 Scheduling new unfirm job:U0000000008287
12:04:08 Done Scheduling job:U0000000008287 sending job to queue SaveLoad
12:04:08 Scheduling new unfirm job:U0000000008189
12:04:09 Done Scheduling job:U0000000008189 sending job to queue SaveLoad
12:04:09 Scheduling new unfirm job:U0000000008382
12:04:09 Done Scheduling job:U0000000008382 sending job to queue SaveLoad
12:04:09 Scheduling new unfirm job:U0000000008383
12:04:09 Done Scheduling job:U0000000008383 sending job to queue SaveLoad
12:04:09 Scheduling new unfirm job:U0000000008295
12:04:10 Done Scheduling job:U0000000008295 sending job to queue SaveLoad
12:04:10 Scheduling new unfirm job:U0000000008296
12:04:10 Done Scheduling job:U0000000008296 sending job to queue SaveLoad
12:04:10 Scheduling new unfirm job:U0000000008297
12:04:11 Done Scheduling job:U0000000008297 sending job to queue SaveLoad
12:04:11 Scheduling new unfirm job:U0000000008298
12:04:11 Done Scheduling job:U0000000008298 sending job to queue SaveLoad
12:04:11 Scheduling new unfirm job:U0000000008299
12:04:12 Done Scheduling job:U0000000008299 sending job to queue SaveLoad
12:04:12 Scheduling new unfirm job:U0000000008300
12:04:12 Done Scheduling job:U0000000008300 sending job to queue SaveLoad
12:04:12 Scheduling new unfirm job:U0000000008301
12:04:13 Done Scheduling job:U0000000008301 sending job to queue SaveLoad
12:04:13 Scheduling new unfirm job:U0000000008392
12:04:14 Done Scheduling job:U0000000008392 sending job to queue SaveLoad
12:04:14 Scheduling new unfirm job:U0000000008393
12:04:14 Done Scheduling job:U0000000008393 sending job to queue SaveLoad
12:04:14 Scheduling new unfirm job:U0000000008394
12:04:15 Done Scheduling job:U0000000008394 sending job to queue SaveLoad
12:04:15 Scheduling new unfirm job:U0000000008306
12:04:16 Done Scheduling job:U0000000008306 sending job to queue SaveLoad
12:04:16 Scheduling new unfirm job:U0000000008307
12:04:17 Done Scheduling job:U0000000008307 sending job to queue SaveLoad
12:04:17 Scheduling new unfirm job:U0000000008308
12:04:17 Done Scheduling job:U0000000008308 sending job to queue SaveLoad
12:04:17 Scheduling new unfirm job:U0000000008309
12:04:18 Done Scheduling job:U0000000008309 sending job to queue SaveLoad
12:04:18 Scheduling new unfirm job:U0000000008398
12:04:18 Done Scheduling job:U0000000008398 sending job to queue SaveLoad
12:04:18 Scheduling new unfirm job:U0000000008204
12:04:20 Done Scheduling job:U0000000008204 sending job to queue SaveLoad
12:04:20 Scheduling new unfirm job:U0000000008399
12:04:20 Done Scheduling job:U0000000008399 sending job to queue SaveLoad
12:04:20 Scheduling new unfirm job:U0000000008205
12:04:21 Done Scheduling job:U0000000008205 sending job to queue SaveLoad
12:04:21 Scheduling new unfirm job:U0000000008206
12:04:23 Done Scheduling job:U0000000008206 sending job to queue SaveLoad
12:04:23 Scheduling new unfirm job:U0000000008402
12:04:23 Done Scheduling job:U0000000008402 sending job to queue SaveLoad
12:04:23 Scheduling new unfirm job:U0000000008403
12:04:24 Done Scheduling job:U0000000008403 sending job to queue SaveLoad
12:04:24 Scheduling new unfirm job:U0000000008209
12:04:25 Done Scheduling job:U0000000008209 sending job to queue SaveLoad
12:04:25 Scheduling new unfirm job:U0000000008210
12:04:25 Done Scheduling job:U0000000008210 sending job to queue SaveLoad
12:04:25 Scheduling new unfirm job:U0000000008406
12:04:26 Done Scheduling job:U0000000008406 sending job to queue SaveLoad
12:04:26 Scheduling new unfirm job:U0000000008409
12:04:26 Done Scheduling job:U0000000008409 sending job to queue SaveLoad
12:04:33 Scheduling new unfirm job:U0000000008222
12:04:33 Done Scheduling job:U0000000008222 sending job to queue SaveLoad
12:04:33 Scheduling new unfirm job:U0000000008224
12:04:34 Done Scheduling job:U0000000008224 sending job to queue SaveLoad
12:04:34 Scheduling new unfirm job:U0000000008226
12:04:34 Done Scheduling job:U0000000008226 sending job to queue SaveLoad
12:04:34 Scheduling new unfirm job:U0000000008228
12:04:35 Done Scheduling job:U0000000008228 sending job to queue SaveLoad
12:04:37 Scheduling new unfirm job:U0000000008233
12:04:38 Done Scheduling job:U0000000008233 sending job to queue SaveLoad
12:04:38 Scheduling new unfirm job:U0000000008235
12:04:38 Done Scheduling job:U0000000008235 sending job to queue SaveLoad
12:04:38 Scheduling new unfirm job:U0000000008419
12:04:39 Done Scheduling job:U0000000008419 sending job to queue SaveLoad
12:04:43 Scheduling new unfirm job:U0000000008426
12:04:44 Done Scheduling job:U0000000008426 sending job to queue SaveLoad
12:04:46 Scheduling new unfirm job:U0000000008430
12:04:47 Done Scheduling job:U0000000008430 sending job to queue SaveLoad
12:04:47 Scheduling new unfirm job:U0000000008431
12:04:48 Done Scheduling job:U0000000008431 sending job to queue SaveLoad
12:04:48 Scheduling new unfirm job:U0000000008433
12:04:48 Done Scheduling job:U0000000008433 sending job to queue SaveLoad
12:05:07 Ending Part Level: 2-0.  Wait Time 00h:03m:06s, Jobs 225
12:05:07 Starting Part Level: 3-0.
12:05:07 Scheduling new unfirm job:U0000000008320
12:05:07 Done Scheduling job:U0000000008320 sending job to queue SaveLoad
12:05:07 Scheduling new unfirm job:U0000000008321
12:05:07 Done Scheduling job:U0000000008321 sending job to queue SaveLoad
12:05:07 Scheduling new unfirm job:U0000000008322
12:05:08 Done Scheduling job:U0000000008322 sending job to queue SaveLoad
12:05:08 Scheduling new unfirm job:U0000000008323
12:05:08 Done Scheduling job:U0000000008323 sending job to queue SaveLoad
12:05:08 Scheduling new unfirm job:U0000000008324
12:05:09 Done Scheduling job:U0000000008324 sending job to queue SaveLoad
12:05:09 Scheduling new unfirm job:U0000000008237
12:05:10 Done Scheduling job:U0000000008237 sending job to queue SaveLoad
12:05:10 Scheduling new unfirm job:U0000000008238
12:05:11 Done Scheduling job:U0000000008238 sending job to queue SaveLoad
12:05:11 Scheduling new unfirm job:U0000000008239
12:05:12 Done Scheduling job:U0000000008239 sending job to queue SaveLoad
12:05:12 Scheduling new unfirm job:U0000000008328
12:05:12 Done Scheduling job:U0000000008328 sending job to queue SaveLoad
12:05:12 Scheduling new unfirm job:U0000000008329
12:05:12 Done Scheduling job:U0000000008329 sending job to queue SaveLoad
12:05:12 Scheduling new unfirm job:U0000000008444
12:05:13 Done Scheduling job:U0000000008444 sending job to queue SaveLoad
12:05:13 Scheduling new unfirm job:U0000000008445
12:05:14 Done Scheduling job:U0000000008445 sending job to queue SaveLoad
12:05:14 Scheduling new unfirm job:U0000000008331
12:05:14 Done Scheduling job:U0000000008331 sending job to queue SaveLoad
12:05:14 Scheduling new unfirm job:U0000000008446
12:05:15 Done Scheduling job:U0000000008446 sending job to queue SaveLoad
12:05:15 Scheduling new unfirm job:U0000000008242
12:05:15 Done Scheduling job:U0000000008242 sending job to queue SaveLoad
12:05:15 Scheduling new unfirm job:U0000000008243
12:05:16 Done Scheduling job:U0000000008243 sending job to queue SaveLoad
12:05:16 Scheduling new unfirm job:U0000000008334
12:05:17 Done Scheduling job:U0000000008334 sending job to queue SaveLoad
12:05:17 Scheduling new unfirm job:U0000000008448
12:05:17 Done Scheduling job:U0000000008448 sending job to queue SaveLoad
12:05:17 Scheduling new unfirm job:U0000000008244
12:05:18 Done Scheduling job:U0000000008244 sending job to queue SaveLoad
12:05:18 Scheduling new unfirm job:U0000000008245
12:05:19 Done Scheduling job:U0000000008245 sending job to queue SaveLoad
12:05:19 Scheduling new unfirm job:U0000000008246
12:05:20 Done Scheduling job:U0000000008246 sending job to queue SaveLoad
12:05:20 Scheduling new unfirm job:U0000000008248
12:05:21 Done Scheduling job:U0000000008248 sending job to queue SaveLoad
12:05:21 Scheduling new unfirm job:U0000000008452
12:05:22 Done Scheduling job:U0000000008452 sending job to queue SaveLoad
12:05:22 Scheduling new unfirm job:U0000000008453
12:05:22 Done Scheduling job:U0000000008453 sending job to queue SaveLoad
12:05:22 Scheduling new unfirm job:U0000000008454
12:05:22 Done Scheduling job:U0000000008454 sending job to queue SaveLoad
12:05:22 Scheduling new unfirm job:U0000000008455
12:05:23 Done Scheduling job:U0000000008455 sending job to queue SaveLoad
12:05:23 Scheduling new unfirm job:U0000000008456
12:05:23 Done Scheduling job:U0000000008456 sending job to queue SaveLoad
12:05:23 Scheduling new unfirm job:U0000000008457
12:05:24 Done Scheduling job:U0000000008457 sending job to queue SaveLoad
12:05:24 Scheduling new unfirm job:U0000000008458
12:05:24 Done Scheduling job:U0000000008458 sending job to queue SaveLoad
12:05:24 Scheduling new unfirm job:U0000000008459
12:05:25 Done Scheduling job:U0000000008459 sending job to queue SaveLoad
12:05:25 Scheduling new unfirm job:U0000000008250
12:05:25 Done Scheduling job:U0000000008250 sending job to queue SaveLoad
12:05:25 Scheduling new unfirm job:U0000000008461
12:05:25 Done Scheduling job:U0000000008461 sending job to queue SaveLoad
12:05:26 Scheduling new unfirm job:U0000000008251
12:05:26 Done Scheduling job:U0000000008251 sending job to queue SaveLoad
12:05:26 Scheduling new unfirm job:U0000000008462
12:05:26 Done Scheduling job:U0000000008462 sending job to queue SaveLoad
12:05:26 Scheduling new unfirm job:U0000000008463
12:05:27 Done Scheduling job:U0000000008463 sending job to queue SaveLoad
12:05:27 Scheduling new unfirm job:U0000000008253
12:05:27 Done Scheduling job:U0000000008253 sending job to queue SaveLoad
12:05:27 Scheduling new unfirm job:U0000000008464
12:05:28 Done Scheduling job:U0000000008464 sending job to queue SaveLoad
12:05:28 Scheduling new unfirm job:U0000000008254
12:05:28 Done Scheduling job:U0000000008254 sending job to queue SaveLoad
12:05:29 Scheduling new unfirm job:U0000000008256
12:05:30 Done Scheduling job:U0000000008256 sending job to queue SaveLoad
12:05:30 Scheduling new unfirm job:U0000000008346
12:05:31 Done Scheduling job:U0000000008346 sending job to queue SaveLoad
12:05:31 Scheduling new unfirm job:U0000000008467
12:05:31 Done Scheduling job:U0000000008467 sending job to queue SaveLoad
12:05:31 Scheduling new unfirm job:U0000000008468
12:05:31 Done Scheduling job:U0000000008468 sending job to queue SaveLoad
12:05:31 Scheduling new unfirm job:U0000000008469
12:05:32 Done Scheduling job:U0000000008469 sending job to queue SaveLoad
12:05:32 Scheduling new unfirm job:U0000000008470
12:05:32 Done Scheduling job:U0000000008470 sending job to queue SaveLoad
12:05:34 Scheduling new unfirm job:U0000000008353
12:05:34 Done Scheduling job:U0000000008353 sending job to queue SaveLoad
12:05:35 Scheduling new unfirm job:U0000000008473
12:05:35 Done Scheduling job:U0000000008473 sending job to queue SaveLoad
12:05:35 Scheduling new unfirm job:U0000000008354
12:05:35 Done Scheduling job:U0000000008354 sending job to queue SaveLoad
12:05:35 Scheduling new unfirm job:U0000000008474
12:05:36 Done Scheduling job:U0000000008474 sending job to queue SaveLoad
12:05:36 Scheduling new unfirm job:U0000000008355
12:05:36 Done Scheduling job:U0000000008355 sending job to queue SaveLoad
12:05:36 Scheduling new unfirm job:U0000000008475
12:05:37 Done Scheduling job:U0000000008475 sending job to queue SaveLoad
12:05:37 Scheduling new unfirm job:U0000000008356
12:05:37 Done Scheduling job:U0000000008356 sending job to queue SaveLoad
12:05:37 Scheduling new unfirm job:U0000000008476
12:05:37 Done Scheduling job:U0000000008476 sending job to queue SaveLoad
12:05:37 Scheduling new unfirm job:U0000000008357
12:05:38 Done Scheduling job:U0000000008357 sending job to queue SaveLoad
12:05:38 Scheduling new unfirm job:U0000000008477
12:05:38 Done Scheduling job:U0000000008477 sending job to queue SaveLoad
12:05:38 Scheduling new unfirm job:U0000000008358
12:05:39 Done Scheduling job:U0000000008358 sending job to queue SaveLoad
12:05:39 Scheduling new unfirm job:U0000000008478
12:05:39 Done Scheduling job:U0000000008478 sending job to queue SaveLoad
12:05:39 Scheduling new unfirm job:U0000000008359
12:05:40 Done Scheduling job:U0000000008359 sending job to queue SaveLoad
12:05:40 Scheduling new unfirm job:U0000000008479
12:05:40 Done Scheduling job:U0000000008479 sending job to queue SaveLoad
12:05:40 Scheduling new unfirm job:U0000000008360
12:05:40 Done Scheduling job:U0000000008360 sending job to queue SaveLoad
12:05:40 Scheduling new unfirm job:U0000000008480
12:05:41 Done Scheduling job:U0000000008480 sending job to queue SaveLoad
12:05:41 Scheduling new unfirm job:U0000000008361
12:05:41 Done Scheduling job:U0000000008361 sending job to queue SaveLoad
12:05:41 Scheduling new unfirm job:U0000000008481
12:05:41 Done Scheduling job:U0000000008481 sending job to queue SaveLoad
12:05:42 Scheduling new unfirm job:U0000000008362
12:05:42 Done Scheduling job:U0000000008362 sending job to queue SaveLoad
12:05:42 Scheduling new unfirm job:U0000000008482
12:05:42 Done Scheduling job:U0000000008482 sending job to queue SaveLoad
12:05:42 Scheduling new unfirm job:U0000000008363
12:05:43 Done Scheduling job:U0000000008363 sending job to queue SaveLoad
12:05:43 Scheduling new unfirm job:U0000000008483
12:05:43 Done Scheduling job:U0000000008483 sending job to queue SaveLoad
12:05:43 Scheduling new unfirm job:U0000000008364
12:05:44 Done Scheduling job:U0000000008364 sending job to queue SaveLoad
12:05:44 Scheduling new unfirm job:U0000000008484
12:05:44 Done Scheduling job:U0000000008484 sending job to queue SaveLoad
12:05:44 Scheduling new unfirm job:U0000000008365
12:05:44 Done Scheduling job:U0000000008365 sending job to queue SaveLoad
12:05:44 Scheduling new unfirm job:U0000000008485
12:05:45 Done Scheduling job:U0000000008485 sending job to queue SaveLoad
12:05:45 Scheduling new unfirm job:U0000000008580
12:05:45 Done Scheduling job:U0000000008580 sending job to queue SaveLoad
12:05:45 Scheduling new unfirm job:U0000000008581
12:05:46 Done Scheduling job:U0000000008581 sending job to queue SaveLoad
12:05:46 Scheduling new unfirm job:U0000000008367
12:05:46 Done Scheduling job:U0000000008367 sending job to queue SaveLoad
12:05:46 Scheduling new unfirm job:U0000000008582
12:05:47 Done Scheduling job:U0000000008582 sending job to queue SaveLoad
12:05:47 Scheduling new unfirm job:U0000000008668
12:05:47 Done Scheduling job:U0000000008668 sending job to queue SaveLoad
12:05:47 Scheduling new unfirm job:U0000000008669
12:05:48 Done Scheduling job:U0000000008669 sending job to queue SaveLoad
12:05:48 Scheduling new unfirm job:U0000000008670
12:05:48 Done Scheduling job:U0000000008670 sending job to queue SaveLoad
12:05:48 Scheduling new unfirm job:U0000000008671
12:05:49 Done Scheduling job:U0000000008671 sending job to queue SaveLoad
12:05:49 Scheduling new unfirm job:U0000000008672
12:05:49 Done Scheduling job:U0000000008672 sending job to queue SaveLoad
12:05:49 Scheduling new unfirm job:U0000000008673
12:05:50 Done Scheduling job:U0000000008673 sending job to queue SaveLoad
12:05:50 Scheduling new unfirm job:U0000000008583
12:05:50 Done Scheduling job:U0000000008583 sending job to queue SaveLoad
12:05:50 Scheduling new unfirm job:U0000000008584
12:05:51 Done Scheduling job:U0000000008584 sending job to queue SaveLoad
12:05:51 Scheduling new unfirm job:U0000000008674
12:05:51 Done Scheduling job:U0000000008674 sending job to queue SaveLoad
12:05:51 Scheduling new unfirm job:U0000000008585
12:05:52 Done Scheduling job:U0000000008585 sending job to queue SaveLoad
12:05:52 Scheduling new unfirm job:U0000000008675
12:05:52 Done Scheduling job:U0000000008675 sending job to queue SaveLoad
12:05:52 Scheduling new unfirm job:U0000000008586
12:05:52 Done Scheduling job:U0000000008586 sending job to queue SaveLoad
12:05:52 Scheduling new unfirm job:U0000000008676
12:05:53 Done Scheduling job:U0000000008676 sending job to queue SaveLoad
12:05:53 Scheduling new unfirm job:U0000000008587
12:05:54 Done Scheduling job:U0000000008587 sending job to queue SaveLoad
12:05:54 Scheduling new unfirm job:U0000000008677
12:05:54 Done Scheduling job:U0000000008677 sending job to queue SaveLoad
12:05:54 Scheduling new unfirm job:U0000000008588
12:05:55 Done Scheduling job:U0000000008588 sending job to queue SaveLoad
12:05:55 Scheduling new unfirm job:U0000000008678
12:05:56 Done Scheduling job:U0000000008678 sending job to queue SaveLoad
12:05:56 Scheduling new unfirm job:U0000000008589
12:05:56 Done Scheduling job:U0000000008589 sending job to queue SaveLoad
12:05:56 Scheduling new unfirm job:U0000000008679
12:05:57 Done Scheduling job:U0000000008679 sending job to queue SaveLoad
12:05:58 Scheduling new unfirm job:U0000000008590
12:05:59 Done Scheduling job:U0000000008590 sending job to queue SaveLoad
12:05:59 Scheduling new unfirm job:U0000000008680
12:05:59 Done Scheduling job:U0000000008680 sending job to queue SaveLoad
12:05:59 Scheduling new unfirm job:U0000000008592
12:05:59 Done Scheduling job:U0000000008592 sending job to queue SaveLoad
12:05:59 Scheduling new unfirm job:U0000000008682
12:06:00 Done Scheduling job:U0000000008682 sending job to queue SaveLoad
12:06:00 Scheduling new unfirm job:U0000000008595
12:06:00 Done Scheduling job:U0000000008595 sending job to queue SaveLoad
12:06:00 Scheduling new unfirm job:U0000000008685
12:06:01 Done Scheduling job:U0000000008685 sending job to queue SaveLoad
12:06:01 Scheduling new unfirm job:U0000000008686
12:06:01 Done Scheduling job:U0000000008686 sending job to queue SaveLoad
12:06:01 Scheduling new unfirm job:U0000000008687
12:06:01 Done Scheduling job:U0000000008687 sending job to queue SaveLoad
12:06:02 Scheduling new unfirm job:U0000000008499
12:06:02 Done Scheduling job:U0000000008499 sending job to queue SaveLoad
12:06:02 Scheduling new unfirm job:U0000000008500
12:06:03 Done Scheduling job:U0000000008500 sending job to queue SaveLoad
12:06:03 Scheduling new unfirm job:U0000000008689
12:06:03 Done Scheduling job:U0000000008689 sending job to queue SaveLoad
12:06:03 Scheduling new unfirm job:U0000000008598
12:06:04 Done Scheduling job:U0000000008598 sending job to queue SaveLoad
12:06:04 Scheduling new unfirm job:U0000000008503
12:06:04 Done Scheduling job:U0000000008503 sending job to queue SaveLoad
12:06:04 Scheduling new unfirm job:U0000000008599
12:06:04 Done Scheduling job:U0000000008599 sending job to queue SaveLoad
12:06:04 Scheduling new unfirm job:U0000000008504
12:06:05 Done Scheduling job:U0000000008504 sending job to queue SaveLoad
12:06:05 Scheduling new unfirm job:U0000000008505
12:06:06 Done Scheduling job:U0000000008505 sending job to queue SaveLoad
12:06:06 Scheduling new unfirm job:U0000000008691
12:06:06 Done Scheduling job:U0000000008691 sending job to queue SaveLoad
12:06:06 Scheduling new unfirm job:U0000000008605
12:06:06 Done Scheduling job:U0000000008605 sending job to queue SaveLoad
12:06:06 Scheduling new unfirm job:U0000000008507
12:06:07 Done Scheduling job:U0000000008507 sending job to queue SaveLoad
12:06:07 Scheduling new unfirm job:U0000000008692
12:06:08 Done Scheduling job:U0000000008692 sending job to queue SaveLoad
12:06:08 Scheduling new unfirm job:U0000000008609
12:06:08 Done Scheduling job:U0000000008609 sending job to queue SaveLoad
12:06:08 Scheduling new unfirm job:U0000000008693
12:06:09 Done Scheduling job:U0000000008693 sending job to queue SaveLoad
12:06:09 Scheduling new unfirm job:U0000000008694
12:06:09 Done Scheduling job:U0000000008694 sending job to queue SaveLoad
12:06:09 Scheduling new unfirm job:U0000000008512
12:06:10 Done Scheduling job:U0000000008512 sending job to queue SaveLoad
12:06:10 Scheduling new unfirm job:U0000000008696
12:06:11 Done Scheduling job:U0000000008696 sending job to queue SaveLoad
12:06:11 Scheduling new unfirm job:U0000000008697
12:06:11 Done Scheduling job:U0000000008697 sending job to queue SaveLoad
12:06:11 Scheduling new unfirm job:U0000000008515
12:06:12 Done Scheduling job:U0000000008515 sending job to queue SaveLoad
12:06:12 Scheduling new unfirm job:U0000000008516
12:06:13 Done Scheduling job:U0000000008516 sending job to queue SaveLoad
12:06:13 Scheduling new unfirm job:U0000000008612
12:06:13 Done Scheduling job:U0000000008612 sending job to queue SaveLoad
12:06:13 Scheduling new unfirm job:U0000000008613
12:06:14 Done Scheduling job:U0000000008613 sending job to queue SaveLoad
12:06:14 Scheduling new unfirm job:U0000000008614
12:06:14 Done Scheduling job:U0000000008614 sending job to queue SaveLoad
12:06:18 Scheduling new unfirm job:U0000000008616
12:06:19 Done Scheduling job:U0000000008616 sending job to queue SaveLoad
12:06:19 Scheduling new unfirm job:U0000000008617
12:06:20 Done Scheduling job:U0000000008617 sending job to queue SaveLoad
12:06:20 Scheduling new unfirm job:U0000000008701
12:06:21 Done Scheduling job:U0000000008701 sending job to queue SaveLoad
12:06:21 Scheduling new unfirm job:U0000000008702
12:06:22 Done Scheduling job:U0000000008702 sending job to queue SaveLoad
12:06:22 Scheduling new unfirm job:U0000000008620
12:06:23 Done Scheduling job:U0000000008620 sending job to queue SaveLoad
12:06:23 Scheduling new unfirm job:U0000000008621
12:06:24 Done Scheduling job:U0000000008621 sending job to queue SaveLoad
12:06:24 Scheduling new unfirm job:U0000000008704
12:06:28 Done Scheduling job:U0000000008704 sending job to queue SaveLoad
12:06:28 Scheduling new unfirm job:U0000000008622
12:06:31 Done Scheduling job:U0000000008622 sending job to queue SaveLoad
12:06:32 Scheduling new unfirm job:U0000000008623
12:06:33 Done Scheduling job:U0000000008623 sending job to queue SaveLoad
12:06:33 Scheduling new unfirm job:U0000000008624
12:06:34 Done Scheduling job:U0000000008624 sending job to queue SaveLoad
12:06:34 Scheduling new unfirm job:U0000000008625
12:06:35 Done Scheduling job:U0000000008625 sending job to queue SaveLoad
12:06:35 Scheduling new unfirm job:U0000000008626
12:06:35 Done Scheduling job:U0000000008626 sending job to queue SaveLoad
12:06:35 Scheduling new unfirm job:U0000000008627
12:06:37 Done Scheduling job:U0000000008627 sending job to queue SaveLoad
12:06:37 Scheduling new unfirm job:U0000000008628
12:06:39 Done Scheduling job:U0000000008628 sending job to queue SaveLoad
12:06:39 Scheduling new unfirm job:U0000000008629
12:06:40 Done Scheduling job:U0000000008629 sending job to queue SaveLoad
12:06:40 Scheduling new unfirm job:U0000000008713
12:06:41 Done Scheduling job:U0000000008713 sending job to queue SaveLoad
12:06:41 Scheduling new unfirm job:U0000000008532
12:06:41 Done Scheduling job:U0000000008532 sending job to queue SaveLoad
12:06:41 Scheduling new unfirm job:U0000000008714
12:06:42 Done Scheduling job:U0000000008714 sending job to queue SaveLoad
12:06:42 Scheduling new unfirm job:U0000000008533
12:06:43 Done Scheduling job:U0000000008533 sending job to queue SaveLoad
12:06:43 Scheduling new unfirm job:U0000000008715
12:06:44 Done Scheduling job:U0000000008715 sending job to queue SaveLoad
12:06:44 Scheduling new unfirm job:U0000000008534
12:06:44 Done Scheduling job:U0000000008534 sending job to queue SaveLoad
12:06:44 Scheduling new unfirm job:U0000000008716
12:06:45 Done Scheduling job:U0000000008716 sending job to queue SaveLoad
12:06:45 Scheduling new unfirm job:U0000000008535
12:06:46 Done Scheduling job:U0000000008535 sending job to queue SaveLoad
12:06:46 Scheduling new unfirm job:U0000000008717
12:06:47 Done Scheduling job:U0000000008717 sending job to queue SaveLoad
12:06:47 Scheduling new unfirm job:U0000000008536
12:06:47 Done Scheduling job:U0000000008536 sending job to queue SaveLoad
12:06:47 Scheduling new unfirm job:U0000000008537
12:06:48 Done Scheduling job:U0000000008537 sending job to queue SaveLoad
12:06:48 Scheduling new unfirm job:U0000000008632
12:06:49 Done Scheduling job:U0000000008632 sending job to queue SaveLoad
12:06:49 Scheduling new unfirm job:U0000000008538
12:06:50 Done Scheduling job:U0000000008538 sending job to queue SaveLoad
12:06:50 Scheduling new unfirm job:U0000000008633
12:06:51 Done Scheduling job:U0000000008633 sending job to queue SaveLoad
12:06:51 Scheduling new unfirm job:U0000000008539
12:06:51 Done Scheduling job:U0000000008539 sending job to queue SaveLoad
12:06:51 Scheduling new unfirm job:U0000000008634
12:06:52 Done Scheduling job:U0000000008634 sending job to queue SaveLoad
12:06:52 Scheduling new unfirm job:U0000000008540
12:06:53 Done Scheduling job:U0000000008540 sending job to queue SaveLoad
12:06:53 Scheduling new unfirm job:U0000000008541
12:06:54 Done Scheduling job:U0000000008541 sending job to queue SaveLoad
12:06:54 Scheduling new unfirm job:U0000000008542
12:06:54 Done Scheduling job:U0000000008542 sending job to queue SaveLoad
12:06:54 Scheduling new unfirm job:U0000000008635
12:06:55 Done Scheduling job:U0000000008635 sending job to queue SaveLoad
12:06:55 Scheduling new unfirm job:U0000000008543
12:06:56 Done Scheduling job:U0000000008543 sending job to queue SaveLoad
12:06:56 Scheduling new unfirm job:U0000000008544
12:06:56 Done Scheduling job:U0000000008544 sending job to queue SaveLoad
12:06:56 Scheduling new unfirm job:U0000000008636
12:06:57 Done Scheduling job:U0000000008636 sending job to queue SaveLoad
12:06:57 Scheduling new unfirm job:U0000000008720
12:06:58 Done Scheduling job:U0000000008720 sending job to queue SaveLoad
12:06:58 Scheduling new unfirm job:U0000000008547
12:06:59 Done Scheduling job:U0000000008547 sending job to queue SaveLoad
12:06:59 Scheduling new unfirm job:U0000000008722
12:07:00 Done Scheduling job:U0000000008722 sending job to queue SaveLoad
12:07:00 Scheduling new unfirm job:U0000000008548
12:07:00 Done Scheduling job:U0000000008548 sending job to queue SaveLoad
12:07:00 Scheduling new unfirm job:U0000000008637
12:07:01 Done Scheduling job:U0000000008637 sending job to queue SaveLoad
12:07:01 Scheduling new unfirm job:U0000000008549
12:07:02 Done Scheduling job:U0000000008549 sending job to queue SaveLoad
12:07:02 Scheduling new unfirm job:U0000000008550
12:07:02 Done Scheduling job:U0000000008550 sending job to queue SaveLoad
12:07:02 Scheduling new unfirm job:U0000000008723
12:07:03 Done Scheduling job:U0000000008723 sending job to queue SaveLoad
12:07:03 Scheduling new unfirm job:U0000000008551
12:07:04 Done Scheduling job:U0000000008551 sending job to queue SaveLoad
12:07:04 Scheduling new unfirm job:U0000000008638
12:07:05 Done Scheduling job:U0000000008638 sending job to queue SaveLoad
12:07:05 Scheduling new unfirm job:U0000000008639
12:07:05 Done Scheduling job:U0000000008639 sending job to queue SaveLoad
12:07:05 Scheduling new unfirm job:U0000000008640
12:07:06 Done Scheduling job:U0000000008640 sending job to queue SaveLoad
12:07:06 Scheduling new unfirm job:U0000000008553
12:07:07 Done Scheduling job:U0000000008553 sending job to queue SaveLoad
12:07:07 Scheduling new unfirm job:U0000000008641
12:07:08 Done Scheduling job:U0000000008641 sending job to queue SaveLoad
12:07:08 Scheduling new unfirm job:U0000000008725
12:07:08 Done Scheduling job:U0000000008725 sending job to queue SaveLoad
12:07:09 Scheduling new unfirm job:U0000000008642
12:07:09 Done Scheduling job:U0000000008642 sending job to queue SaveLoad
12:07:09 Scheduling new unfirm job:U0000000008726
12:07:10 Done Scheduling job:U0000000008726 sending job to queue SaveLoad
12:07:10 Scheduling new unfirm job:U0000000008554
12:07:11 Done Scheduling job:U0000000008554 sending job to queue SaveLoad
12:07:11 Scheduling new unfirm job:U0000000008643
12:07:12 Done Scheduling job:U0000000008643 sending job to queue SaveLoad
12:07:12 Scheduling new unfirm job:U0000000008727
12:07:12 Done Scheduling job:U0000000008727 sending job to queue SaveLoad
12:07:12 Scheduling new unfirm job:U0000000008555
12:07:13 Done Scheduling job:U0000000008555 sending job to queue SaveLoad
12:07:13 Scheduling new unfirm job:U0000000008644
12:07:14 Done Scheduling job:U0000000008644 sending job to queue SaveLoad
12:07:14 Scheduling new unfirm job:U0000000008729
12:07:15 Done Scheduling job:U0000000008729 sending job to queue SaveLoad
12:07:15 Scheduling new unfirm job:U0000000008645
12:07:16 Done Scheduling job:U0000000008645 sending job to queue SaveLoad
12:07:16 Scheduling new unfirm job:U0000000008731
12:07:16 Done Scheduling job:U0000000008731 sending job to queue SaveLoad
12:07:16 Scheduling new unfirm job:U0000000008732
12:07:17 Done Scheduling job:U0000000008732 sending job to queue SaveLoad
12:07:17 Scheduling new unfirm job:U0000000008733
12:07:17 Done Scheduling job:U0000000008733 sending job to queue SaveLoad
12:07:17 Scheduling new unfirm job:U0000000008735
12:07:17 Done Scheduling job:U0000000008735 sending job to queue SaveLoad
12:07:17 Scheduling new unfirm job:U0000000008647
12:07:17 Done Scheduling job:U0000000008647 sending job to queue SaveLoad
12:07:17 Scheduling new unfirm job:U0000000008738
12:07:18 Done Scheduling job:U0000000008738 sending job to queue SaveLoad
12:07:18 Scheduling new unfirm job:U0000000008740
12:07:18 Done Scheduling job:U0000000008740 sending job to queue SaveLoad
12:07:18 Scheduling new unfirm job:U0000000008650
12:07:18 Done Scheduling job:U0000000008650 sending job to queue SaveLoad
12:07:18 Scheduling new unfirm job:U0000000008651
12:07:19 Done Scheduling job:U0000000008651 sending job to queue SaveLoad
12:07:19 Scheduling new unfirm job:U0000000008652
12:07:20 Done Scheduling job:U0000000008652 sending job to queue SaveLoad
12:07:20 Scheduling new unfirm job:U0000000008563
12:07:21 Done Scheduling job:U0000000008563 sending job to queue SaveLoad
12:07:21 Scheduling new unfirm job:U0000000008564
12:07:21 Done Scheduling job:U0000000008564 sending job to queue SaveLoad
12:07:21 Scheduling new unfirm job:U0000000008653
12:07:22 Done Scheduling job:U0000000008653 sending job to queue SaveLoad
12:07:22 Scheduling new unfirm job:U0000000008565
12:07:23 Done Scheduling job:U0000000008565 sending job to queue SaveLoad
12:07:23 Scheduling new unfirm job:U0000000008566
12:07:24 Done Scheduling job:U0000000008566 sending job to queue SaveLoad
12:07:24 Scheduling new unfirm job:U0000000008567
12:07:24 Done Scheduling job:U0000000008567 sending job to queue SaveLoad
12:07:24 Scheduling new unfirm job:U0000000008768
12:07:25 Done Scheduling job:U0000000008768 sending job to queue SaveLoad
12:07:25 Scheduling new unfirm job:U0000000008770
12:07:26 Done Scheduling job:U0000000008770 sending job to queue SaveLoad
12:07:26 Scheduling new unfirm job:U0000000008658
12:07:26 Done Scheduling job:U0000000008658 sending job to queue SaveLoad
12:07:26 Scheduling new unfirm job:U0000000008659
12:07:27 Done Scheduling job:U0000000008659 sending job to queue SaveLoad
12:07:27 Scheduling new unfirm job:U0000000008773
12:07:28 Done Scheduling job:U0000000008773 sending job to queue SaveLoad
12:07:28 Scheduling new unfirm job:U0000000008775
12:07:28 Done Scheduling job:U0000000008775 sending job to queue SaveLoad
12:07:28 Scheduling new unfirm job:U0000000008752
12:07:29 Done Scheduling job:U0000000008752 sending job to queue SaveLoad
12:07:29 Scheduling new unfirm job:U0000000008753
12:07:29 Done Scheduling job:U0000000008753 sending job to queue SaveLoad
12:07:29 Scheduling new unfirm job:U0000000008754
12:07:29 Done Scheduling job:U0000000008754 sending job to queue SaveLoad
12:07:29 Scheduling new unfirm job:U0000000008755
12:07:30 Done Scheduling job:U0000000008755 sending job to queue SaveLoad
12:07:30 Scheduling new unfirm job:U0000000008756
12:07:30 Done Scheduling job:U0000000008756 sending job to queue SaveLoad
12:07:30 Scheduling new unfirm job:U0000000008757
12:07:30 Done Scheduling job:U0000000008757 sending job to queue SaveLoad
12:07:30 Scheduling new unfirm job:U0000000008758
12:07:31 Done Scheduling job:U0000000008758 sending job to queue SaveLoad
12:07:31 Scheduling new unfirm job:U0000000008759
12:07:31 Done Scheduling job:U0000000008759 sending job to queue SaveLoad
12:07:31 Scheduling new unfirm job:U0000000008760
12:07:31 Done Scheduling job:U0000000008760 sending job to queue SaveLoad
12:07:31 Scheduling new unfirm job:U0000000008761
12:07:32 Done Scheduling job:U0000000008761 sending job to queue SaveLoad
12:07:32 Scheduling new unfirm job:U0000000008762
12:07:32 Done Scheduling job:U0000000008762 sending job to queue SaveLoad
12:07:32 Scheduling new unfirm job:U0000000008776
12:07:32 Done Scheduling job:U0000000008776 sending job to queue SaveLoad
12:07:32 Scheduling new unfirm job:U0000000008661
12:07:34 Done Scheduling job:U0000000008661 sending job to queue SaveLoad
12:07:34 Scheduling new unfirm job:U0000000008764
12:07:34 Done Scheduling job:U0000000008764 sending job to queue SaveLoad
12:07:34 Scheduling new unfirm job:U0000000008765
12:07:35 Done Scheduling job:U0000000008765 sending job to queue SaveLoad
12:07:35 Scheduling new unfirm job:U0000000008662
12:07:36 Done Scheduling job:U0000000008662 sending job to queue SaveLoad
12:07:36 Scheduling new unfirm job:U0000000008779
12:07:37 Done Scheduling job:U0000000008779 sending job to queue SaveLoad
12:07:37 Scheduling new unfirm job:U0000000008766
12:07:38 Done Scheduling job:U0000000008766 sending job to queue SaveLoad
12:07:38 Scheduling new unfirm job:U0000000008767
12:07:38 Done Scheduling job:U0000000008767 sending job to queue SaveLoad
12:07:38 Scheduling new unfirm job:U0000000008663
12:07:39 Done Scheduling job:U0000000008663 sending job to queue SaveLoad
12:07:39 Scheduling new unfirm job:U0000000008869
12:07:40 Done Scheduling job:U0000000008869 sending job to queue SaveLoad
12:07:40 Scheduling new unfirm job:U0000000008664
12:07:41 Done Scheduling job:U0000000008664 sending job to queue SaveLoad
12:07:41 Scheduling new unfirm job:U0000000008871
12:07:42 Done Scheduling job:U0000000008871 sending job to queue SaveLoad
12:07:42 Scheduling new unfirm job:U0000000008665
12:07:44 Done Scheduling job:U0000000008665 sending job to queue SaveLoad
12:07:44 Scheduling new unfirm job:U0000000008667
12:07:46 Done Scheduling job:U0000000008667 sending job to queue SaveLoad
12:07:46 Scheduling new unfirm job:U0000000008969
12:07:47 Done Scheduling job:U0000000008969 sending job to queue SaveLoad
12:07:47 Scheduling new unfirm job:U0000000008877
12:07:48 Done Scheduling job:U0000000008877 sending job to queue SaveLoad
12:07:48 Scheduling new unfirm job:U0000000008878
12:07:49 Done Scheduling job:U0000000008878 sending job to queue SaveLoad
12:07:49 Scheduling new unfirm job:U0000000008879
12:07:50 Done Scheduling job:U0000000008879 sending job to queue SaveLoad
12:07:50 Scheduling new unfirm job:U0000000008880
12:07:50 Done Scheduling job:U0000000008880 sending job to queue SaveLoad
12:07:50 Scheduling new unfirm job:U0000000008881
12:07:51 Done Scheduling job:U0000000008881 sending job to queue SaveLoad
12:07:51 Scheduling new unfirm job:U0000000008971
12:07:52 Done Scheduling job:U0000000008971 sending job to queue SaveLoad
12:07:52 Scheduling new unfirm job:U0000000008972
12:07:52 Done Scheduling job:U0000000008972 sending job to queue SaveLoad
12:07:52 Scheduling new unfirm job:U0000000008792
12:07:53 Done Scheduling job:U0000000008792 sending job to queue SaveLoad
12:07:53 Scheduling new unfirm job:U0000000008793
12:07:54 Done Scheduling job:U0000000008793 sending job to queue SaveLoad
12:07:54 Scheduling new unfirm job:U0000000008794
12:07:54 Done Scheduling job:U0000000008794 sending job to queue SaveLoad
12:07:54 Scheduling new unfirm job:U0000000008795
12:07:55 Done Scheduling job:U0000000008795 sending job to queue SaveLoad
12:07:55 Scheduling new unfirm job:U0000000008796
12:07:56 Done Scheduling job:U0000000008796 sending job to queue SaveLoad
12:07:56 Scheduling new unfirm job:U0000000008798
12:07:56 Done Scheduling job:U0000000008798 sending job to queue SaveLoad
12:07:56 Scheduling new unfirm job:U0000000008974
12:07:57 Done Scheduling job:U0000000008974 sending job to queue SaveLoad
12:07:57 Scheduling new unfirm job:U0000000008976
12:07:58 Done Scheduling job:U0000000008976 sending job to queue SaveLoad
12:07:58 Scheduling new unfirm job:U0000000008978
12:07:59 Done Scheduling job:U0000000008978 sending job to queue SaveLoad
12:07:59 Scheduling new unfirm job:U0000000008979
12:08:00 Done Scheduling job:U0000000008979 sending job to queue SaveLoad
12:08:00 Scheduling new unfirm job:U0000000008980
12:08:01 Done Scheduling job:U0000000008980 sending job to queue SaveLoad
12:08:01 Scheduling new unfirm job:U0000000008803
12:08:02 Done Scheduling job:U0000000008803 sending job to queue SaveLoad
12:08:02 Scheduling new unfirm job:U0000000008804
12:08:03 Done Scheduling job:U0000000008804 sending job to queue SaveLoad
12:08:03 Scheduling new unfirm job:U0000000008805
12:08:04 Done Scheduling job:U0000000008805 sending job to queue SaveLoad
12:08:04 Scheduling new unfirm job:U0000000008807
12:08:04 Done Scheduling job:U0000000008807 sending job to queue SaveLoad
12:08:04 Scheduling new unfirm job:U0000000008809
12:08:05 Done Scheduling job:U0000000008809 sending job to queue SaveLoad
12:08:05 Scheduling new unfirm job:U0000000008888
12:08:06 Done Scheduling job:U0000000008888 sending job to queue SaveLoad
12:08:06 Scheduling new unfirm job:U0000000008890
12:08:07 Done Scheduling job:U0000000008890 sending job to queue SaveLoad
12:08:07 Scheduling new unfirm job:U0000000008986
12:08:08 Done Scheduling job:U0000000008986 sending job to queue SaveLoad
12:08:08 Scheduling new unfirm job:U0000000008891
12:08:09 Done Scheduling job:U0000000008891 sending job to queue SaveLoad
12:08:09 Scheduling new unfirm job:U0000000008988
12:08:10 Done Scheduling job:U0000000008988 sending job to queue SaveLoad
12:08:10 Scheduling new unfirm job:U0000000008989
12:08:11 Done Scheduling job:U0000000008989 sending job to queue SaveLoad
12:08:11 Scheduling new unfirm job:U0000000008893
12:08:12 Done Scheduling job:U0000000008893 sending job to queue SaveLoad
12:08:12 Scheduling new unfirm job:U0000000008990
12:08:12 Done Scheduling job:U0000000008990 sending job to queue SaveLoad
12:08:12 Scheduling new unfirm job:U0000000008894
12:08:14 Done Scheduling job:U0000000008894 sending job to queue SaveLoad
12:08:14 Scheduling new unfirm job:U0000000008992
12:08:14 Done Scheduling job:U0000000008992 sending job to queue SaveLoad
12:08:14 Scheduling new unfirm job:U0000000008815
12:08:15 Done Scheduling job:U0000000008815 sending job to queue SaveLoad
12:08:15 Scheduling new unfirm job:U0000000008816
12:08:16 Done Scheduling job:U0000000008816 sending job to queue SaveLoad
12:08:16 Scheduling new unfirm job:U0000000008994
12:08:17 Done Scheduling job:U0000000008994 sending job to queue SaveLoad
12:08:17 Scheduling new unfirm job:U0000000008818
12:08:18 Done Scheduling job:U0000000008818 sending job to queue SaveLoad
12:08:18 Scheduling new unfirm job:U0000000008819
12:08:19 Done Scheduling job:U0000000008819 sending job to queue SaveLoad
12:08:19 Scheduling new unfirm job:U0000000008820
12:08:19 Done Scheduling job:U0000000008820 sending job to queue SaveLoad
12:08:19 Scheduling new unfirm job:U0000000008821
12:08:20 Done Scheduling job:U0000000008821 sending job to queue SaveLoad
12:08:20 Scheduling new unfirm job:U0000000008899
12:08:21 Done Scheduling job:U0000000008899 sending job to queue SaveLoad
12:08:21 Scheduling new unfirm job:U0000000008996
12:08:22 Done Scheduling job:U0000000008996 sending job to queue SaveLoad
12:08:22 Scheduling new unfirm job:U0000000008997
12:08:22 Done Scheduling job:U0000000008997 sending job to queue SaveLoad
12:08:22 Scheduling new unfirm job:U0000000008999
12:08:23 Done Scheduling job:U0000000008999 sending job to queue SaveLoad
12:08:23 Scheduling new unfirm job:U0000000008823
12:08:23 Done Scheduling job:U0000000008823 sending job to queue SaveLoad
12:08:23 Scheduling new unfirm job:U0000000009001
12:08:24 Done Scheduling job:U0000000009001 sending job to queue SaveLoad
12:08:24 Scheduling new unfirm job:U0000000008902
12:08:25 Done Scheduling job:U0000000008902 sending job to queue SaveLoad
12:08:25 Scheduling new unfirm job:U0000000009002
12:08:25 Done Scheduling job:U0000000009002 sending job to queue SaveLoad
12:08:25 Scheduling new unfirm job:U0000000008903
12:08:26 Done Scheduling job:U0000000008903 sending job to queue SaveLoad
12:08:26 Scheduling new unfirm job:U0000000009003
12:08:27 Done Scheduling job:U0000000009003 sending job to queue SaveLoad
12:08:27 Scheduling new unfirm job:U0000000008905
12:08:27 Done Scheduling job:U0000000008905 sending job to queue SaveLoad
12:08:27 Scheduling new unfirm job:U0000000008827
12:08:28 Done Scheduling job:U0000000008827 sending job to queue SaveLoad
12:08:28 Scheduling new unfirm job:U0000000008906
12:08:28 Done Scheduling job:U0000000008906 sending job to queue SaveLoad
12:08:28 Scheduling new unfirm job:U0000000008828
12:08:29 Done Scheduling job:U0000000008828 sending job to queue SaveLoad
12:08:29 Scheduling new unfirm job:U0000000008907
12:08:30 Done Scheduling job:U0000000008907 sending job to queue SaveLoad
12:08:30 Scheduling new unfirm job:U0000000008908
12:08:31 Done Scheduling job:U0000000008908 sending job to queue SaveLoad
12:08:31 Scheduling new unfirm job:U0000000008909
12:08:31 Done Scheduling job:U0000000008909 sending job to queue SaveLoad
12:08:31 Scheduling new unfirm job:U0000000008831
12:08:32 Done Scheduling job:U0000000008831 sending job to queue SaveLoad
12:08:32 Scheduling new unfirm job:U0000000008832
12:08:33 Done Scheduling job:U0000000008832 sending job to queue SaveLoad
12:08:33 Scheduling new unfirm job:U0000000009008
12:08:33 Done Scheduling job:U0000000009008 sending job to queue SaveLoad
12:08:33 Scheduling new unfirm job:U0000000009010
12:08:34 Done Scheduling job:U0000000009010 sending job to queue SaveLoad
12:08:34 Scheduling new unfirm job:U0000000008913
12:08:34 Done Scheduling job:U0000000008913 sending job to queue SaveLoad
12:08:34 Scheduling new unfirm job:U0000000008914
12:08:35 Done Scheduling job:U0000000008914 sending job to queue SaveLoad
12:08:35 Scheduling new unfirm job:U0000000008915
12:08:36 Done Scheduling job:U0000000008915 sending job to queue SaveLoad
12:08:36 Scheduling new unfirm job:U0000000009014
12:08:36 Done Scheduling job:U0000000009014 sending job to queue SaveLoad
12:08:36 Scheduling new unfirm job:U0000000008917
12:08:37 Done Scheduling job:U0000000008917 sending job to queue SaveLoad
12:08:37 Scheduling new unfirm job:U0000000008919
12:08:37 Done Scheduling job:U0000000008919 sending job to queue SaveLoad
12:08:37 Scheduling new unfirm job:U0000000008921
12:08:38 Done Scheduling job:U0000000008921 sending job to queue SaveLoad
12:08:38 Scheduling new unfirm job:U0000000008835
12:08:39 Done Scheduling job:U0000000008835 sending job to queue SaveLoad
12:08:39 Scheduling new unfirm job:U0000000008837
12:08:40 Done Scheduling job:U0000000008837 sending job to queue SaveLoad
12:08:40 Scheduling new unfirm job:U0000000008839
12:08:41 Done Scheduling job:U0000000008839 sending job to queue SaveLoad
12:08:41 Scheduling new unfirm job:U0000000008840
12:08:42 Done Scheduling job:U0000000008840 sending job to queue SaveLoad
12:08:42 Scheduling new unfirm job:U0000000009023
12:08:43 Done Scheduling job:U0000000009023 sending job to queue SaveLoad
12:08:43 Scheduling new unfirm job:U0000000009024
12:08:44 Done Scheduling job:U0000000009024 sending job to queue SaveLoad
12:08:44 Scheduling new unfirm job:U0000000008843
12:08:45 Done Scheduling job:U0000000008843 sending job to queue SaveLoad
12:08:45 Scheduling new unfirm job:U0000000008844
12:08:45 Done Scheduling job:U0000000008844 sending job to queue SaveLoad
12:08:45 Scheduling new unfirm job:U0000000008847
12:08:46 Done Scheduling job:U0000000008847 sending job to queue SaveLoad
12:08:46 Scheduling new unfirm job:U0000000008848
12:08:46 Done Scheduling job:U0000000008848 sending job to queue SaveLoad
12:08:46 Scheduling new unfirm job:U0000000008851
12:08:47 Done Scheduling job:U0000000008851 sending job to queue SaveLoad
12:08:49 Scheduling new unfirm job:U0000000008941
12:08:50 Done Scheduling job:U0000000008941 sending job to queue SaveLoad
12:09:14 Ending Part Level: 3-0.  Wait Time 00h:03m:42s, Jobs 314
12:09:14 Starting Part Level: 4-0.
12:09:14 Scheduling new unfirm job:U0000000008854
12:09:15 Done Scheduling job:U0000000008854 sending job to queue SaveLoad
12:09:15 Scheduling new unfirm job:U0000000008855
12:09:16 Done Scheduling job:U0000000008855 sending job to queue SaveLoad
12:09:16 Scheduling new unfirm job:U0000000008856
12:09:17 Done Scheduling job:U0000000008856 sending job to queue SaveLoad
12:09:17 Scheduling new unfirm job:U0000000009030
12:09:19 Done Scheduling job:U0000000009030 sending job to queue SaveLoad
12:09:19 Scheduling new unfirm job:U0000000008946
12:09:20 Done Scheduling job:U0000000008946 sending job to queue SaveLoad
12:09:20 Scheduling new unfirm job:U0000000009031
12:09:21 Done Scheduling job:U0000000009031 sending job to queue SaveLoad
12:09:21 Scheduling new unfirm job:U0000000009032
12:09:23 Done Scheduling job:U0000000009032 sending job to queue SaveLoad
12:09:23 Scheduling new unfirm job:U0000000008949
12:09:24 Done Scheduling job:U0000000008949 sending job to queue SaveLoad
12:09:24 Scheduling new unfirm job:U0000000009034
12:09:25 Done Scheduling job:U0000000009034 sending job to queue SaveLoad
12:09:25 Scheduling new unfirm job:U0000000008950
12:09:27 Done Scheduling job:U0000000008950 sending job to queue SaveLoad
12:09:27 Scheduling new unfirm job:U0000000009035
12:09:28 Done Scheduling job:U0000000009035 sending job to queue SaveLoad
12:09:28 Scheduling new unfirm job:U0000000008951
12:09:29 Done Scheduling job:U0000000008951 sending job to queue SaveLoad
12:09:29 Scheduling new unfirm job:U0000000008952
12:09:31 Done Scheduling job:U0000000008952 sending job to queue SaveLoad
12:09:31 Scheduling new unfirm job:U0000000008953
12:09:32 Done Scheduling job:U0000000008953 sending job to queue SaveLoad
12:09:32 Scheduling new unfirm job:U0000000009039
12:09:32 Done Scheduling job:U0000000009039 sending job to queue SaveLoad
12:09:32 Scheduling new unfirm job:U0000000009040
12:09:33 Done Scheduling job:U0000000009040 sending job to queue SaveLoad
12:09:33 Scheduling new unfirm job:U0000000008862
12:09:35 Done Scheduling job:U0000000008862 sending job to queue SaveLoad
12:09:35 Scheduling new unfirm job:U0000000008956
12:09:36 Done Scheduling job:U0000000008956 sending job to queue SaveLoad
12:09:36 Scheduling new unfirm job:U0000000009044
12:09:38 Done Scheduling job:U0000000009044 sending job to queue SaveLoad
12:09:38 Scheduling new unfirm job:U0000000008958
12:09:38 Done Scheduling job:U0000000008958 sending job to queue SaveLoad
12:09:38 Scheduling new unfirm job:U0000000009045
12:09:40 Done Scheduling job:U0000000009045 sending job to queue SaveLoad
12:09:42 Scheduling new unfirm job:U0000000009047
12:09:44 Done Scheduling job:U0000000009047 sending job to queue SaveLoad
12:09:44 Scheduling new unfirm job:U0000000008864
12:09:47 Done Scheduling job:U0000000008864 sending job to queue SaveLoad
12:09:47 Scheduling new unfirm job:U0000000009048
12:09:48 Done Scheduling job:U0000000009048 sending job to queue SaveLoad
12:09:48 Scheduling new unfirm job:U0000000009049
12:09:49 Done Scheduling job:U0000000009049 sending job to queue SaveLoad
12:09:49 Scheduling new unfirm job:U0000000008865
12:09:52 Done Scheduling job:U0000000008865 sending job to queue SaveLoad
12:09:52 Scheduling new unfirm job:U0000000009050
12:09:53 Done Scheduling job:U0000000009050 sending job to queue SaveLoad
12:09:53 Scheduling new unfirm job:U0000000008866
12:09:57 Done Scheduling job:U0000000008866 sending job to queue SaveLoad
12:09:57 Scheduling new unfirm job:U0000000009071
12:09:57 Done Scheduling job:U0000000009071 sending job to queue SaveLoad
12:09:57 Scheduling new unfirm job:U0000000008867
12:09:58 Done Scheduling job:U0000000008867 sending job to queue SaveLoad
12:09:58 Scheduling new unfirm job:U0000000009055
12:09:58 Done Scheduling job:U0000000009055 sending job to queue SaveLoad
12:09:58 Scheduling new unfirm job:U0000000009056
12:09:58 Done Scheduling job:U0000000009056 sending job to queue SaveLoad
12:09:59 Scheduling new unfirm job:U0000000009057
12:09:59 Done Scheduling job:U0000000009057 sending job to queue SaveLoad
12:09:59 Scheduling new unfirm job:U0000000009058
12:09:59 Done Scheduling job:U0000000009058 sending job to queue SaveLoad
12:09:59 Scheduling new unfirm job:U0000000009059
12:10:00 Done Scheduling job:U0000000009059 sending job to queue SaveLoad
12:10:00 Scheduling new unfirm job:U0000000009060
12:10:00 Done Scheduling job:U0000000009060 sending job to queue SaveLoad
12:10:00 Scheduling new unfirm job:U0000000009061
12:10:01 Done Scheduling job:U0000000009061 sending job to queue SaveLoad
12:10:01 Scheduling new unfirm job:U0000000009170
12:10:01 Done Scheduling job:U0000000009170 sending job to queue SaveLoad
12:10:01 Scheduling new unfirm job:U0000000009172
12:10:02 Done Scheduling job:U0000000009172 sending job to queue SaveLoad
12:10:02 Scheduling new unfirm job:U0000000009174
12:10:03 Done Scheduling job:U0000000009174 sending job to queue SaveLoad
12:10:03 Scheduling new unfirm job:U0000000009175
12:10:04 Done Scheduling job:U0000000009175 sending job to queue SaveLoad
12:10:04 Scheduling new unfirm job:U0000000009075
12:10:04 Done Scheduling job:U0000000009075 sending job to queue SaveLoad
12:10:04 Scheduling new unfirm job:U0000000009176
12:10:05 Done Scheduling job:U0000000009176 sending job to queue SaveLoad
12:10:05 Scheduling new unfirm job:U0000000009076
12:10:06 Done Scheduling job:U0000000009076 sending job to queue SaveLoad
12:10:06 Scheduling new unfirm job:U0000000009063
12:10:07 Done Scheduling job:U0000000009063 sending job to queue SaveLoad
12:10:07 Scheduling new unfirm job:U0000000009077
12:10:07 Done Scheduling job:U0000000009077 sending job to queue SaveLoad
12:10:07 Scheduling new unfirm job:U0000000009064
12:10:08 Done Scheduling job:U0000000009064 sending job to queue SaveLoad
12:10:08 Scheduling new unfirm job:U0000000009065
12:10:09 Done Scheduling job:U0000000009065 sending job to queue SaveLoad
12:10:09 Scheduling new unfirm job:U0000000009067
12:10:10 Done Scheduling job:U0000000009067 sending job to queue SaveLoad
12:10:10 Scheduling new unfirm job:U0000000009268
12:10:11 Done Scheduling job:U0000000009268 sending job to queue SaveLoad
12:10:11 Scheduling new unfirm job:U0000000009178
12:10:13 Done Scheduling job:U0000000009178 sending job to queue SaveLoad
12:10:13 Scheduling new unfirm job:U0000000009179
12:10:14 Done Scheduling job:U0000000009179 sending job to queue SaveLoad
12:10:14 Scheduling new unfirm job:U0000000009180
12:10:15 Done Scheduling job:U0000000009180 sending job to queue SaveLoad
12:10:15 Scheduling new unfirm job:U0000000009181
12:10:17 Done Scheduling job:U0000000009181 sending job to queue SaveLoad
12:10:17 Scheduling new unfirm job:U0000000009082
12:10:18 Done Scheduling job:U0000000009082 sending job to queue SaveLoad
12:10:18 Scheduling new unfirm job:U0000000009271
12:10:19 Done Scheduling job:U0000000009271 sending job to queue SaveLoad
12:10:19 Scheduling new unfirm job:U0000000009184
12:10:20 Done Scheduling job:U0000000009184 sending job to queue SaveLoad
12:10:20 Scheduling new unfirm job:U0000000009272
12:10:21 Done Scheduling job:U0000000009272 sending job to queue SaveLoad
12:10:21 Scheduling new unfirm job:U0000000009275
12:10:22 Done Scheduling job:U0000000009275 sending job to queue SaveLoad
12:10:22 Scheduling new unfirm job:U0000000009087
12:10:24 Done Scheduling job:U0000000009087 sending job to queue SaveLoad
12:10:36 Ending Part Level: 4-0.  Wait Time 00h:00m:56s, Jobs 60
12:10:36 Starting Part Level: 5-0.
12:10:36 Scheduling new unfirm job:U0000000009194
12:10:37 Done Scheduling job:U0000000009194 sending job to queue SaveLoad
12:10:37 Scheduling new unfirm job:U0000000009195
12:10:37 Done Scheduling job:U0000000009195 sending job to queue SaveLoad
12:10:54 Scheduling new unfirm job:U0000000009292
12:10:54 Done Scheduling job:U0000000009292 sending job to queue SaveLoad
12:10:54 Scheduling new unfirm job:U0000000009293
12:10:55 Done Scheduling job:U0000000009293 sending job to queue SaveLoad
12:10:55 Scheduling new unfirm job:U0000000009205
12:10:55 Done Scheduling job:U0000000009205 sending job to queue SaveLoad
12:10:55 Scheduling new unfirm job:U0000000009294
12:10:56 Done Scheduling job:U0000000009294 sending job to queue SaveLoad
12:10:56 Scheduling new unfirm job:U0000000009206
12:10:56 Done Scheduling job:U0000000009206 sending job to queue SaveLoad
12:10:56 Scheduling new unfirm job:U0000000009207
12:10:57 Done Scheduling job:U0000000009207 sending job to queue SaveLoad
12:10:57 Scheduling new unfirm job:U0000000009295
12:10:58 Done Scheduling job:U0000000009295 sending job to queue SaveLoad
12:10:58 Scheduling new unfirm job:U0000000009208
12:10:58 Done Scheduling job:U0000000009208 sending job to queue SaveLoad
12:10:58 Scheduling new unfirm job:U0000000009296
12:10:59 Done Scheduling job:U0000000009296 sending job to queue SaveLoad
12:10:59 Scheduling new unfirm job:U0000000009209
12:10:59 Done Scheduling job:U0000000009209 sending job to queue SaveLoad
12:10:59 Scheduling new unfirm job:U0000000009297
12:11:00 Done Scheduling job:U0000000009297 sending job to queue SaveLoad
12:11:00 Scheduling new unfirm job:U0000000009210
12:11:00 Done Scheduling job:U0000000009210 sending job to queue SaveLoad
12:11:00 Scheduling new unfirm job:U0000000009298
12:11:01 Done Scheduling job:U0000000009298 sending job to queue SaveLoad
12:11:01 Scheduling new unfirm job:U0000000009211
12:11:01 Done Scheduling job:U0000000009211 sending job to queue SaveLoad
12:11:01 Scheduling new unfirm job:U0000000009299
12:11:02 Done Scheduling job:U0000000009299 sending job to queue SaveLoad
12:11:02 Scheduling new unfirm job:U0000000009212
12:11:02 Done Scheduling job:U0000000009212 sending job to queue SaveLoad
12:11:02 Scheduling new unfirm job:U0000000009300
12:11:03 Done Scheduling job:U0000000009300 sending job to queue SaveLoad
12:11:03 Scheduling new unfirm job:U0000000009213
12:11:04 Done Scheduling job:U0000000009213 sending job to queue SaveLoad
12:11:04 Scheduling new unfirm job:U0000000009301
12:11:04 Done Scheduling job:U0000000009301 sending job to queue SaveLoad
12:11:04 Scheduling new unfirm job:U0000000009214
12:11:05 Done Scheduling job:U0000000009214 sending job to queue SaveLoad
12:11:05 Scheduling new unfirm job:U0000000009100
12:11:05 Done Scheduling job:U0000000009100 sending job to queue SaveLoad
12:11:05 Scheduling new unfirm job:U0000000009302
12:11:06 Done Scheduling job:U0000000009302 sending job to queue SaveLoad
12:11:06 Scheduling new unfirm job:U0000000009215
12:11:06 Done Scheduling job:U0000000009215 sending job to queue SaveLoad
12:11:06 Scheduling new unfirm job:U0000000009216
12:11:07 Done Scheduling job:U0000000009216 sending job to queue SaveLoad
12:11:07 Scheduling new unfirm job:U0000000009101
12:11:07 Done Scheduling job:U0000000009101 sending job to queue SaveLoad
12:11:07 Scheduling new unfirm job:U0000000009303
12:11:08 Done Scheduling job:U0000000009303 sending job to queue SaveLoad
12:11:08 Scheduling new unfirm job:U0000000009217
12:11:08 Done Scheduling job:U0000000009217 sending job to queue SaveLoad
12:11:08 Scheduling new unfirm job:U0000000009102
12:11:09 Done Scheduling job:U0000000009102 sending job to queue SaveLoad
12:11:09 Scheduling new unfirm job:U0000000009218
12:11:09 Done Scheduling job:U0000000009218 sending job to queue SaveLoad
12:11:09 Scheduling new unfirm job:U0000000009103
12:11:10 Done Scheduling job:U0000000009103 sending job to queue SaveLoad
12:11:10 Scheduling new unfirm job:U0000000009104
12:11:10 Done Scheduling job:U0000000009104 sending job to queue SaveLoad
12:11:10 Scheduling new unfirm job:U0000000009220
12:11:11 Done Scheduling job:U0000000009220 sending job to queue SaveLoad
12:11:11 Scheduling new unfirm job:U0000000009221
12:11:11 Done Scheduling job:U0000000009221 sending job to queue SaveLoad
12:11:11 Scheduling new unfirm job:U0000000009222
12:11:12 Done Scheduling job:U0000000009222 sending job to queue SaveLoad
12:11:12 Scheduling new unfirm job:U0000000009223
12:11:12 Done Scheduling job:U0000000009223 sending job to queue SaveLoad
12:11:12 Scheduling new unfirm job:U0000000009224
12:11:13 Done Scheduling job:U0000000009224 sending job to queue SaveLoad
12:11:13 Scheduling new unfirm job:U0000000009225
12:11:13 Done Scheduling job:U0000000009225 sending job to queue SaveLoad
12:11:13 Scheduling new unfirm job:U0000000009226
12:11:14 Done Scheduling job:U0000000009226 sending job to queue SaveLoad
12:11:14 Scheduling new unfirm job:U0000000009227
12:11:14 Done Scheduling job:U0000000009227 sending job to queue SaveLoad
12:11:14 Scheduling new unfirm job:U0000000009306
12:11:15 Done Scheduling job:U0000000009306 sending job to queue SaveLoad
12:11:15 Scheduling new unfirm job:U0000000009228
12:11:16 Done Scheduling job:U0000000009228 sending job to queue SaveLoad
12:11:16 Scheduling new unfirm job:U0000000009108
12:11:16 Done Scheduling job:U0000000009108 sending job to queue SaveLoad
12:11:16 Scheduling new unfirm job:U0000000009109
12:11:17 Done Scheduling job:U0000000009109 sending job to queue SaveLoad
12:11:17 Scheduling new unfirm job:U0000000009232
12:11:17 Done Scheduling job:U0000000009232 sending job to queue SaveLoad
12:11:17 Scheduling new unfirm job:U0000000009234
12:11:17 Done Scheduling job:U0000000009234 sending job to queue SaveLoad
12:11:17 Scheduling new unfirm job:U0000000009114
12:11:18 Done Scheduling job:U0000000009114 sending job to queue SaveLoad
12:11:18 Scheduling new unfirm job:U0000000009116
12:11:19 Done Scheduling job:U0000000009116 sending job to queue SaveLoad
12:11:19 Scheduling new unfirm job:U0000000009240
12:11:19 Done Scheduling job:U0000000009240 sending job to queue SaveLoad
12:11:19 Scheduling new unfirm job:U0000000009117
12:11:20 Done Scheduling job:U0000000009117 sending job to queue SaveLoad
12:11:20 Scheduling new unfirm job:U0000000009243
12:11:21 Done Scheduling job:U0000000009243 sending job to queue SaveLoad
12:11:21 Scheduling new unfirm job:U0000000009244
12:11:21 Done Scheduling job:U0000000009244 sending job to queue SaveLoad
12:11:21 Scheduling new unfirm job:U0000000009120
12:11:21 Done Scheduling job:U0000000009120 sending job to queue SaveLoad
12:11:21 Scheduling new unfirm job:U0000000009121
12:11:22 Done Scheduling job:U0000000009121 sending job to queue SaveLoad
12:11:22 Scheduling new unfirm job:U0000000009309
12:11:22 Done Scheduling job:U0000000009309 sending job to queue SaveLoad
12:11:22 Scheduling new unfirm job:U0000000009123
12:11:22 Done Scheduling job:U0000000009123 sending job to queue SaveLoad
12:11:22 Scheduling new unfirm job:U0000000009312
12:11:23 Done Scheduling job:U0000000009312 sending job to queue SaveLoad
12:11:23 Scheduling new unfirm job:U0000000009313
12:11:23 Done Scheduling job:U0000000009313 sending job to queue SaveLoad
12:11:23 Scheduling new unfirm job:U0000000009315
12:11:24 Done Scheduling job:U0000000009315 sending job to queue SaveLoad
12:11:24 Scheduling new unfirm job:U0000000009318
12:11:24 Done Scheduling job:U0000000009318 sending job to queue SaveLoad
12:11:26 Scheduling new unfirm job:U0000000009324
12:11:27 Done Scheduling job:U0000000009324 sending job to queue SaveLoad
12:11:27 Scheduling new unfirm job:U0000000009325
12:11:27 Done Scheduling job:U0000000009325 sending job to queue SaveLoad
12:11:27 Scheduling new unfirm job:U0000000009125
12:11:28 Done Scheduling job:U0000000009125 sending job to queue SaveLoad
12:11:28 Scheduling new unfirm job:U0000000009126
12:11:28 Done Scheduling job:U0000000009126 sending job to queue SaveLoad
12:11:28 Scheduling new unfirm job:U0000000009246
12:11:28 Done Scheduling job:U0000000009246 sending job to queue SaveLoad
12:11:28 Scheduling new unfirm job:U0000000009328
12:11:28 Done Scheduling job:U0000000009328 sending job to queue SaveLoad
12:11:28 Scheduling new unfirm job:U0000000009329
12:11:29 Done Scheduling job:U0000000009329 sending job to queue SaveLoad
12:11:29 Scheduling new unfirm job:U0000000009129
12:11:29 Done Scheduling job:U0000000009129 sending job to queue SaveLoad
12:11:29 Scheduling new unfirm job:U0000000009130
12:11:30 Done Scheduling job:U0000000009130 sending job to queue SaveLoad
12:11:30 Scheduling new unfirm job:U0000000009331
12:11:30 Done Scheduling job:U0000000009331 sending job to queue SaveLoad
12:11:30 Scheduling new unfirm job:U0000000009250
12:11:30 Done Scheduling job:U0000000009250 sending job to queue SaveLoad
12:11:30 Scheduling new unfirm job:U0000000009333
12:11:31 Done Scheduling job:U0000000009333 sending job to queue SaveLoad
12:11:31 Scheduling new unfirm job:U0000000009335
12:11:31 Done Scheduling job:U0000000009335 sending job to queue SaveLoad
12:11:31 Scheduling new unfirm job:U0000000009336
12:11:32 Done Scheduling job:U0000000009336 sending job to queue SaveLoad
12:11:32 Scheduling new unfirm job:U0000000009337
12:11:32 Done Scheduling job:U0000000009337 sending job to queue SaveLoad
12:11:32 Scheduling new unfirm job:U0000000009252
12:11:33 Done Scheduling job:U0000000009252 sending job to queue SaveLoad
12:11:33 Scheduling new unfirm job:U0000000009253
12:11:33 Done Scheduling job:U0000000009253 sending job to queue SaveLoad
12:11:33 Scheduling new unfirm job:U0000000009341
12:11:34 Done Scheduling job:U0000000009341 sending job to queue SaveLoad
12:11:34 Scheduling new unfirm job:U0000000009343
12:11:34 Done Scheduling job:U0000000009343 sending job to queue SaveLoad
12:11:34 Scheduling new unfirm job:U0000000009345
12:11:35 Done Scheduling job:U0000000009345 sending job to queue SaveLoad
12:11:35 Scheduling new unfirm job:U0000000009346
12:11:35 Done Scheduling job:U0000000009346 sending job to queue SaveLoad
12:11:35 Scheduling new unfirm job:U0000000009347
12:11:36 Done Scheduling job:U0000000009347 sending job to queue SaveLoad
12:11:36 Scheduling new unfirm job:U0000000009348
12:11:36 Done Scheduling job:U0000000009348 sending job to queue SaveLoad
12:11:36 Scheduling new unfirm job:U0000000009349
12:11:36 Done Scheduling job:U0000000009349 sending job to queue SaveLoad
12:11:36 Scheduling new unfirm job:U0000000009350
12:11:37 Done Scheduling job:U0000000009350 sending job to queue SaveLoad
12:11:37 Scheduling new unfirm job:U0000000009351
12:11:37 Done Scheduling job:U0000000009351 sending job to queue SaveLoad
12:11:37 Scheduling new unfirm job:U0000000009137
12:11:38 Done Scheduling job:U0000000009137 sending job to queue SaveLoad
12:11:38 Scheduling new unfirm job:U0000000009138
12:11:38 Done Scheduling job:U0000000009138 sending job to queue SaveLoad
12:11:38 Scheduling new unfirm job:U0000000009139
12:11:39 Done Scheduling job:U0000000009139 sending job to queue SaveLoad
12:11:39 Scheduling new unfirm job:U0000000009140
12:11:39 Done Scheduling job:U0000000009140 sending job to queue SaveLoad
12:11:39 Scheduling new unfirm job:U0000000009141
12:11:40 Done Scheduling job:U0000000009141 sending job to queue SaveLoad
12:11:40 Scheduling new unfirm job:U0000000009142
12:11:40 Done Scheduling job:U0000000009142 sending job to queue SaveLoad
12:11:40 Scheduling new unfirm job:U0000000009143
12:11:40 Done Scheduling job:U0000000009143 sending job to queue SaveLoad
12:11:40 Scheduling new unfirm job:U0000000009144
12:11:41 Done Scheduling job:U0000000009144 sending job to queue SaveLoad
12:11:41 Scheduling new unfirm job:U0000000009261
12:11:41 Done Scheduling job:U0000000009261 sending job to queue SaveLoad
12:11:41 Scheduling new unfirm job:U0000000009262
12:11:42 Done Scheduling job:U0000000009262 sending job to queue SaveLoad
12:11:42 Scheduling new unfirm job:U0000000009263
12:11:42 Done Scheduling job:U0000000009263 sending job to queue SaveLoad
12:11:42 Scheduling new unfirm job:U0000000009264
12:11:42 Done Scheduling job:U0000000009264 sending job to queue SaveLoad
12:11:42 Scheduling new unfirm job:U0000000009265
12:11:43 Done Scheduling job:U0000000009265 sending job to queue SaveLoad
12:11:43 Scheduling new unfirm job:U0000000009266
12:11:43 Done Scheduling job:U0000000009266 sending job to queue SaveLoad
12:11:43 Scheduling new unfirm job:U0000000009267
12:11:44 Done Scheduling job:U0000000009267 sending job to queue SaveLoad
12:11:44 Scheduling new unfirm job:U0000000009354
12:11:45 Done Scheduling job:U0000000009354 sending job to queue SaveLoad
12:11:45 Scheduling new unfirm job:U0000000009368
12:11:45 Done Scheduling job:U0000000009368 sending job to queue SaveLoad
12:11:45 Scheduling new unfirm job:U0000000009355
12:11:46 Done Scheduling job:U0000000009355 sending job to queue SaveLoad
12:11:46 Scheduling new unfirm job:U0000000009369
12:11:47 Done Scheduling job:U0000000009369 sending job to queue SaveLoad
12:11:47 Scheduling new unfirm job:U0000000009370
12:11:47 Done Scheduling job:U0000000009370 sending job to queue SaveLoad
12:11:47 Scheduling new unfirm job:U0000000009371
12:11:47 Done Scheduling job:U0000000009371 sending job to queue SaveLoad
12:11:47 Scheduling new unfirm job:U0000000009372
12:11:48 Done Scheduling job:U0000000009372 sending job to queue SaveLoad
12:11:48 Scheduling new unfirm job:U0000000009149
12:11:49 Done Scheduling job:U0000000009149 sending job to queue SaveLoad
12:11:49 Scheduling new unfirm job:U0000000009150
12:11:49 Done Scheduling job:U0000000009150 sending job to queue SaveLoad
12:11:49 Scheduling new unfirm job:U0000000009151
12:11:50 Done Scheduling job:U0000000009151 sending job to queue SaveLoad
12:11:50 Scheduling new unfirm job:U0000000009359
12:11:51 Done Scheduling job:U0000000009359 sending job to queue SaveLoad
12:11:51 Scheduling new unfirm job:U0000000009152
12:11:52 Done Scheduling job:U0000000009152 sending job to queue SaveLoad
12:11:52 Scheduling new unfirm job:U0000000009360
12:11:53 Done Scheduling job:U0000000009360 sending job to queue SaveLoad
12:11:53 Scheduling new unfirm job:U0000000009361
12:11:53 Done Scheduling job:U0000000009361 sending job to queue SaveLoad
12:11:53 Scheduling new unfirm job:U0000000009362
12:11:54 Done Scheduling job:U0000000009362 sending job to queue SaveLoad
12:11:54 Scheduling new unfirm job:U0000000009363
12:11:55 Done Scheduling job:U0000000009363 sending job to queue SaveLoad
12:11:55 Scheduling new unfirm job:U0000000009364
12:11:56 Done Scheduling job:U0000000009364 sending job to queue SaveLoad
12:11:56 Scheduling new unfirm job:U0000000009155
12:11:56 Done Scheduling job:U0000000009155 sending job to queue SaveLoad
12:11:56 Scheduling new unfirm job:U0000000009156
12:11:56 Done Scheduling job:U0000000009156 sending job to queue SaveLoad
12:11:56 Scheduling new unfirm job:U0000000009157
12:11:56 Done Scheduling job:U0000000009157 sending job to queue SaveLoad
12:11:56 Scheduling new unfirm job:U0000000009158
12:11:57 Done Scheduling job:U0000000009158 sending job to queue SaveLoad
12:11:57 Scheduling new unfirm job:U0000000009159
12:11:57 Done Scheduling job:U0000000009159 sending job to queue SaveLoad
12:11:57 Scheduling new unfirm job:U0000000009160
12:11:57 Done Scheduling job:U0000000009160 sending job to queue SaveLoad
12:11:57 Scheduling new unfirm job:U0000000009161
12:11:58 Done Scheduling job:U0000000009161 sending job to queue SaveLoad
12:11:58 Scheduling new unfirm job:U0000000009162
12:11:58 Done Scheduling job:U0000000009162 sending job to queue SaveLoad
12:11:58 Scheduling new unfirm job:U0000000009163
12:11:58 Done Scheduling job:U0000000009163 sending job to queue SaveLoad
12:11:58 Scheduling new unfirm job:U0000000009164
12:11:58 Done Scheduling job:U0000000009164 sending job to queue SaveLoad
12:11:58 Scheduling new unfirm job:U0000000009165
12:11:59 Done Scheduling job:U0000000009165 sending job to queue SaveLoad
12:11:59 Scheduling new unfirm job:U0000000009367
12:11:59 Done Scheduling job:U0000000009367 sending job to queue SaveLoad
12:12:01 Scheduling new unfirm job:U0000000009471
12:12:01 Done Scheduling job:U0000000009471 sending job to queue SaveLoad
12:12:01 Scheduling new unfirm job:U0000000009472
12:12:02 Done Scheduling job:U0000000009472 sending job to queue SaveLoad
12:12:02 Scheduling new unfirm job:U0000000009473
12:12:02 Done Scheduling job:U0000000009473 sending job to queue SaveLoad
12:12:02 Scheduling new unfirm job:U0000000009474
12:12:03 Done Scheduling job:U0000000009474 sending job to queue SaveLoad
12:12:03 Scheduling new unfirm job:U0000000009475
12:12:03 Done Scheduling job:U0000000009475 sending job to queue SaveLoad
12:12:03 Scheduling new unfirm job:U0000000009476
12:12:03 Done Scheduling job:U0000000009476 sending job to queue SaveLoad
12:12:03 Scheduling new unfirm job:U0000000009477
12:12:04 Done Scheduling job:U0000000009477 sending job to queue SaveLoad
12:12:04 Scheduling new unfirm job:U0000000009478
12:12:04 Done Scheduling job:U0000000009478 sending job to queue SaveLoad
12:12:04 Scheduling new unfirm job:U0000000009479
12:12:04 Done Scheduling job:U0000000009479 sending job to queue SaveLoad
12:12:04 Scheduling new unfirm job:U0000000009480
12:12:05 Done Scheduling job:U0000000009480 sending job to queue SaveLoad
12:12:05 Scheduling new unfirm job:U0000000009481
12:12:05 Done Scheduling job:U0000000009481 sending job to queue SaveLoad
12:12:05 Scheduling new unfirm job:U0000000009482
12:12:05 Done Scheduling job:U0000000009482 sending job to queue SaveLoad
12:12:05 Scheduling new unfirm job:U0000000009483
12:12:06 Done Scheduling job:U0000000009483 sending job to queue SaveLoad
12:12:08 Scheduling new unfirm job:U0000000009484
12:12:08 Done Scheduling job:U0000000009484 sending job to queue SaveLoad
12:12:08 Scheduling new unfirm job:U0000000009382
12:12:09 Done Scheduling job:U0000000009382 sending job to queue SaveLoad
12:12:09 Scheduling new unfirm job:U0000000009383
12:12:10 Done Scheduling job:U0000000009383 sending job to queue SaveLoad
12:12:10 Scheduling new unfirm job:U0000000009384
12:12:11 Done Scheduling job:U0000000009384 sending job to queue SaveLoad
12:12:11 Scheduling new unfirm job:U0000000009385
12:12:12 Done Scheduling job:U0000000009385 sending job to queue SaveLoad
12:12:12 Scheduling new unfirm job:U0000000009386
12:12:13 Done Scheduling job:U0000000009386 sending job to queue SaveLoad
12:12:13 Scheduling new unfirm job:U0000000009387
12:12:14 Done Scheduling job:U0000000009387 sending job to queue SaveLoad
12:12:14 Scheduling new unfirm job:U0000000009388
12:12:14 Done Scheduling job:U0000000009388 sending job to queue SaveLoad
12:12:14 Scheduling new unfirm job:U0000000009390
12:12:15 Done Scheduling job:U0000000009390 sending job to queue SaveLoad
